Workbook

Sheet Elec Audit
A1: REC_NO | B1: DWG | C1: REV_NO | D1: SCHED_ID | E1: CAREA | F1: CODE | G1: SYSTEM | H1: CIRCUIT | I1: TAG_NO | J1: SZE | K1: FLD_QTY | L1: UOM | M1: FLD_WHRS | N1: PIPE_SPEC | O1: ERN_QTY | P1: EARN_WHRS | Q1: MI_Q_1 | R1: M1_DESC | S1: MI_Q_2 | T1: M2_DESC | U1: MI_Q_3 | V1: M3_DESC | W1: MI_Q_4 | X1: M4_DESC | Y1: MI_Q_5 | Z1: M5_DESC | AA1: MI_Q_6 | AB1: M6_DESC | AC1: MI_Q_7 | AD1: M7_DESC | AE1: MI_Q_8 | AF1: M8_DESC | AG1: TEST_PKG | AH1: CWP | AI1: IWP_PLAN_NO | AJ1: SPL_CNT | AK1: IWP_FOREMAN | AL1: IWP_GEN_FOREMAN | AM1: WHRS_UNIT | AN1: M1 | AO1: M2 | AP1: M3 | AQ1: M4 | AR1: M5 | AS1: M6 | AT1: M7 | AU1: M8 | AV1: VAR1 | AW1: PAINT_SPEC | AX1: INSU_SPEC | AY1: HEAT_TRACE_SPEC | AZ1: TA_BANK | BA1: TA_BAY | BB1: TA_LEVEL | BC1: PSLIP
A2: 1 | B2: P02.03-EL-120-PLN-00022 | C2: 0 | D2: *C | E2: PLN-00031 DUCT BANKS | F2: 09220 | G2: 401 UG DUCT BANK | H2: DUCT BANK | I2: DBC-H | J2: 2 | K2: 6408 | L2: LF. | M2: =_xlfn.XLOOKUP(J2, Sheet1!E:E, Sheet1!I:I, "")*K2 -> 686.2968 | R2: Receive Materials | T2: Run Conduit | AI2: EL-401-001 | AN2: 0.3 | AO2: 0.7 | AV2: 401
A3: 2 | B3: P02.03-EL-120-PLN-00022 | C3: 0 | D3: *C | E3: PLN-00031 DUCT BANKS | F3: 09220 | G3: 401 UG DUCT BANK | H3: DUCT BANK | I3: DBC-H | J3: 4 | K3: 801 | L3: LF. | M3: =_xlfn.XLOOKUP(J3, Sheet1!E:E, Sheet1!I:I, "")*K3 -> 133.4466 | R3: Receive Materials | T3: Run Conduit | AI3: EL-401-001 | AN3: 0.3 | AO3: 0.7 | AV3: 401
A4: 3 | B4: P02.03-EL-120-PLN-00022 | C4: 0 | D4: *C | E4: PLN-00031 DUCT BANKS | F4: 09220 | G4: 401 UG DUCT BANK | H4: DUCT BANK | I4: DBC-H-stub | J4: 1 | K4: 120 | L4: LF. | M4: =_xlfn.XLOOKUP(J4, Sheet1!E:E, Sheet1!I:I, "")*K4 -> 9.996 | R4: Receive Materials | T4: Run Conduit | AI4: EL-401-001 | AN4: 0.3 | AO4: 0.7 | AV4: 401
A5: 4 | B5: P02.03-EL-120-PLN-00022 | C5: 0 | D5: *C | E5: PLN-00028 DUCT BANKS | F5: 09220 | G5: 401 UG DUCT BANK | H5: DUCT BANK | I5: DBC-D | J5: 6 | K5: 1344 | L5: LF. | M5: =_xlfn.XLOOKUP(J5, Sheet1!E:E, Sheet1!I:I, "")*K5 -> 319.872 | R5: Receive Materials | T5: Run Conduit | AI5: EL-401-002 | AN5: 0.3 | AO5: 0.7 | AV5: 402
A6: 5 | B6: P02.03-EL-120-PLN-00022 | C6: 0 | D6: *C | E6: PLN-00028 DUCT BANKS | F6: 09220 | G6: 401 UG DUCT BANK | H6: DUCT BANK | I6: DBC-D | J6: 4 | K6: 3360 | L6: LF. | M6: =_xlfn.XLOOKUP(J6, Sheet1!E:E, Sheet1!I:I, "")*K6 -> 559.776 | R6: Receive Materials | T6: Run Conduit | AI6: EL-401-002 | AN6: 0.3 | AO6: 0.7 | AV6: 402
A7: 6 | B7: P02.03-EL-120-PLN-00022 | C7: 0 | D7: *C | E7: PLN-00028 DUCT BANKS | F7: 09220 | G7: 401 UG DUCT BANK | H7: DUCT BANK | I7: DBC-D | J7: 2 | K7: 6048 | L7: LF. | M7: =_xlfn.XLOOKUP(J7, Sheet1!E:E, Sheet1!I:I, "")*K7 -> 647.7408 | R7: Receive Materials | T7: Run Conduit | AI7: EL-401-002 | AN7: 0.3 | AO7: 0.7 | AV7: 402
A8: 7 | B8: P02.03-EL-120-PLN-00022 | C8: 0 | D8: *C | E8: PLN-00028 DUCT BANKS | F8: 09220 | G8: 401 UG DUCT BANK | H8: DUCT BANK | I8: DBC-E | J8: 6 | K8: 320 | L8: LF. | M8: =_xlfn.XLOOKUP(J8, Sheet1!E:E, Sheet1!I:I, "")*K8 -> 76.16 | R8: Receive Materials | T8: Run Conduit | AI8: EL-401-003 | AN8: 0.3 | AO8: 0.7 | AV8: 403
A9: 8 | B9: P02.03-EL-120-PLN-00022 | C9: 0 | D9: *C | E9: PLN-00028 DUCT BANKS | F9: 09220 | G9: 401 UG DUCT BANK | H9: DUCT BANK | I9: DBC-E | J9: 4 | K9: 800 | L9: LF. | M9: =_xlfn.XLOOKUP(J9, Sheet1!E:E, Sheet1!I:I, "")*K9 -> 133.28 | R9: Receive Materials | T9: Run Conduit | AI9: EL-401-003 | AN9: 0.3 | AO9: 0.7 | AV9: 401
A10: 9 | B10: P02.03-EL-120-PLN-00022 | C10: 0 | D10: *C | E10: PLN-00028 DUCT BANKS | F10: 09220 | G10: 401 UG DUCT BANK | H10: DUCT BANK | I10: DBC-E | J10: 2 | K10: 1440 | L10: LF. | M10: =_xlfn.XLOOKUP(J10, Sheet1!E:E, Sheet1!I:I, "")*K10 -> 154.224 | R10: Receive Materials | T10: Run Conduit | AI10: EL-401-003 | AN10: 0.3 | AO10: 0.7 | AV10: 401
A11: 10 | B11: P02.03-EL-120-PLN-00022 | C11: 0 | D11: *C | E11: PLN-00027 DUCT BANKS | F11: 09220 | G11: 401 UG DUCT BANK | H11: DUCT BANK | I11: DBC-A | J11: 6 | K11: 272 | L11: LF. | M11: =_xlfn.XLOOKUP(J11, Sheet1!E:E, Sheet1!I:I, "")*K11 -> 64.736 | R11: Receive Materials | T11: Run Conduit | AI11: EL-401-004 | AN11: 0.3 | AO11: 0.7 | AV11: 401
A12: 11 | B12: P02.03-EL-120-PLN-00022 | C12: 0 | D12: *C | E12: PLN-00028 DUCT BANKS | F12: 09220 | G12: 402 UG DUCT BANK | H12: DUCT BANK | I12: DBC-F | J12: 6 | K12: 440 | L12: LF. | M12: =_xlfn.XLOOKUP(J12, Sheet1!E:E, Sheet1!I:I, "")*K12 -> 104.72 | R12: Receive Materials | T12: Run Conduit | AI12: EL-402-001 | AN12: 0.3 | AO12: 0.7 | AV12: 402
A13: 12 | B13: P02.03-EL-120-PLN-00022 | C13: 0 | D13: *C | E13: PLN-00028 DUCT BANKS | F13: 09220 | G13: 402 UG DUCT BANK | H13: DUCT BANK | I13: DBC-F | J13: 4 | K13: 1100 | L13: LF. | M13: =_xlfn.XLOOKUP(J13, Sheet1!E:E, Sheet1!I:I, "")*K13 -> 183.26 | R13: Receive Materials | T13: Run Conduit | AI13: EL-402-001 | AN13: 0.3 | AO13: 0.7 | AV13: 402
... A29: 28 | B29: P02.03-EL-120-PLN-00026 | C29: 0 | D29: *C | E29: PLN-00031 DUCT BANKS | F29: 09220 | G29: 401 UG DUCT BANK | H29: DUCT BANK | I29: DBC-H | J29: 2 | K29: 720 | L29: LF. | M29: =_xlfn.XLOOKUP(J29, Sheet1!E:E, Sheet1!I:I, "")*K29 -> 77.112 | R29: Receive Materials | T29: Run Conduit | AI29: EL-401-001 | AN29: 0.3 | AO29: 0.7 | AV29: 404
A30: 29 | B30: P02.03-EL-120-PLN-00015 | C30: 0 | D30: *C | F30: 09100 | H30: GROUNDING PLAN | I30: GRND | K30: 206.48 | L30: LF. | M30: =K30*Sheet1!I6 -> 56.98848 | R30: Trenching | T30: Install Wire | V30: Backfill | AI30: GND-200-001 | AN30: 0.3 | AO30: 0.5 | AP30: 0.2 | AV30: 200
A31: 30 | B31: P02.03-EL-120-PLN-00012 | C31: 0 | D31: *C | F31: 09100 | H31: GROUNDING PLAN | I31: GRND | K31: 727.55 | L31: LF. | M31: =K31*Sheet1!I6 -> 200.8038 | R31: Trenching | T31: Install Wire | V31: Backfill | AI31: GND-200-002 | AN31: 0.3 | AO31: 0.5 | AP31: 0.2 | AV31: 200
A32: 31 | B32: P02.03-EL-120-PLN-00002 | C32: 0 | D32: *C | F32: 09100 | H32: GROUNDING PLAN | I32: GRND | K32: 613.1 | L32: LF. | M32: =K32*Sheet1!I6 -> 169.2156 | R32: Trenching | T32: Install Wire | V32: Backfill | AI32: GND-401-001 | AN32: 0.3 | AO32: 0.5 | AP32: 0.2 | AV32: 401
A33: 32 | B33: P02.03-EL-120-PLN-00005 | C33: 0 | D33: *C | F33: 09100 | H33: GROUNDING PLAN | I33: GRND | K33: 1564.48 | L33: LF. | M33: =K33*Sheet1!I6 -> 431.79648 | R33: Trenching | T33: Install Wire | V33: Backfill | AI33: GND-401-002 | AN33: 0.3 | AO33: 0.5 | AP33: 0.2 | AV33: 401
A34: 33 | B34: P02.03-EL-120-PLN-00003 | C34: 0 | D34: *C | F34: 09100 | H34: GROUNDING PLAN | I34: GRND | K34: 959.92 | L34: LF. | M34: =K34*Sheet1!I6 -> 264.93792 | R34: Trenching | T34: Install Wire | V34: Backfill | AI34: GND-402-001 | AN34: 0.3 | AO34: 0.5 | AP34: 0.2 | AV34: 402
A35: 34 | B35: P02.03-EL-120-PLN-00006 | C35: 0 | D35: *C | F35: 09100 | H35: GROUNDING PLAN | I35: GRND | K35: 2929.17 | L35: LF. | M35: =K35*Sheet1!I6 -> 808.45092 | R35: Trenching | T35: Install Wire | V35: Backfill | AI35: GND-402-002 | AN35: 0.3 | AO35: 0.5 | AP35: 0.2 | AV35: 402
A36: 35 | B36: P02.03-EL-120-PLN-00008 | C36: 0 | D36: *C | F36: 09100 | H36: GROUNDING PLAN | I36: GRND | K36: 1026.04 | L36: LF. | M36: =K36*Sheet1!I6 -> 283.18704 | R36: Trenching | T36: Install Wire | V36: Backfill | AI36: GND-404-001 | AN36: 0.3 | AO36: 0.5 | AP36: 0.2 | AV36: 404
A37: 36 | B37: P02.03-EL-120-PLN-00004 | C37: 0 | D37: *C | F37: 09100 | H37: GROUNDING PLAN | I37: GRND | K37: 436.52 | L37: LF. | M37: =K37*Sheet1!I6 -> 120.47952 | R37: Trenching | T37: Install Wire | V37: Backfill | AI37: GND-601-001 | AN37: 0.3 | AO37: 0.5 | AP37: 0.2 | AV37: 601
A38: 37 | B38: P02.03-EL-120-PLN-00007 | C38: 0 | D38: *C | F38: 09100 | H38: GROUNDING PLAN | I38: GRND | K38: 510.01 | L38: LF. | M38: =K38*Sheet1!I6 -> 140.76276 | R38: Trenching | T38: Install Wire | V38: Backfill | AI38: GND-601-002 | AN38: 0.3 | AO38: 0.5 | AP38: 0.2 | AV38: 601
A39: 38 | B39: P02.03-EL-120-PLN-00009 | C39: 0 | D39: *C | F39: 09100 | H39: GROUNDING PLAN | I39: GRND | K39: 2136.54 | L39: LF. | M39: =K39*Sheet1!I6 -> 589.68504 | R39: Trenching | T39: Install Wire | V39: Backfill | AI39: GND-404-002 | AN39: 0.3 | AO39: 0.5 | AP39: 0.2 | AV39: 404
A40: 39 | B40: P02.03-EL-120-PLN-00011 | C40: 0 | D40: *C | F40: 09100 | H40: GROUNDING PLAN | I40: GRND | K40: 269.2 | L40: LF. | M40: =K40*Sheet1!I6 -> 74.2992 | R40: Trenching | T40: Install Wire | V40: Backfill | AI40: GND-404-003 | AN40: 0.3 | AO40: 0.5 | AP40: 0.2 | AV40: 404
A41: 40 | B41: P02.03-EL-120-PLN-00010 | C41: 0 | D41: *C | F41: 09100 | H41: GROUNDING PLAN | I41: GRND | K41: 1192.47 | L41: LF. | M41: =K41*Sheet1!I6 -> 329.12172 | R41: Trenching | T41: Install Wire | V41: Backfill | AI41: GND-406-001 | AN41: 0.3 | AO41: 0.5 | AP41: 0.2 | AV41: 406
A42: 41 | B42: P02.03-EL-120-PLN-00013 | C42: 0 | D42: *C | F42: 09100 | H42: GROUNDING PLAN | I42: GRND | K42: 626.44 | L42: LF. | M42: =K42*Sheet1!I6 -> 172.89744 | R42: Trenching | T42: Install Wire | V42: Backfill | AI42: GND-406-002 | AN42: 0.3 | AO42: 0.5 | AP42: 0.2 | AV42: 406
A43: 42 | B43: P02.03-EL-120-PLN-00016 | C43: 0 | D43: *C | F43: 09100 | H43: GROUNDING PLAN | I43: GRND | K43: 165.2 | L43: LF. | M43: =K43*Sheet1!I6 -> 45.5952 | R43: Trenching | T43: Install Wire | V43: Backfill | AI43: GND-406-003 | AN43: 0.3 | AO43: 0.5 | AP43: 0.2 | AV43: 406
A44: 43 | B44: P02.03-EL-120-PLN-00022 | C44: 0 | D44: *C | F44: 09100 | H44: TRENCH TR-4/ C01 | I44: 4/C#10AWG | K44: 36 | L44: LF. | M44: =K44*Sheet1!$I$6 -> 9.936 | R44: Trenching | T44: Install Wire | V44: Backfill | AI44: EL-401-005 | AN44: 0.3 | AO44: 0.5 | AP44: 0.2 | AV44: 401
A45: 44 | B45: P02.03-EL-120-PLN-00022 | C45: 0 | D45: *C | F45: 09100 | H45: TRENCH TR-4/C02 | I45: 4/C#10AWG | K45: 36 | L45: LF. | M45: =K45*Sheet1!$I$6 -> 9.936 | R45: Trenching | T45: Install Wire | V45: Backfill | AI45: EL-401-005 | AN45: 0.3 | AO45: 0.5 | AP45: 0.2 | AV45: 401
A46: 45 | B46: P02.03-EL-120-PLN-00022 | C46: 0 | D46: *C | F46: 09100 | H46: TRENCH TR-4/C03 | I46: 12/C#10AWG | K46: 36 | L46: LF. | M46: =K46*Sheet1!$I$6 -> 9.936 | R46: Trenching | T46: Install Wire | V46: Backfill | AI46: EL-401-005 | AN46: 0.3 | AO46: 0.5 | AP46: 0.2 | AV46: 401
A47: 46 | B47: P02.03-EL-120-PLN-00022 | C47: 0 | D47: *C | F47: 09100 | H47: TRENCH TR-4/PA04 | I47: 4/C#10AWG | K47: 36 | L47: LF. | M47: =K47*Sheet1!$I$6 -> 9.936 | R47: Trenching | T47: Install Wire | V47: Backfill | AI47: EL-401-005 | AN47: 0.3 | AO47: 0.5 | AP47: 0.2 | AV47: 401
A48: 47 | B48: P02.03-EL-120-PLN-00022 | C48: 0 | D48: *C | F48: 09100 | H48: TRENCH TR-4/PD10 | I48: 2/C#10AWG | K48: 36 | L48: LF. | M48: =K48*Sheet1!$I$6 -> 9.936 | R48: Trenching | T48: Install Wire | V48: Backfill | AI48: EL-401-005 | AN48: 0.3 | AO48: 0.5 | AP48: 0.2 | AV48: 401
A49: 48 | B49: P02.03-EL-120-PLN-00022 | C49: 0 | D49: *C | F49: 09100 | H49: TRENCH TR-4/MMFO-T1-01 | I49: 12/FO OM1 | K49: 36 | L49: LF. | M49: =K49*Sheet1!$I$6 -> 9.936 | R49: Trenching | T49: Install Wire | V49: Backfill | AI49: EL-401-005 | AN49: 0.3 | AO49: 0.5 | AP49: 0.2 | AV49: 401
A50: 49 | B50: P02.03-EL-120-PLN-00022 | C50: 0 | D50: *C | F50: 09100 | H50: TRENCH TR-4/EP1-7,9,11 | I50: 3/C#10AWG | K50: 36 | L50: LF. | M50: =K50*Sheet1!$I$6 -> 9.936 | R50: Trenching | T50: Install Wire | V50: Backfill | AI50: EL-401-005 | AN50: 0.3 | AO50: 0.5 | AP50: 0.2 | AV50: 401
A51: 50 | B51: P02.03-EL-120-PLN-00022 | C51: 0 | D51: *C | F51: 09100 | H51: TRENCH TR-4/P-AT3-DSC-DIFF | I51: 4/C#8AWG | K51: 36 | L51: LF. | M51: =K51*Sheet1!$I$6 -> 9.936 | R51: Trenching | T51: Install Wire | V51: Backfill | AI51: EL-401-005 | AN51: 0.3 | AO51: 0.5 | AP51: 0.2 | AV51: 401
A52: 51 | B52: P02.03-EL-120-PLN-00022 | C52: 0 | D52: *C | F52: 09100 | H52: TRENCH TR-4 /PD11 | I52: 2/C#10AWG | K52: 36 | L52: LF. | M52: =K52*Sheet1!$I$6 -> 9.936 | R52: Trenching | T52: Install Wire | V52: Backfill | AI52: EL-401-005 | AN52: 0.3 | AO52: 0.5 | AP52: 0.2 | AV52: 401
A53: 52 | B53: P02.03-EL-120-PLN-00022 | C53: 0 | D53: *C | F53: 09100 | H53: TRENCH TR-11/ SPARE | K53: 28 | L53: LF. | M53: =K53*Sheet1!$I$6 -> 7.728 | R53: Trenching | T53: Install Wire | V53: Backfill | AI53: EL-401-005 | AN53: 0.3 | AO53: 0.5 | AP53: 0.2 | AV53: 401
A54: 53 | B54: P02.03-EL-120-PLN-00022 | C54: 0 | D54: *C | F54: 09100 | H54: TRENCH TR-11/ SPARE | K54: 28 | L54: LF. | M54: =K54*Sheet1!$I$6 -> 7.728 | R54: Trenching | T54: Install Wire | V54: Backfill | AI54: EL-401-005 | AN54: 0.3 | AO54: 0.5 | AP54: 0.2 | AV54: 401
A55: 54 | B55: P02.03-EL-120-PLN-00022 | C55: 0 | D55: *C | F55: 09100 | H55: TRENCH TR-11/ SPARE | K55: 28 | L55: LF. | M55: =K55*Sheet1!$I$6 -> 7.728 | R55: Trenching | T55: Install Wire | V55: Backfill | AI55: EL-401-005 | AN55: 0.3 | AO55: 0.5 | AP55: 0.2 | AV55: 401
...

Sheet Sheet1
D1: Type | E1: Size | F1: cost code | G1: Base U/R | H1: PF Adjust | I1: PF U/R
C2: stubles 5ft | D2: PVC Conduit 1" Ground Stub-up | E2: 1 | F2: 09220 | G2: 0.07 | H2: 1.19 | I2: =G2*H2 -> 0.0833
D3: PVC Conduit 2" | E3: 2 | F3: 09220 | G3: 0.09 | H3: 1.19 | I3: =G3*H3 -> 0.1071
D4: PVC Conduit 4" | E4: 4 | F4: 09220 | G4: 0.14 | H4: 1.19 | I4: =G4*H4 -> 0.1666
D5: PVC Conduit 6" | E5: 6 | F5: 09220 | G5: 0.2 | H5: 1.19 | I5: =G5*H5 -> 0.238
D6: #4/0 Green Insulated Grounding wire | F6: 09100 | I6: 0.276

Sheet Sheet2
B1: Duct Bank IWPs | C1: Description | E1: Man Hours | F1: LF.
B2: EL-401-001 | C2: PLN-00031 DUCT BANKS | D2: 401 UG DUCT BANK | E2: 922 | F2: 8139
B3: EL-401-002 | C3: PLN-00028 DUCT BANKS | D3: 401 UG DUCT BANK | E3: 1527 | F3: 10752
B4: EL-401-003 | C4: PLN-00028 DUCT BANKS | D4: 401 UG DUCT BANK | E4: 364 | F4: 2560
B5: EL-401-004 | C5: PLN-00027 DUCT BANKS | D5: 401 UG DUCT BANK | E5: 65 | F5: 272
B6: EL-402-001 | C6: PLN-00028 DUCT BANKS | D6: 402 UG DUCT BANK | E6: 500 | F6: 3520
B7: EL-402-002 | C7: PLN-00027 DUCT BANKS | D7: 402 UG DUCT BANK | E7: 65 | F7: 272
B8: EL-403-001 | C8: PLN-00028 DUCT BANKS | D8: 403 UG DUCT BANK | E8: 774 | F8: 5190
B9: EL-403-002 | C9: PLN-00028 DUCT BANKS | D9: 403 UG DUCT BANK | E9: 345 | F9: 2310
B10: EL-403-003 | C10: PLN-00027 DUCT BANKS | D10: 403 UG DUCT BANK | E10: 155 | F10: 1088
B11: EL-404-001 | C11: PLN-00028 DUCT BANKS | D11: 404 UG DUCT BANK | E11: 318 | F11: 2240
B15: Grounding drawings | E15: Man Hours | F15: LF.
B16: GND-200-001 | E16: 57 | F16: 206
B17: GND-200-002 | E17: 201 | F17: 728
B18: GND-401-001 | E18: 169 | F18: 613
B19: GND-401-002 | E19: 432 | F19: 1564
B20: GND-402-001 | F20: 959.92
B21: GND-402-002 | F21: 2929.17
B22: GND-404-001 | F22: 1026.04
B23: GND-601-001
B24: GND-601-002
