Workbook

Sheet excel_output - 2025-12-05T14592
A1: REC_NO | B1: DWG | C1: REV_NO | D1: SCHED_ID | E1: CAREA | F1: CODE | G1: SYSTEM | H1: LINE_AREA | I1: SPOOL_FR | J1: SZE | K1: FLD_QTY | L1: UOM | M1: FLD_WHRS | N1: PIPE_SPEC | O1: ERN_QTY | P1: EARN_WHRS | Q1: M1_PCT | R1: M1_DESC | S1: M2_PCT | T1: M2_DESC | U1: M3_PCT | V1: M3_DESC | W1: M4_PCT | X1: M4_DESC | Y1: M5_PCT | Z1: M5_DESC | AA1: M6_PCT | AB1: M6_DESC | AC1: M7_PCT | AD1: M7_DESC | AE1: M8_PCT | AF1: M8_DESC | AG1: TEST_PKG1 | AH1: CWP | AI1: IWP_PLAN_NO | AJ1: SPL_CNT | AK1: IWP_FOREMAN | AL1: IWP_GEN_FOREMAN | AM1: WHRS_UNIT | AN1: M1 | AO1: M2 | AP1: M3 | AQ1: M4 | AR1: M5 | AS1: M6 | AT1: M7 | AU1: M8 | AV1: VAR_AREA | AW1: PAINT_SPEC | AX1: INSU_SPEC | AY1: HEAT_TRACE_SPEC | AZ1: TA_BANK | BA1: TA_BAY | BB1: TA_LEVEL | BC1: PSLIP
A2: 1 | B2: 120-DR-590-SHT01 | C2: 0 | D2: CN-2760 | E2: SITE DRAIN SYS SLOP TANK UN# 2 | F2: 08331 | G2: DR | H2: UG | I2: 120-DR-590-SHT01-1 | J2: 02 | K2: 136 | L2: LF | M2: =_xlfn.XLOOKUP(F2, 'Sheet12.10.25'!C:C, 'Sheet12.10.25'!F:F, "")*K2 -> 695.912 | N2: 01HDPE | R2: Receive | T2: Stage | V2: Erect | X2: Connect | Z2: Jeep/Trace | AB2: Mech. Sell Off | AD2: Test | AF2: Post | AI2: PI-402-002 | AJ2: 1 | AK2: Bob | AN2: 0.02 | AO2: 0.03 | AP2: 0.2 | AQ2: 0.3 | AR2: 0.1 | AS2: 0.1 | AT2: 0.15 | AU2: 0.1 | AV2: 120 | AW2: N/A | AX2: N/A | AY2: N/A
A3: 2 | B3: 120-DR-590-SHT02 | C3: 0 | D3: CN-2760 | E3: SITE DRAIN SYS SLOP TANK UN# 2 | F3: 08331 | G3: DR | H3: UG | I3: 120-DR-590-SHT02-1 | J3: 02 | K3: 217 | L3: LF | M3: =_xlfn.XLOOKUP(F3, 'Sheet12.10.25'!C:C, 'Sheet12.10.25'!F:F, "")*K3 -> 1110.389 | N3: 01HDPE | R3: Receive | T3: Stage | V3: Erect | X3: Connect | Z3: Jeep/Trace | AB3: Mech. Sell Off | AD3: Test | AF3: Post | AI3: PI-402-002 | AJ3: 1 | AK3: Jose | AN3: 0.02 | AO3: 0.03 | AP3: 0.2 | AQ3: 0.3 | AR3: 0.1 | AS3: 0.1 | AT3: 0.15 | AU3: 0.1 | AV3: 120 | AW3: N/A | AX3: N/A | AY3: N/A
A4: 3 | B4: 120-DR-591-SHT01 | C4: 0 | D4: CN-2760 | E4: DRAIN SYS TO SLOP TANK UN# 3 | F4: 08331 | G4: DR | H4: UG | I4: 120-DR-591-SHT01-1 | J4: 02 | K4: 142 | L4: LF | M4: =_xlfn.XLOOKUP(F4, 'Sheet12.10.25'!C:C, 'Sheet12.10.25'!F:F, "")*K4 -> 726.614 | N4: 01HDPE | R4: Receive | T4: Stage | V4: Erect | X4: Connect | Z4: Jeep/Trace | AB4: Mech. Sell Off | AD4: Test | AF4: Post | AI4: PI-403-002 | AJ4: 1 | AK4: Juan | AN4: 0.02 | AO4: 0.03 | AP4: 0.2 | AQ4: 0.3 | AR4: 0.1 | AS4: 0.1 | AT4: 0.15 | AU4: 0.1 | AV4: 403 | AW4: N/A | AX4: N/A | AY4: N/A
A5: 4 | B5: 120-DR-591-SHT02 | C5: 0 | D5: CN-2760 | E5: DRAIN SYS TO SLOP TANK UN# 3 | F5: 08331 | G5: DR | H5: UG | I5: 120-DR-591-SHT02-1 | J5: 02 | K5: 222 | L5: LF | M5: =_xlfn.XLOOKUP(F5, 'Sheet12.10.25'!C:C, 'Sheet12.10.25'!F:F, "")*K5 -> 1135.974 | N5: 01HDPE | R5: Receive | T5: Stage | V5: Erect | X5: Connect | Z5: Jeep/Trace | AB5: Mech. Sell Off | AD5: Test | AF5: Post | AI5: PI-403-002 | AJ5: 1 | AK5: Jerry | AN5: 0.02 | AO5: 0.03 | AP5: 0.2 | AQ5: 0.3 | AR5: 0.1 | AS5: 0.1 | AT5: 0.15 | AU5: 0.1 | AV5: 403 | AW5: N/A | AX5: N/A | AY5: N/A
A6: 5 | B6: 120-GTD-501-SHT01 | C6: 0 | D6: CN-2880 | E6: SITE DRAIN SYS SLOP TANK PKG3 UN# 1 | F6: 08331 | G6: GTD | H6: UG | I6: 120-GTD-501-SHT01-1 | J6: 02 | K6: 5 | L6: LF | M6: =_xlfn.XLOOKUP(F6, 'Sheet12.10.25'!C:C, 'Sheet12.10.25'!F:F, "")*K6 -> 25.585 | N6: 01HDPE | R6: Receive | T6: Stage | V6: Erect | X6: Connect | Z6: Jeep/Trace | AB6: Mech. Sell Off | AD6: Test | AF6: Post | AI6: PI-401-007 | AJ6: 1 | AK6: Sandra | AN6: 0.02 | AO6: 0.03 | AP6: 0.2 | AQ6: 0.3 | AR6: 0.1 | AS6: 0.1 | AT6: 0.15 | AU6: 0.1 | AV6: 401 | AW6: N/A | AX6: N/A | AY6: N/A
A7: 6 | B7: 120-GTD-501-SHT01 | C7: 0 | D7: CN-2880 | E7: SITE DRAIN SYS SLOP TANK PKG3 UN# 1 | F7: 08332 | G7: GTD | H7: UG | I7: 120-GTD-501-SHT01-2 | J7: 06 | K7: 27 | L7: LF | M7: =_xlfn.XLOOKUP(F7, 'Sheet12.10.25'!C:C, 'Sheet12.10.25'!F:F, "")*K7 -> 131.733 | N7: 01HDPE | R7: Receive | T7: Stage | V7: Erect | X7: Connect | Z7: Jeep/Trace | AB7: Mech. Sell Off | AD7: Test | AF7: Post | AI7: PI-401-007 | AJ7: 1 | AK7: Bob | AN7: 0.02 | AO7: 0.03 | AP7: 0.2 | AQ7: 0.3 | AR7: 0.1 | AS7: 0.1 | AT7: 0.15 | AU7: 0.1 | AV7: 401 | AW7: N/A | AX7: N/A | AY7: N/A
A8: 7 | B8: 120-GTD-501-SHT02 | C8: 0 | D8: CN-2880 | E8: SITE DRAIN SYS SLOP TANK PKG3 UN# 1 | F8: 08331 | G8: GTD | H8: UG | I8: 120-GTD-501-SHT02-1 | J8: 02 | K8: 7 | L8: LF | M8: =_xlfn.XLOOKUP(F8, 'Sheet12.10.25'!C:C, 'Sheet12.10.25'!F:F, "")*K8 -> 35.819 | N8: 01HDPE | R8: Receive | T8: Stage | V8: Erect | X8: Connect | Z8: Jeep/Trace | AB8: Mech. Sell Off | AD8: Test | AF8: Post | AI8: PI-401-007 | AJ8: 1 | AK8: Jose | AN8: 0.02 | AO8: 0.03 | AP8: 0.2 | AQ8: 0.3 | AR8: 0.1 | AS8: 0.1 | AT8: 0.15 | AU8: 0.1 | AV8: 401 | AW8: N/A | AX8: N/A | AY8: N/A
A9: 8 | B9: 120-GTD-501-SHT02 | C9: 0 | D9: CN-2880 | E9: SITE DRAIN SYS SLOP TANK PKG3 UN# 1 | F9: 08332 | G9: GTD | H9: UG | I9: 120-GTD-501-SHT02-2 | J9: 06 | K9: 14 | L9: LF | M9: =_xlfn.XLOOKUP(F9, 'Sheet12.10.25'!C:C, 'Sheet12.10.25'!F:F, "")*K9 -> 68.306 | N9: 01HDPE | R9: Receive | T9: Stage | V9: Erect | X9: Connect | Z9: Jeep/Trace | AB9: Mech. Sell Off | AD9: Test | AF9: Post | AI9: PI-401-007 | AJ9: 1 | AK9: Jose | AN9: 0.02 | AO9: 0.03 | AP9: 0.2 | AQ9: 0.3 | AR9: 0.1 | AS9: 0.1 | AT9: 0.15 | AU9: 0.1 | AV9: 401 | AW9: N/A | AX9: N/A | AY9: N/A
A10: 9 | B10: 120-GTD-501-SHT03 | C10: 0 | D10: CN-2880 | E10: SITE DRAIN SYS SLOP TANK PKG3 UN# 1 | F10: 08331 | G10: GTD | H10: UG | I10: 120-GTD-501-SHT03-1 | J10: 02 | K10: 3 | L10: LF | M10: =_xlfn.XLOOKUP(F10, 'Sheet12.10.25'!C:C, 'Sheet12.10.25'!F:F, "")*K10 -> 15.351 | N10: 01HDPE | R10: Receive | T10: Stage | V10: Erect | X10: Connect | Z10: Jeep/Trace | AB10: Mech. Sell Off | AD10: Test | AF10: Post | AI10: PI-401-007 | AJ10: 1 | AK10: Juan | AN10: 0.02 | AO10: 0.03 | AP10: 0.2 | AQ10: 0.3 | AR10: 0.1 | AS10: 0.1 | AT10: 0.15 | AU10: 0.1 | AV10: 401 | AW10: N/A | AX10: N/A | AY10: N/A
A11: 10 | B11: 120-GTD-501-SHT03 | C11: 0 | D11: CN-2880 | E11: SITE DRAIN SYS SLOP TANK PKG3 UN# 1 | F11: 08332 | G11: GTD | H11: UG | I11: 120-GTD-501-SHT03-2 | J11: 06 | K11: 29 | L11: LF | M11: =_xlfn.XLOOKUP(F11, 'Sheet12.10.25'!C:C, 'Sheet12.10.25'!F:F, "")*K11 -> 141.491 | N11: 01HDPE | R11: Receive | T11: Stage | V11: Erect | X11: Connect | Z11: Jeep/Trace | AB11: Mech. Sell Off | AD11: Test | AF11: Post | AI11: PI-401-007 | AJ11: 1 | AK11: Juan | AN11: 0.02 | AO11: 0.03 | AP11: 0.2 | AQ11: 0.3 | AR11: 0.1 | AS11: 0.1 | AT11: 0.15 | AU11: 0.1 | AV11: 401 | AW11: N/A | AX11: N/A | AY11: N/A
A12: 11 | B12: 120-GTD-501-SHT04 | C12: 0 | D12: CN-2880 | E12: SITE DRAIN SYS SLOP TANK PKG3 UN# 1 | F12: 08332 | G12: GTD | H12: UG | I12: 120-GTD-501-SHT04-1 | J12: 06 | K12: 126 | L12: LF | M12: =_xlfn.XLOOKUP(F12, 'Sheet12.10.25'!C:C, 'Sheet12.10.25'!F:F, "")*K12 -> 614.754 | N12: 01HDPE | R12: Receive | T12: Stage | V12: Erect | X12: Connect | Z12: Jeep/Trace | AB12: Mech. Sell Off | AD12: Test | AF12: Post | AI12: PI-401-007 | AJ12: 1 | AK12: Juan | AN12: 0.02 | AO12: 0.03 | AP12: 0.2 | AQ12: 0.3 | AR12: 0.1 | AS12: 0.1 | AT12: 0.15 | AU12: 0.1 | AV12: 401 | AW12: N/A | AX12: N/A | AY12: N/A
A13: 12 | B13: 120-GTD-519-SHT01 | C13: 0 | D13: CN-2880 | E13: FUEL SYS PIPE UN# 2 | F13: 08331 | G13: GTD | H13: UG | I13: 120-GTD-519-SHT01-1 | J13: 02 | K13: 7 | L13: LF | M13: =_xlfn.XLOOKUP(F13, 'Sheet12.10.25'!C:C, 'Sheet12.10.25'!F:F, "")*K13 -> 35.819 | N13: 01HDPE | R13: Receive | T13: Stage | V13: Erect | X13: Connect | Z13: Jeep/Trace | AB13: Mech. Sell Off | AD13: Test | AF13: Post | AI13: PI-402-003 | AJ13: 1 | AK13: Jerry | AN13: 0.02 | AO13: 0.03 | AP13: 0.2 | AQ13: 0.3 | AR13: 0.1 | AS13: 0.1 | AT13: 0.15 | AU13: 0.1 | AV13: 120 | AW13: N/A | AX13: N/A | AY13: N/A
... A21: 20 | B21: 120-GTD-537-SHT02 | C21: 0 | D21: CN-2880 | E21: DRAIN SYS TO SLOP TANK UN# 3 | F21: 08331 | G21: GTD | H21: UG | I21: 120-GTD-537-SHT02-1 | J21: 02 | K21: 9 | L21: LF | M21: =_xlfn.XLOOKUP(F21, 'Sheet12.10.25'!C:C, 'Sheet12.10.25'!F:F, "")*K21 -> 46.053 | N21: 01HDPE | R21: Receive | T21: Stage | V21: Erect | X21: Connect | Z21: Jeep/Trace | AB21: Mech. Sell Off | AD21: Test | AF21: Post | AI21: PI-403-003 | AJ21: 1 | AK21: Sandra | AN21: 0.02 | AO21: 0.03 | AP21: 0.2 | AQ21: 0.3 | AR21: 0.1 | AS21: 0.1 | AT21: 0.15 | AU21: 0.1 | AV21: 403 | AW21: N/A | AX21: N/A | AY21: N/A
A22: 21 | B22: 120-GTD-537-SHT02 | E22: DRAIN SYS TO SLOP TANK UN# 3 | F22: 08332 | G22: GTD | H22: UG | I22: 120-GTD-537-SHT02-2 | J22: 06 | K22: 20 | L22: LF | M22: =_xlfn.XLOOKUP(F22, 'Sheet12.10.25'!C:C, 'Sheet12.10.25'!F:F, "")*K22 -> 97.58 | N22: 01HDPE | R22: Receive | T22: Stage | V22: Erect | X22: Connect | Z22: Jeep/Trace | AB22: Mech. Sell Off | AD22: Test | AF22: Post | AI22: PI-403-003 | AJ22: 1 | AN22: 0.02 | AO22: 0.03 | AP22: 0.2 | AQ22: 0.3 | AR22: 0.1 | AS22: 0.1 | AT22: 0.15 | AU22: 0.1 | AV22: 403 | AW22: N/A | AX22: N/A | AY22: N/A
A23: 22 | B23: 120-GTD-537-SHT03 | C23: 0 | D23: CN-2880 | E23: DRAIN SYS TO SLOP TANK UN# 3 | F23: 08331 | G23: GTD | H23: UG | I23: 120-GTD-537-SHT03-1 | J23: 02 | K23: 3 | L23: LF | M23: =_xlfn.XLOOKUP(F23, 'Sheet12.10.25'!C:C, 'Sheet12.10.25'!F:F, "")*K23 -> 15.351 | N23: 01HDPE | R23: Receive | T23: Stage | V23: Erect | X23: Connect | Z23: Jeep/Trace | AB23: Mech. Sell Off | AD23: Test | AF23: Post | AI23: PI-403-003 | AJ23: 1 | AK23: Bob | AN23: 0.02 | AO23: 0.03 | AP23: 0.2 | AQ23: 0.3 | AR23: 0.1 | AS23: 0.1 | AT23: 0.15 | AU23: 0.1 | AV23: 403 | AW23: N/A | AX23: N/A | AY23: N/A
A24: 23 | B24: 120-GTD-537-SHT03 | E24: DRAIN SYS TO SLOP TANK UN# 3 | F24: 08332 | G24: GTD | H24: UG | I24: 120-GTD-537-SHT03-1 | J24: 06 | K24: 126 | L24: LF | M24: =_xlfn.XLOOKUP(F24, 'Sheet12.10.25'!C:C, 'Sheet12.10.25'!F:F, "")*K24 -> 614.754 | N24: 01HDPE | R24: Receive | T24: Stage | V24: Erect | X24: Connect | Z24: Jeep/Trace | AB24: Mech. Sell Off | AD24: Test | AF24: Post | AI24: PI-403-003 | AJ24: 1 | AN24: 0.02 | AO24: 0.03 | AP24: 0.2 | AQ24: 0.3 | AR24: 0.1 | AS24: 0.1 | AT24: 0.15 | AU24: 0.1 | AV24: 403 | AW24: N/A | AX24: N/A | AY24: N/A
A25: 24 | B25: 120-GTD-537-SHT04 | C25: 0 | D25: CN-2880 | E25: DRAIN SYS TO SLOP TANK UN# 3 | F25: 08332 | G25: GTD | H25: UG | I25: 120-GTD-537-SHT04-1 | J25: 06 | K25: 39 | L25: LF | M25: =_xlfn.XLOOKUP(F25, 'Sheet12.10.25'!C:C, 'Sheet12.10.25'!F:F, "")*K25 -> 190.281 | N25: 01HDPE | R25: Receive | T25: Stage | V25: Erect | X25: Connect | Z25: Jeep/Trace | AB25: Mech. Sell Off | AD25: Test | AF25: Post | AI25: PI-403-003 | AJ25: 1 | AK25: Jose | AN25: 0.02 | AO25: 0.03 | AP25: 0.2 | AQ25: 0.3 | AR25: 0.1 | AS25: 0.1 | AT25: 0.15 | AU25: 0.1 | AV25: 403 | AW25: N/A | AX25: N/A | AY25: N/A
A26: 25 | B26: 120-IA-1210-SHT01 | C26: 0 | D26: CN-2910 | E26: SERVICE AIR PIPE UN# 1 | F26: 08211 | G26: IA | H26: UG | I26: 120-IA-1210-SHT01-1 | J26: 02 | K26: 91 | L26: LF | M26: =_xlfn.XLOOKUP(F26, 'Sheet12.10.25'!C:C, 'Sheet12.10.25'!F:F, "")*K26 -> 227.409 | N26: 01CS150 | R26: Receive | T26: Stage | V26: Erect | X26: Connect | Z26: Supts | AB26: Punch | AD26: Test | AF26: Post | AI26: PI-401-014 | AJ26: 1 | AK26: Juan | AN26: 0.02 | AO26: 0.03 | AP26: 0.2 | AQ26: 0.3 | AR26: 0.1 | AS26: 0.1 | AT26: 0.15 | AU26: 0.1 | AV26: 401 | AW26: CTSU1000-D011 | AX26: N/A | AY26: N/A
A27: 26 | B27: 120-IA-1210-SHT02 | C27: 0 | D27: CN-2910 | E27: SERVICE AIR PIPE UN# 1 | F27: 08211 | G27: IA | H27: UG | I27: 120-IA-1210-SHT02-1 | J27: 02 | K27: 34 | L27: LF | M27: =_xlfn.XLOOKUP(F27, 'Sheet12.10.25'!C:C, 'Sheet12.10.25'!F:F, "")*K27 -> 84.966 | N27: 01CS150 | R27: Receive | T27: Stage | V27: Erect | X27: Connect | Z27: Supts | AB27: Punch | AD27: Test | AF27: Post | AI27: PI-401-014 | AJ27: 1 | AK27: Jerry | AN27: 0.02 | AO27: 0.03 | AP27: 0.2 | AQ27: 0.3 | AR27: 0.1 | AS27: 0.1 | AT27: 0.15 | AU27: 0.1 | AV27: 401 | AW27: CTSU1000-D011 | AX27: N/A | AY27: N/A
A28: 27 | B28: 120-IA-1210-SHT03 | C28: 0 | D28: CN-2910 | E28: SERVICE AIR PIPE UN# 1 | F28: 08211 | G28: IA | H28: UG | I28: 120-IA-1210-SHT03-1 | J28: 02 | K28: 110 | L28: LF | M28: =_xlfn.XLOOKUP(F28, 'Sheet12.10.25'!C:C, 'Sheet12.10.25'!F:F, "")*K28 -> 274.89 | N28: 01CS150 | R28: Receive | T28: Stage | V28: Erect | X28: Connect | Z28: Supts | AB28: Punch | AD28: Test | AF28: Post | AI28: PI-401-014 | AJ28: 1 | AK28: Sandra | AN28: 0.02 | AO28: 0.03 | AP28: 0.2 | AQ28: 0.3 | AR28: 0.1 | AS28: 0.1 | AT28: 0.15 | AU28: 0.1 | AV28: 401 | AW28: CTSU1000-D011 | AX28: N/A | AY28: N/A
A29: 28 | B29: 120-IA-1210-SHT04 | C29: 0 | D29: CN-2910 | E29: SERVICE AIR PIPE UN# 1 | F29: 08211 | G29: IA | H29: UG | I29: 120-IA-1210-SHT04-1 | J29: 02 | K29: 66 | L29: LF | M29: =_xlfn.XLOOKUP(F29, 'Sheet12.10.25'!C:C, 'Sheet12.10.25'!F:F, "")*K29 -> 164.934 | N29: 01CS150 | R29: Receive | T29: Stage | V29: Erect | X29: Connect | Z29: Supts | AB29: Punch | AD29: Test | AF29: Post | AI29: PI-401-014 | AJ29: 1 | AK29: Bob | AN29: 0.02 | AO29: 0.03 | AP29: 0.2 | AQ29: 0.3 | AR29: 0.1 | AS29: 0.1 | AT29: 0.15 | AU29: 0.1 | AV29: 401 | AW29: CTSU1000-D011 | AX29: N/A | AY29: N/A
A30: 29 | B30: 120-IA-1210-SHT05 | C30: 0 | D30: CN-2910 | E30: SERVICE AIR PIPE UN# 1 | F30: 08211 | G30: IA | H30: UG | I30: 120-IA-1210-SHT05-1 | J30: 02 | K30: 54 | L30: LF | M30: =_xlfn.XLOOKUP(F30, 'Sheet12.10.25'!C:C, 'Sheet12.10.25'!F:F, "")*K30 -> 134.946 | N30: 01CS150 | R30: Receive | T30: Stage | V30: Erect | X30: Connect | Z30: Supts | AB30: Punch | AD30: Test | AF30: Post | AI30: PI-401-014 | AJ30: 1 | AK30: Jose | AN30: 0.02 | AO30: 0.03 | AP30: 0.2 | AQ30: 0.3 | AR30: 0.1 | AS30: 0.1 | AT30: 0.15 | AU30: 0.1 | AV30: 401 | AW30: CTSU1000-D011 | AX30: N/A | AY30: N/A
A31: 30 | B31: 120-IA-1230-SHT01 | C31: 0 | D31: CN-2910 | F31: 08211 | G31: IA | H31: UG | I31: 120-IA-1230-SHT01-1 | J31: 02 | K31: 43 | L31: LF | M31: =_xlfn.XLOOKUP(F31, 'Sheet12.10.25'!C:C, 'Sheet12.10.25'!F:F, "")*K31 -> 107.457 | N31: 01CS150 | R31: Receive | T31: Stage | V31: Erect | X31: Connect | Z31: Supts | AB31: Punch | AD31: Test | AF31: Post | AI31: UNASSIGNED | AJ31: 1 | AK31: Juan | AN31: 0.02 | AO31: 0.03 | AP31: 0.2 | AQ31: 0.3 | AR31: 0.1 | AS31: 0.1 | AT31: 0.15 | AU31: 0.1 | AV31: 120 | AW31: CTCE1000-D014 | AX31: N/A | AY31: N/A
A32: 31 | B32: 120-IA-1230-SHT02 | C32: 0 | D32: CN-2910 | E32: SERVICE AIR PIPE UN# 3 | F32: 08211 | G32: IA | H32: UG | I32: 120-IA-1230-SHT02-1 | J32: 02 | K32: 92 | L32: LF | M32: =_xlfn.XLOOKUP(F32, 'Sheet12.10.25'!C:C, 'Sheet12.10.25'!F:F, "")*K32 -> 229.908 | N32: 01CS150 | R32: Receive | T32: Stage | V32: Erect | X32: Connect | Z32: Supts | AB32: Punch | AD32: Test | AF32: Post | AI32: PI-403-008 | AJ32: 1 | AK32: Jerry | AN32: 0.02 | AO32: 0.03 | AP32: 0.2 | AQ32: 0.3 | AR32: 0.1 | AS32: 0.1 | AT32: 0.15 | AU32: 0.1 | AV32: 403 | AW32: CTSU1000-D011 | AX32: N/A | AY32: N/A
A33: 32 | B33: 120-IA-1230-SHT03 | C33: 0 | D33: CN-2910 | E33: SERVICE AIR PIPE UN# 3 | F33: 08211 | G33: IA | H33: UG | I33: 120-IA-1230-SHT03-1 | J33: 02 | K33: 51 | L33: LF | M33: =_xlfn.XLOOKUP(F33, 'Sheet12.10.25'!C:C, 'Sheet12.10.25'!F:F, "")*K33 -> 127.449 | N33: 01CS150 | R33: Receive | T33: Stage | V33: Erect | X33: Connect | Z33: Supts | AB33: Punch | AD33: Test | AF33: Post | AI33: PI-403-008 | AJ33: 1 | AK33: Sandra | AN33: 0.02 | AO33: 0.03 | AP33: 0.2 | AQ33: 0.3 | AR33: 0.1 | AS33: 0.1 | AT33: 0.15 | AU33: 0.1 | AV33: 403 | AW33: CTSU1000-D011 | AX33: N/A | AY33: N/A
A34: 33 | B34: 120-IA-1230-SHT04 | C34: 0 | D34: CN-2910 | E34: SERVICE AIR PIPE UN# 3 | F34: 08211 | G34: IA | H34: UG | I34: 120-IA-1230-SHT04-1 | J34: 02 | K34: 33 | L34: LF | M34: =_xlfn.XLOOKUP(F34, 'Sheet12.10.25'!C:C, 'Sheet12.10.25'!F:F, "")*K34 -> 82.467 | N34: 01CS150 | R34: Receive | T34: Stage | V34: Erect | X34: Connect | Z34: Supts | AB34: Punch | AD34: Test | AF34: Post | AI34: PI-403-008 | AJ34: 1 | AK34: Bob | AN34: 0.02 | AO34: 0.03 | AP34: 0.2 | AQ34: 0.3 | AR34: 0.1 | AS34: 0.1 | AT34: 0.15 | AU34: 0.1 | AV34: 403 | AW34: CTSU1000-D011 | AX34: N/A | AY34: N/A
A35: 34 | B35: 120-IA-1230-SHT05 | C35: 0 | D35: CN-2910 | E35: SERVICE AIR PIPE UN# 3 | F35: 08211 | G35: IA | H35: UG | I35: 120-IA-1230-SHT05-1 | J35: 02 | K35: 53 | L35: LF | M35: =_xlfn.XLOOKUP(F35, 'Sheet12.10.25'!C:C, 'Sheet12.10.25'!F:F, "")*K35 -> 132.447 | N35: 01CS150 | R35: Receive | T35: Stage | V35: Erect | X35: Connect | Z35: Supts | AB35: Punch | AD35: Test | AF35: Post | AI35: PI-403-008 | AJ35: 1 | AK35: Jose | AN35: 0.02 | AO35: 0.03 | AP35: 0.2 | AQ35: 0.3 | AR35: 0.1 | AS35: 0.1 | AT35: 0.15 | AU35: 0.1 | AV35: 403 | AW35: CTSU1000-D011 | AX35: N/A | AY35: N/A
A36: 35 | B36: 120-IA-1230-SHT06 | E36: SERVICE AIR PIPE UN# 3 | F36: 08211 | G36: IA | H36: UG | I36: 120-IA-1230-SHT06-1 | J36: 02 | K36: 43 | L36: LF | M36: =_xlfn.XLOOKUP(F36, 'Sheet12.10.25'!C:C, 'Sheet12.10.25'!F:F, "")*K36 -> 107.457 | N36: 01CS150 | R36: Receive | T36: Stage | V36: Erect | X36: Connect | Z36: Supts | AB36: Punch | AD36: Test | AF36: Post | AI36: PI-403-008 | AJ36: 1 | AN36: 0.02 | AO36: 0.03 | AP36: 0.2 | AQ36: 0.3 | AR36: 0.1 | AS36: 0.1 | AT36: 0.15 | AU36: 0.1 | AV36: 403 | AW36: CTSU1000-D011 | AX36: N/A | AY36: N/A
A37: 36 | B37: 120-GCW-802-SHT01 | C37: 0 | D37: CN-2850 | E37: GCW SYS PIPE UN# 1 | F37: 08332 | G37: GCW | H37: UG | I37: 120-GCW-802-SHT01-1 | J37: 08 | K37: 179 | L37: LF | M37: =_xlfn.XLOOKUP(F37, 'Sheet12.10.25'!C:C, 'Sheet12.10.25'!F:F, "")*K37 -> 873.341 | N37: 01HDPE | R37: Receive | T37: Stage | V37: Erect | X37: Connect | Z37: Jeep/Trace | AB37: Mech. Sell Off | AD37: Test | AF37: Post | AI37: PI-401-009 | AJ37: 1 | AK37: Juan | AN37: 0.02 | AO37: 0.03 | AP37: 0.2 | AQ37: 0.3 | AR37: 0.1 | AS37: 0.1 | AT37: 0.15 | AU37: 0.1 | AV37: 401 | AW37: N/A | AX37: N/A | AY37: N/A
A38: 37 | B38: 120-GCW-802-SHT02 | C38: 0 | D38: CN-2850 | F38: 08332 | G38: GCW | H38: UG | I38: 120-GCW-802-SHT02-1 | J38: 08 | K38: 21 | L38: LF | M38: =_xlfn.XLOOKUP(F38, 'Sheet12.10.25'!C:C, 'Sheet12.10.25'!F:F, "")*K38 -> 102.459 | N38: 01HDPE | R38: Receive | T38: Stage | V38: Erect | X38: Connect | Z38: Jeep/Trace | AB38: Mech. Sell Off | AD38: Test | AF38: Post | AI38: UNASSIGNED | AJ38: 1 | AK38: Jerry | AN38: 0.02 | AO38: 0.03 | AP38: 0.2 | AQ38: 0.3 | AR38: 0.1 | AS38: 0.1 | AT38: 0.15 | AU38: 0.1 | AV38: 401 | AW38: N/A | AX38: N/A | AY38: N/A
A39: 38 | B39: 120-IA-1227-SHT01 | C39: 0 | D39: CN-2910 | E39: SERVICE AIR PIPE UN# 2 | F39: 08211 | G39: IA | H39: UG | I39: 120-IA-1227-SHT01-1 | J39: 02 | K39: 66 | L39: LF | M39: =_xlfn.XLOOKUP(F39, 'Sheet12.10.25'!C:C, 'Sheet12.10.25'!F:F, "")*K39 -> 164.934 | N39: 01CS150 | R39: Receive | T39: Stage | V39: Erect | X39: Connect | Z39: Supts | AB39: Punch | AD39: Test | AF39: Post | AI39: PI-402-008 | AJ39: 1 | AK39: Sandra | AN39: 0.02 | AO39: 0.03 | AP39: 0.2 | AQ39: 0.3 | AR39: 0.1 | AS39: 0.1 | AT39: 0.15 | AU39: 0.1 | AV39: 401 | AW39: CTSU1000 | AX39: N/A | AY39: N/A
A40: 39 | B40: 120-IA-1227-SHT02 | C40: 0 | D40: CN-2910 | E40: SERVICE AIR PIPE UN# 2 | F40: 08211 | G40: IA | H40: UG | I40: 120-IA-1227-SHT02-1 | J40: 02 | K40: 65 | L40: LF | M40: =_xlfn.XLOOKUP(F40, 'Sheet12.10.25'!C:C, 'Sheet12.10.25'!F:F, "")*K40 -> 162.435 | N40: 01CS150 | R40: Receive | T40: Stage | V40: Erect | X40: Connect | Z40: Supts | AB40: Punch | AD40: Test | AF40: Post | AI40: PI-402-008 | AJ40: 1 | AK40: Bob | AN40: 0.02 | AO40: 0.03 | AP40: 0.2 | AQ40: 0.3 | AR40: 0.1 | AS40: 0.1 | AT40: 0.15 | AU40: 0.1 | AV40: 120 | AW40: CTCE1000-D014 | AX40: N/A | AY40: N/A
A41: 40 | B41: 120-IA-1227-SHT03 | C41: 0 | D41: CN-2910 | E41: SERVICE AIR PIPE UN# 2 | F41: 08211 | G41: IA | H41: UG | I41: 120-IA-1227-SHT03-1 | J41: 02 | K41: 87 | L41: LF | M41: =_xlfn.XLOOKUP(F41, 'Sheet12.10.25'!C:C, 'Sheet12.10.25'!F:F, "")*K41 -> 217.413 | N41: 01CS150 | R41: Receive | T41: Stage | V41: Erect | X41: Connect | Z41: Supts | AB41: Punch | AD41: Test | AF41: Post | AI41: PI-402-008 | AJ41: 1 | AK41: Jose | AN41: 0.02 | AO41: 0.03 | AP41: 0.2 | AQ41: 0.3 | AR41: 0.1 | AS41: 0.1 | AT41: 0.15 | AU41: 0.1 | AV41: 120 | AW41: CTCE1000-D014 | AX41: N/A | AY41: N/A
A42: 41 | B42: 120-IA-1227-SHT04 | C42: 0 | D42: CN-2910 | E42: SERVICE AIR PIPE UN# 2 | F42: 08211 | G42: IA | H42: UG | I42: 120-IA-1227-SHT04-1 | J42: 02 | K42: 46 | L42: LF | M42: =_xlfn.XLOOKUP(F42, 'Sheet12.10.25'!C:C, 'Sheet12.10.25'!F:F, "")*K42 -> 114.954 | N42: 01CS150 | R42: Receive | T42: Stage | V42: Erect | X42: Connect | Z42: Supts | AB42: Punch | AD42: Test | AF42: Post | AI42: PI-402-008 | AJ42: 1 | AK42: Juan | AN42: 0.02 | AO42: 0.03 | AP42: 0.2 | AQ42: 0.3 | AR42: 0.1 | AS42: 0.1 | AT42: 0.15 | AU42: 0.1 | AV42: 120 | AW42: CTCE1000-D014 | AX42: N/A | AY42: N/A
A43: 42 | B43: 120-DR-587-SHT01 | C43: 0 | D43: CN-2760 | E43: SITE DRAIN SYS SLOP TANK PKG1 UN# 1 | F43: 08331 | G43: DR | H43: UG | I43: 120-DR-587-SHT01-1 | J43: 02 | K43: 144 | L43: LF | M43: =_xlfn.XLOOKUP(F43, 'Sheet12.10.25'!C:C, 'Sheet12.10.25'!F:F, "")*K43 -> 736.848 | N43: 01HDPE | R43: Receive | T43: Stage | V43: Erect | X43: Connect | Z43: Jeep/Trace | AB43: Mech. Sell Off | AD43: Test | AF43: Post | AI43: PI-401-005 | AJ43: 1 | AK43: Jerry | AN43: 0.02 | AO43: 0.03 | AP43: 0.2 | AQ43: 0.3 | AR43: 0.1 | AS43: 0.1 | AT43: 0.15 | AU43: 0.1 | AV43: 401 | AW43: N/A | AX43: N/A | AY43: N/A
A44: 43 | B44: 120-DR-587-SHT02 | C44: 0 | D44: CN-2760 | E44: SITE DRAIN SYS SLOP TANK PKG1 UN# 1 | F44: 08331 | G44: DR | H44: UG | I44: 120-DR-587-SHT02-1 | J44: 02 | K44: 215 | L44: LF | M44: =_xlfn.XLOOKUP(F44, 'Sheet12.10.25'!C:C, 'Sheet12.10.25'!F:F, "")*K44 -> 1100.155 | N44: 01HDPE | R44: Receive | T44: Stage | V44: Erect | X44: Connect | Z44: Jeep/Trace | AB44: Mech. Sell Off | AD44: Test | AF44: Post | AI44: PI-401-005 | AJ44: 1 | AK44: Sandra | AN44: 0.02 | AO44: 0.03 | AP44: 0.2 | AQ44: 0.3 | AR44: 0.1 | AS44: 0.1 | AT44: 0.15 | AU44: 0.1 | AV44: 401 | AW44: N/A | AX44: N/A | AY44: N/A
A45: 44 | B45: 120-NH3-2103-SHT01 | C45: 0 | D45: CN-2970 | E45: AMMONIA SYSTEM 1 UN#1,2,3 | F45: 08332 | G45: NH3 | H45: UG | I45: 120-NH3-2103-SHT01-1 | J45: 03 | K45: 104 | L45: LF | M45: =_xlfn.XLOOKUP(F45, 'Sheet12.10.25'!C:C, 'Sheet12.10.25'!F:F, "")*K45 -> 507.416 | N45: 01HDPE | R45: Receive | T45: Stage | V45: Erect | X45: Connect | Z45: Jeep/Trace | AB45: Mech. Sell Off | AD45: Test | AF45: Post | AI45: PI-401-003 | AJ45: 1 | AK45: Bob | AN45: 0.02 | AO45: 0.03 | AP45: 0.2 | AQ45: 0.3 | AR45: 0.1 | AS45: 0.1 | AT45: 0.15 | AU45: 0.1 | AV45: 401 | AW45: N/A | AX45: N/A | AY45: N/A
A46: 45 | B46: 120-NH3-2103-SHT02 | C46: 0 | D46: CN-2970 | E46: AMMONIA SYSTEM 1 UN#1,2,3 | F46: 08332 | G46: NH3 | H46: UG | I46: 120-NH3-2103-SHT02-1 | J46: 03 | K46: 399 | L46: LF | M46: =_xlfn.XLOOKUP(F46, 'Sheet12.10.25'!C:C, 'Sheet12.10.25'!F:F, "")*K46 -> 1946.721 | N46: 01HDPE | R46: Receive | T46: Stage | V46: Erect | X46: Connect | Z46: Jeep/Trace | AB46: Mech. Sell Off | AD46: Test | AF46: Post | AI46: PI-401-003 | AJ46: 1 | AK46: Jose | AN46: 0.02 | AO46: 0.03 | AP46: 0.2 | AQ46: 0.3 | AR46: 0.1 | AS46: 0.1 | AT46: 0.15 | AU46: 0.1 | AV46: 401 | AW46: N/A | AX46: N/A | AY46: N/A
A47: 46 | B47: 120-NH3-2103-SHT03 | C47: 0 | D47: CN-2970 | E47: AMMONIA SYSTEM 1 UN#1,2,3 | F47: 08332 | G47: NH3 | H47: UG | I47: 120-NH3-2103-SHT03-1 | J47: 03 | K47: 71 | L47: LF | M47: =_xlfn.XLOOKUP(F47, 'Sheet12.10.25'!C:C, 'Sheet12.10.25'!F:F, "")*K47 -> 346.409 | N47: 01HDPE | R47: Receive | T47: Stage | V47: Erect | X47: Connect | Z47: Jeep/Trace | AB47: Mech. Sell Off | AD47: Test | AF47: Post | AI47: PI-401-003 | AJ47: 1 | AK47: Juan | AN47: 0.02 | AO47: 0.03 | AP47: 0.2 | AQ47: 0.3 | AR47: 0.1 | AS47: 0.1 | AT47: 0.15 | AU47: 0.1 | AV47: 403 | AW47: N/A | AX47: N/A | AY47: N/A
...

Sheet Sheet12.10.25
A1: PF U/R | B1: Type | C1: cost code | D1: Base U/R | E1: PF Adjust | F1: PF U/R | H1: check | K1: check
A2: 2.499 | B2: Carbon Steel Field Run Pipe 2.5" and under | C2: 08211 | D2: 2.1 | E2: 1.19 | F2: =D2*E2 -> 2.499 | H2: 2.87
A3: 4.522 | B3: Carbon Steel Field Run Pipe 3" to 10" | C3: 08212 | D3: 3.8 | E3: 1.19 | F3: =D3*E3 -> 4.522 | H3: 2.51
A4: 9.52 | B4: Carbon Steel Field Run Pipe 12" and over | C4: 08213 | D4: 8 | E4: 1.19 | F4: =D4*E4 -> 9.52 | H4: 4.0457895
A5: 3.927 | B5: Stainless Steel Alloy Field Run Pipe 2.5" and under | C5: 08221 | D5: 3.3 | E5: 1.19 | F5: =D5*E5 -> 3.927 | H5: 3.41
A6: 6.902 | B6: Stainless Steel Alloy Field Run Pipe 3" to 10" | C6: 08222 | D6: 5.8 | E6: 1.19 | F6: =D6*E6 -> 6.902 | H6: 3.12
A7: 12.852 | B7: Stainless Steel Alloy Field Run Pipe 12" and over | C7: 08223 | D7: 10.8 | E7: 1.19 | F7: =D7*E7 -> 12.852 | H7: 12.08
B8: UG Speciality Matl Pipe 2.5 and under | C8: 08331 | D8: 4.3 | E8: 1.19 | F8: =D8*E8 -> 5.117 | H8: 4.3 | I8: chevron | J8: T&M
B9: U/G Speciailty Matl Pipe 3-10 | C9: 08332 | D9: 4.1 | E9: 1.19 | F9: =D9*E9 -> 4.879 | H9: 4.1 | I9: frac 14(10")5.2-10" non bathtub/4.1- 10" bathtub | K9: 4.08 | L9: chevron T&M
B10: UG Speciality Matl Pipe 2.5 and under12 and over | C10: 08333 | D10: 3.41 | E10: 1.19 | F10: =D10*E10 -> 4.0579 | H10: 3.417 | I10: hdpe 12"

Sheet Sheet1
B2: IWP | C2: CAREA | D2: Line Area | E2: Manhours | F2: Footage
B4: PI-000-001 | C4: EASTSIDE FIREWATER | D4: UG | E4: 1527 | F4: 385
B5: PI-000-002 | C5: NORTHSIDE FIREWATER | D5: UG | E5: 3684 | F5: 755
B6: PI-000-003 | C6: SOUTH FIREWATER | D6: UG | E6: 3088 | F6: 633
B7: PI-401-001 | C7: POTABLE WATER UN# 1,2,3 | D7: UG | E7: 3459 | F7: 676
B8: PI-401-002 | C8: POTABLE WATER UN# 1 | D8: UG | E8: 573 | F8: 112
B9: PI-401-003 | C9: AMMONIA SYS 1 UN#1,2,3 | D9: UG | E9: 3488 | F9: 715
B10: PI-401-004 | C10: AMMONIA SYS 2 UN# 1 | D10: UG | E10: 498 | F10: 102
B11: PI-401-005 | C11: SITE DRAIN SYS SLOP TANK PKG1 UN# 1 | D11: UG | E11: 1837 | F11: 359
B12: PI-401-006 | C12: SITE DRAIN SYS SLOP TANK PKG2 UN# 1 | D12: UG | E12: 461 | F12: 90
B13: PI-401-007 | C13: SITE DRAIN SYS SLOP TANK PKG3 UN# 1 | D13: UG | E13: 1361 | F13: 275
B14: PI-401-008 | C14: SITE UTILITIES UN# 1 | D14: UG | E14: 439 | F14: 90
B15: PI-401-009 | C15: GCW SYS PIPE UN# 1 | D15: UG | E15: 873 | F15: 179
... B40: PI-403-009 | C40: FUEL SYS PIPE UN# 3 | D40: UG | E40: 402 | F40: 89

Sheet Sheet2
B2: Discipline | C2: Prime | D2: Code | E2: Description
B3: Pipe | C3: 08 | D3: 08111 | E3: FR CS 2.5<
B4: Pipe | C4: 08 | D4: 08112 | E4: FR CS >2.5
B5: Pipe | C5: 08 | D5: 08113 | E5: Test
B6: Pipe | C6: 08 | D6: 08114 | E6: test
B7: Civil | C7: 04 | D7: 04110 | E7: test
B8: Civil | C8: 04 | D8: 04111 | E8: test
B9: Civil | C9: 04 | D9: 04112 | E9: test
B10: Civil | C10: 04 | D10: 04113 | E10: test
B11: Steel | C11: 05 | D11: 05111 | E11: test
