Workbook

Sheet Steel Audit
A1: REC_NO | B1: DWG | C1: REV_NO | D1: SCHED_ID | E1: CAREA | F1: CODE | G1: SYSTEM | H1: LINE_AREA | I1: SPOOL_FR | J1: SZE | K1: FLD_QTY | L1: FLD_WHRS | M1: UOM | N1: PIPE_SPEC | O1: ERN_QTY | P1: EARN_WHRS | Q1: M1_PCT | R1: M1_DESC | S1: M2_PCT | T1: M2_DESC | U1: M3_PCT | V1: M3_DESC | W1: M4_PCT | X1: M4_DESC | Y1: M5_PCT | Z1: M5_DESC | AA1: M6_PCT | AB1: M6_DESC | AC1: M7_PCT | AD1: M7_DESC | AE1: M8_PCT | AF1: M8_DESC | AG1: TEST_PKG1 | AH1: CWP | AI1: IWP_PLAN_NO | AJ1: SPL_CNT | AK1: IWP_FOREMAN | AL1: IWP_GEN_FOREMAN | AM1: WHRS_UNIT | AN1: M1 | AO1: M2 | AP1: M3 | AQ1: M4 | AR1: M5 | AS1: M6 | AT1: M7 | AU1: M8 | AV1: VAR_AREA | AW1: PAINT_SPEC | AX1: INSU_SPEC | AY1: HEAT_TRACE_SPEC | AZ1: TA_BANK | BA1: TA_BAY | BB1: TA_LEVEL | BC1: PSLIP
A2: 1 | B2: 1224A25-120-ST-1015 | C2: 0 | D2: *C | E2: EAST-WEST PIPERACK SEC 1 | F2: 05220 | G2: *S | H2: 100 | I2: 10001C | J2: W10X49 | K2: 1 | L2: =K2*BF2 -> 8.8439536 | M2: TN | R2: Receive | T2: Shake Out | V2: PreAssemble | X2: Erect | Z2: Bolt Up | AB2: Impact | AD2: Punch | AF2: Sell Off | AH2: HVY | AI2: ST-100-001 | AJ2: 1 | AN2: 0.05 | AO2: 0.05 | AP2: 0.15 | AQ2: 0.2 | AR2: 0.2 | AS2: 0.2 | AT2: 0.1 | AU2: 0.05 | AV2: 100 | AW2: N/A | AX2: N/A | AY2: N/A | AZ2: N/A | BA2: N/A | BB2: N/A | BC2: N/A | BD2: =Sheet1!$H$4 -> 15.735716 | BE2: 0.5620306 | BF2: =BD2*BE2 -> 8.8439536
A3: 2 | B3: 1224A25-120-ST-1015 | C3: 0 | D3: *C | E3: EAST-WEST PIPERACK SEC 1 | F3: 05220 | G3: *S | H3: 100 | I3: 10002C | J3: W10X49 | K3: 1 | L3: =K3*BF3 -> 8.8439536 | M3: TN | R3: Receive | T3: Shake Out | V3: PreAssemble | X3: Erect | Z3: Bolt Up | AB3: Impact | AD3: Punch | AF3: Sell Off | AH3: HVY | AI3: ST-100-001 | AJ3: 1 | AN3: 0.05 | AO3: 0.05 | AP3: 0.15 | AQ3: 0.2 | AR3: 0.2 | AS3: 0.2 | AT3: 0.1 | AU3: 0.05 | AV3: 100 | AW3: N/A | AX3: N/A | AY3: N/A | AZ3: N/A | BA3: N/A | BB3: N/A | BC3: N/A | BD3: =Sheet1!$H$4 -> 15.735716 | BE3: 0.5620306 | BF3: =BD3*BE3 -> 8.8439536
A4: 3 | B4: 1224A25-120-ST-1015 | C4: 0 | D4: *C | E4: EAST-WEST PIPERACK SEC 1 | F4: 05220 | G4: *S | H4: 100 | I4: 10003C | J4: W10X49 | K4: 1 | L4: =K4*BF4 -> 8.8439536 | M4: TN | R4: Receive | T4: Shake Out | V4: PreAssemble | X4: Erect | Z4: Bolt Up | AB4: Impact | AD4: Punch | AF4: Sell Off | AH4: HVY | AI4: ST-100-001 | AJ4: 1 | AN4: 0.05 | AO4: 0.05 | AP4: 0.15 | AQ4: 0.2 | AR4: 0.2 | AS4: 0.2 | AT4: 0.1 | AU4: 0.05 | AV4: 100 | AW4: N/A | AX4: N/A | AY4: N/A | AZ4: N/A | BA4: N/A | BB4: N/A | BC4: N/A | BD4: =Sheet1!$H$4 -> 15.735716 | BE4: 0.5620306 | BF4: =BD4*BE4 -> 8.8439536
A5: 4 | B5: 1224A25-120-ST-1015 | C5: 0 | D5: *C | E5: EAST-WEST PIPERACK SEC 1 | F5: 05220 | G5: *S | H5: 100 | I5: 10004C | J5: W10X49 | K5: 1 | L5: =K5*BF5 -> 8.8439536 | M5: TN | R5: Receive | T5: Shake Out | V5: PreAssemble | X5: Erect | Z5: Bolt Up | AB5: Impact | AD5: Punch | AF5: Sell Off | AH5: HVY | AI5: ST-100-001 | AJ5: 1 | AN5: 0.05 | AO5: 0.05 | AP5: 0.15 | AQ5: 0.2 | AR5: 0.2 | AS5: 0.2 | AT5: 0.1 | AU5: 0.05 | AV5: 100 | AW5: N/A | AX5: N/A | AY5: N/A | AZ5: N/A | BA5: N/A | BB5: N/A | BC5: N/A | BD5: =Sheet1!$H$4 -> 15.735716 | BE5: 0.5620306 | BF5: =BD5*BE5 -> 8.8439536
A6: 5 | B6: 1224A25-120-ST-1015 | C6: 0 | D6: *C | E6: EAST-WEST PIPERACK SEC 1 | F6: 05220 | G6: *S | H6: 100 | I6: 10005C | J6: W10X49 | K6: 1 | L6: =K6*BF6 -> 8.8439536 | M6: TN | R6: Receive | T6: Shake Out | V6: PreAssemble | X6: Erect | Z6: Bolt Up | AB6: Impact | AD6: Punch | AF6: Sell Off | AH6: HVY | AI6: ST-100-001 | AJ6: 1 | AN6: 0.05 | AO6: 0.05 | AP6: 0.15 | AQ6: 0.2 | AR6: 0.2 | AS6: 0.2 | AT6: 0.1 | AU6: 0.05 | AV6: 100 | AW6: N/A | AX6: N/A | AY6: N/A | AZ6: N/A | BA6: N/A | BB6: N/A | BC6: N/A | BD6: =Sheet1!$H$4 -> 15.735716 | BE6: 0.5620306 | BF6: =BD6*BE6 -> 8.8439536
A7: 6 | B7: 1224A25-120-ST-1015 | C7: 0 | D7: *C | E7: EAST-WEST PIPERACK SEC 1 | F7: 05220 | G7: *S | H7: 100 | I7: 10006C | J7: W10X49 | K7: 1 | L7: =K7*BF7 -> 8.8439536 | M7: TN | R7: Receive | T7: Shake Out | V7: PreAssemble | X7: Erect | Z7: Bolt Up | AB7: Impact | AD7: Punch | AF7: Sell Off | AH7: HVY | AI7: ST-100-001 | AJ7: 1 | AN7: 0.05 | AO7: 0.05 | AP7: 0.15 | AQ7: 0.2 | AR7: 0.2 | AS7: 0.2 | AT7: 0.1 | AU7: 0.05 | AV7: 100 | AW7: N/A | AX7: N/A | AY7: N/A | AZ7: N/A | BA7: N/A | BB7: N/A | BC7: N/A | BD7: =Sheet1!$H$4 -> 15.735716 | BE7: 0.5620306 | BF7: =BD7*BE7 -> 8.8439536
A8: 7 | B8: 1224A25-120-ST-1015 | C8: 0 | D8: *C | E8: EAST-WEST PIPERACK SEC 1 | F8: 05220 | G8: *S | H8: 100 | I8: 10007C | J8: W10X49 | K8: 1 | L8: =K8*BF8 -> 8.8439536 | M8: TN | R8: Receive | T8: Shake Out | V8: PreAssemble | X8: Erect | Z8: Bolt Up | AB8: Impact | AD8: Punch | AF8: Sell Off | AH8: HVY | AI8: ST-100-001 | AJ8: 1 | AN8: 0.05 | AO8: 0.05 | AP8: 0.15 | AQ8: 0.2 | AR8: 0.2 | AS8: 0.2 | AT8: 0.1 | AU8: 0.05 | AV8: 100 | AW8: N/A | AX8: N/A | AY8: N/A | AZ8: N/A | BA8: N/A | BB8: N/A | BC8: N/A | BD8: =Sheet1!$H$4 -> 15.735716 | BE8: 0.5620306 | BF8: =BD8*BE8 -> 8.8439536
A9: 8 | B9: 1224A25-120-ST-1015 | C9: 0 | D9: *C | E9: EAST-WEST PIPERACK SEC 1 | F9: 05220 | G9: *S | H9: 100 | I9: 10008C | J9: W10X49 | K9: 1 | L9: =K9*BF9 -> 8.8439536 | M9: TN | R9: Receive | T9: Shake Out | V9: PreAssemble | X9: Erect | Z9: Bolt Up | AB9: Impact | AD9: Punch | AF9: Sell Off | AH9: HVY | AI9: ST-100-001 | AJ9: 1 | AN9: 0.05 | AO9: 0.05 | AP9: 0.15 | AQ9: 0.2 | AR9: 0.2 | AS9: 0.2 | AT9: 0.1 | AU9: 0.05 | AV9: 100 | AW9: N/A | AX9: N/A | AY9: N/A | AZ9: N/A | BA9: N/A | BB9: N/A | BC9: N/A | BD9: =Sheet1!$H$4 -> 15.735716 | BE9: 0.5620306 | BF9: =BD9*BE9 -> 8.8439536
A10: 9 | B10: 1224A25-120-ST-1015 | C10: 0 | D10: *C | E10: EAST-WEST PIPERACK SEC 1 | F10: 05220 | G10: *S | H10: 100 | I10: 10009C | J10: W10 | K10: 1 | L10: =K10*BF10 -> 12.462687 | M10: TN | R10: Receive | T10: Shake Out | V10: PreAssemble | X10: Erect | Z10: Bolt Up | AB10: Impact | AD10: Punch | AF10: Sell Off | AH10: HVY | AI10: ST-100-001 | AJ10: 1 | AN10: 0.05 | AO10: 0.05 | AP10: 0.15 | AQ10: 0.2 | AR10: 0.2 | AS10: 0.2 | AT10: 0.1 | AU10: 0.05 | AV10: 100 | AW10: N/A | AX10: N/A | AY10: N/A | AZ10: N/A | BA10: N/A | BB10: N/A | BC10: N/A | BD10: =Sheet1!$H$4 -> 15.735716 | BE10: 0.792 | BF10: =BD10*BE10 -> 12.462687
A11: 10 | B11: 1224A25-120-ST-1015 | C11: 0 | D11: *C | E11: EAST-WEST PIPERACK SEC 1 | F11: 05220 | G11: *S | H11: 100 | I11: 10010C | J11: W10 | K11: 1 | L11: =K11*BF11 -> 12.462687 | M11: TN | R11: Receive | T11: Shake Out | V11: PreAssemble | X11: Erect | Z11: Bolt Up | AB11: Impact | AD11: Punch | AF11: Sell Off | AH11: HVY | AI11: ST-100-001 | AJ11: 1 | AN11: 0.05 | AO11: 0.05 | AP11: 0.15 | AQ11: 0.2 | AR11: 0.2 | AS11: 0.2 | AT11: 0.1 | AU11: 0.05 | AV11: 100 | AW11: N/A | AX11: N/A | AY11: N/A | AZ11: N/A | BA11: N/A | BB11: N/A | BC11: N/A | BD11: =Sheet1!$H$4 -> 15.735716 | BE11: 0.792 | BF11: =BD11*BE11 -> 12.462687
A12: 11 | B12: 1224A25-120-ST-1015 | C12: 0 | D12: *C | E12: EAST-WEST PIPERACK SEC 1 | F12: 05220 | G12: *S | H12: 100 | I12: 11010A | J12: WT5X11 | K12: 4 | L12: =K12*BF12 -> 4.7743888 | M12: TN | R12: Receive | T12: Shake Out | V12: PreAssemble | X12: Erect | Z12: Bolt Up | AB12: Impact | AD12: Punch | AF12: Sell Off | AH12: LGHT | AI12: ST-100-001 | AJ12: 1 | AN12: 0.05 | AO12: 0.05 | AP12: 0.15 | AQ12: 0.2 | AR12: 0.2 | AS12: 0.2 | AT12: 0.1 | AU12: 0.05 | AV12: 100 | AW12: N/A | AX12: N/A | AY12: N/A | AZ12: N/A | BA12: N/A | BB12: N/A | BC12: N/A | BD12: =Sheet1!$H$2 -> 21.859554 | BE12: 0.054603 | BF12: =BD12*BE12 -> 1.1935972
A13: 12 | B13: 1224A25-120-ST-1015 | C13: 0 | D13: *C | E13: EAST-WEST PIPERACK SEC 1 | F13: 05220 | G13: *S | H13: 100 | I13: 11011A | J13: WT5X11 | K13: 2 | L13: =K13*BF13 -> 2.3871944 | M13: TN | R13: Receive | T13: Shake Out | V13: PreAssemble | X13: Erect | Z13: Bolt Up | AB13: Impact | AD13: Punch | AF13: Sell Off | AH13: LGHT | AI13: ST-100-001 | AJ13: 1 | AN13: 0.05 | AO13: 0.05 | AP13: 0.15 | AQ13: 0.2 | AR13: 0.2 | AS13: 0.2 | AT13: 0.1 | AU13: 0.05 | AV13: 100 | AW13: N/A | AX13: N/A | AY13: N/A | AZ13: N/A | BA13: N/A | BB13: N/A | BC13: N/A | BD13: =Sheet1!$H$2 -> 21.859554 | BE13: 0.054603 | BF13: =BD13*BE13 -> 1.1935972
A14: 13 | B14: 1224A25-120-ST-1015 | C14: 0 | D14: *C | E14: EAST-WEST PIPERACK SEC 1 | F14: 05220 | G14: *S | H14: 100 | I14: 11017B TYPE 1 | K14: 1 | L14: =K14*BF14 -> 31.432092 | M14: TN | R14: Receive | T14: Shake Out | V14: PreAssemble | X14: Erect | Z14: Bolt Up | AB14: Impact | AD14: Punch | AF14: Sell Off | AH14: HVY | AI14: ST-100-001 | AJ14: 1 | AN14: 0.05 | AO14: 0.05 | AP14: 0.15 | AQ14: 0.2 | AR14: 0.2 | AS14: 0.2 | AT14: 0.1 | AU14: 0.05 | AV14: 100 | AW14: N/A | AX14: N/A | AY14: N/A | AZ14: N/A | BA14: N/A | BB14: N/A | BC14: N/A | BD14: =Sheet1!$H$4 -> 15.735716 | BE14: 1.9975 | BF14: =BD14*BE14 -> 31.432092
A15: 14 | B15: 12224A25-120-ST-1022 | C15: 0 | D15: *C | E15: EAST-WEST PIPERACK SEC 1 | F15: 05220 | G15: *S | H15: 100 | I15: 12001B | J15: W10X26 | K15: 24 | L15: =K15*BF15 -> 100.76981 | M15: TN | R15: Receive | T15: Shake Out | V15: PreAssemble | X15: Erect | Z15: Bolt Up | AB15: Impact | AD15: Punch | AF15: Sell Off | AH15: MED | AI15: ST-100-001 | AJ15: 1 | AN15: 0.05 | AO15: 0.05 | AP15: 0.15 | AQ15: 0.2 | AR15: 0.2 | AS15: 0.2 | AT15: 0.1 | AU15: 0.05 | AV15: 100 | AW15: N/A | AX15: N/A | AY15: N/A | AZ15: N/A | BA15: N/A | BB15: N/A | BC15: N/A | BD15: =Sheet1!$H$3 -> 18.948477 | BE15: 0.2215873 | BF15: =BD15*BE15 -> 4.1987419
A16: 15 | B16: 1224A25-120-ST-1015 | C16: 0 | D16: *C | E16: EAST-WEST PIPERACK SEC 1 | F16: 05220 | G16: *S | H16: 100 | I16: 12002B | J16: W10X26 | K16: 15 | L16: =K16*BF16 -> 62.981129 | M16: TN | R16: Receive | T16: Shake Out | V16: PreAssemble | X16: Erect | Z16: Bolt Up | AB16: Impact | AD16: Punch | AF16: Sell Off | AH16: MED | AI16: ST-100-001 | AJ16: 1 | AN16: 0.05 | AO16: 0.05 | AP16: 0.15 | AQ16: 0.2 | AR16: 0.2 | AS16: 0.2 | AT16: 0.1 | AU16: 0.05 | AV16: 100 | AW16: N/A | AX16: N/A | AY16: N/A | AZ16: N/A | BA16: N/A | BB16: N/A | BC16: N/A | BD16: =Sheet1!$H$3 -> 18.948477 | BE16: 0.2215873 | BF16: =BD16*BE16 -> 4.1987419
A17: 16 | B17: 1224A25-120-ST-1015 | C17: 0 | D17: *C | E17: EAST-WEST PIPERACK SEC 1 | F17: 05220 | G17: *S | H17: 100 | I17: 12003B | J17: W10X26 | K17: 2 | L17: =K17*BF17 -> 8.3974838 | M17: TN | R17: Receive | T17: Shake Out | V17: PreAssemble | X17: Erect | Z17: Bolt Up | AB17: Impact | AD17: Punch | AF17: Sell Off | AH17: MED | AI17: ST-100-001 | AJ17: 1 | AN17: 0.05 | AO17: 0.05 | AP17: 0.15 | AQ17: 0.2 | AR17: 0.2 | AS17: 0.2 | AT17: 0.1 | AU17: 0.05 | AV17: 100 | AW17: N/A | AX17: N/A | AY17: N/A | AZ17: N/A | BA17: N/A | BB17: N/A | BC17: N/A | BD17: =Sheet1!$H$3 -> 18.948477 | BE17: 0.2215873 | BF17: =BD17*BE17 -> 4.1987419
A18: 17 | B18: 1224A25-120-ST-1015 | C18: 0 | D18: *C | E18: EAST-WEST PIPERACK SEC 1 | F18: 05220 | G18: *S | H18: 100 | I18: 12006B | J18: W10X26 | K18: 2 | L18: =K18*BF18 -> 8.3974838 | M18: TN | AH18: MED | AI18: ST-100-001 | AJ18: 1 | AN18: 0.05 | AO18: 0.05 | AP18: 0.15 | AQ18: 0.2 | AR18: 0.2 | AS18: 0.2 | AT18: 0.1 | AU18: 0.05 | AV18: 100 | AW18: N/A | AX18: N/A | AY18: N/A | AZ18: N/A | BA18: N/A | BB18: N/A | BC18: N/A | BD18: =Sheet1!$H$3 -> 18.948477 | BE18: 0.2215873 | BF18: =BD18*BE18 -> 4.1987419
A19: 18 | B19: 12224A25-120-ST-1015 | C19: 0 | D19: *C | E19: EAST-WEST PIPERACK SEC 1 | F19: 05220 | G19: *S | H19: 100 | I19: 12010B | J19: W10X26 | K19: 5 | L19: =K19*BF19 -> 20.99371 | M19: TN | R19: Receive | T19: Shake Out | V19: PreAssemble | X19: Erect | Z19: Bolt Up | AB19: Impact | AD19: Punch | AF19: Sell Off | AH19: MED | AI19: ST-100-001 | AJ19: 1 | AN19: 0.05 | AO19: 0.05 | AP19: 0.15 | AQ19: 0.2 | AR19: 0.2 | AS19: 0.2 | AT19: 0.1 | AU19: 0.05 | AV19: 100 | AW19: N/A | AX19: N/A | AY19: N/A | AZ19: N/A | BA19: N/A | BB19: N/A | BC19: N/A | BD19: =Sheet1!$H$3 -> 18.948477 | BE19: 0.2215873 | BF19: =BD19*BE19 -> 4.1987419
A20: 19 | B20: 1224A25-120-ST-1015 | C20: 0 | E20: EAST-WEST PIPERACK SEC 1 | F20: 05220 | G20: *S | H20: 100 | I20: 20001C | J20: W10X49 | K20: 1 | L20: =K20*BF20 -> 8.8439536 | M20: TN | R20: Receive | T20: Shake Out | V20: PreAssemble | X20: Erect | Z20: Bolt Up | AB20: Impact | AD20: Punch | AF20: Sell Off | AH20: HVY | AI20: ST-100-001 | AJ20: 1 | AN20: 0.05 | AO20: 0.05 | AP20: 0.15 | AQ20: 0.2 | AR20: 0.2 | AS20: 0.2 | AT20: 0.1 | AU20: 0.05 | AV20: 100 | AW20: N/A | AX20: N/A | AY20: N/A | AZ20: N/A | BA20: N/A | BB20: N/A | BC20: N/A | BD20: =Sheet1!$H$4 -> 15.735716 | BE20: 0.5620306 | BF20: =BD20*BE20 -> 8.8439536
A21: 20 | B21: 1224A25-120-ST-1015 | C21: 0 | D21: *C | E21: EAST-WEST PIPERACK SEC 1 | F21: 05220 | G21: *S | H21: 100 | I21: 20002C | J21: W10X49 | K21: 1 | L21: =K21*BF21 -> 8.8439536 | M21: TN | R21: Receive | T21: Shake Out | V21: PreAssemble | X21: Erect | Z21: Bolt Up | AB21: Impact | AD21: Punch | AF21: Sell Off | AH21: HVY | AI21: ST-100-001 | AJ21: 1 | AN21: 0.05 | AO21: 0.05 | AP21: 0.15 | AQ21: 0.2 | AR21: 0.2 | AS21: 0.2 | AT21: 0.1 | AU21: 0.05 | AV21: 100 | AW21: N/A | AX21: N/A | AY21: N/A | AZ21: N/A | BA21: N/A | BB21: N/A | BC21: N/A | BD21: =Sheet1!$H$4 -> 15.735716 | BE21: 0.5620306 | BF21: =BD21*BE21 -> 8.8439536
A22: 21 | B22: 1224A25-120-ST-1015 | C22: 0 | D22: *C | E22: EAST-WEST PIPERACK SEC 1 | F22: 05220 | G22: *S | H22: 100 | I22: 20003C | J22: W10X49 | K22: 1 | L22: =K22*BF22 -> 8.8439536 | M22: TN | R22: Receive | T22: Shake Out | V22: PreAssemble | X22: Erect | Z22: Bolt Up | AB22: Impact | AD22: Punch | AF22: Sell Off | AH22: HVY | AI22: ST-100-001 | AJ22: 1 | AN22: 0.05 | AO22: 0.05 | AP22: 0.15 | AQ22: 0.2 | AR22: 0.2 | AS22: 0.2 | AT22: 0.1 | AU22: 0.05 | AV22: 100 | AW22: N/A | AX22: N/A | AY22: N/A | AZ22: N/A | BA22: N/A | BB22: N/A | BC22: N/A | BD22: =Sheet1!$H$4 -> 15.735716 | BE22: 0.5620306 | BF22: =BD22*BE22 -> 8.8439536
A23: 22 | B23: 1224A25-120-ST-1015 | C23: 0 | D23: *C | E23: EAST-WEST PIPERACK SEC 1 | F23: 05220 | G23: *S | H23: 100 | I23: 20004C | J23: W10X49 | K23: 1 | L23: =K23*BF23 -> 8.8439536 | M23: TN | R23: Receive | T23: Shake Out | V23: PreAssemble | X23: Erect | Z23: Bolt Up | AB23: Impact | AD23: Punch | AF23: Sell Off | AH23: HVY | AI23: ST-100-001 | AJ23: 1 | AN23: 0.05 | AO23: 0.05 | AP23: 0.15 | AQ23: 0.2 | AR23: 0.2 | AS23: 0.2 | AT23: 0.1 | AU23: 0.05 | AV23: 100 | AW23: N/A | AX23: N/A | AY23: N/A | AZ23: N/A | BA23: N/A | BB23: N/A | BC23: N/A | BD23: =Sheet1!$H$4 -> 15.735716 | BE23: 0.5620306 | BF23: =BD23*BE23 -> 8.8439536
A24: 23 | B24: 1224A25-120-ST-1015 | C24: 0 | D24: *C | E24: EAST-WEST PIPERACK SEC 1 | F24: 05220 | G24: *S | H24: 100 | I24: 20005C | J24: W10X49 | K24: 1 | L24: =K24*BF24 -> 8.8439536 | M24: TN | R24: Receive | T24: Shake Out | V24: PreAssemble | X24: Erect | Z24: Bolt Up | AB24: Impact | AD24: Punch | AF24: Sell Off | AH24: HVY | AI24: ST-100-001 | AJ24: 1 | AN24: 0.05 | AO24: 0.05 | AP24: 0.15 | AQ24: 0.2 | AR24: 0.2 | AS24: 0.2 | AT24: 0.1 | AU24: 0.05 | AV24: 100 | AW24: N/A | AX24: N/A | AY24: N/A | AZ24: N/A | BA24: N/A | BB24: N/A | BC24: N/A | BD24: =Sheet1!$H$4 -> 15.735716 | BE24: 0.5620306 | BF24: =BD24*BE24 -> 8.8439536
A25: 24 | B25: 1224A25-120-ST-1015 | C25: 0 | D25: *C | E25: EAST-WEST PIPERACK SEC 1 | F25: 05220 | G25: *S | H25: 100 | I25: 20006C | J25: W10X49 | K25: 1 | L25: =K25*BF25 -> 8.8439536 | M25: TN | R25: Receive | T25: Shake Out | V25: PreAssemble | X25: Erect | Z25: Bolt Up | AB25: Impact | AD25: Punch | AF25: Sell Off | AH25: HVY | AI25: ST-100-001 | AJ25: 1 | AN25: 0.05 | AO25: 0.05 | AP25: 0.15 | AQ25: 0.2 | AR25: 0.2 | AS25: 0.2 | AT25: 0.1 | AU25: 0.05 | AV25: 100 | AW25: N/A | AX25: N/A | AY25: N/A | AZ25: N/A | BA25: N/A | BB25: N/A | BC25: N/A | BD25: =Sheet1!$H$4 -> 15.735716 | BE25: 0.5620306 | BF25: =BD25*BE25 -> 8.8439536
A26: 25 | B26: 1224A25-120-ST-1015 | C26: 0 | D26: *C | E26: EAST-WEST PIPERACK SEC 1 | F26: 05220 | G26: *S | H26: 100 | I26: 20007C | J26: W10X49 | K26: 1 | L26: =K26*BF26 -> 8.8439536 | M26: TN | R26: Receive | T26: Shake Out | V26: PreAssemble | X26: Erect | Z26: Bolt Up | AB26: Impact | AD26: Punch | AF26: Sell Off | AH26: HVY | AI26: ST-100-001 | AJ26: 1 | AN26: 0.05 | AO26: 0.05 | AP26: 0.15 | AQ26: 0.2 | AR26: 0.2 | AS26: 0.2 | AT26: 0.1 | AU26: 0.05 | AV26: 100 | AW26: N/A | AX26: N/A | AY26: N/A | AZ26: N/A | BA26: N/A | BB26: N/A | BC26: N/A | BD26: =Sheet1!$H$4 -> 15.735716 | BE26: 0.5620306 | BF26: =BD26*BE26 -> 8.8439536
A27: 26 | B27: 1224A25-120-ST-1015 | C27: 0 | D27: *C | E27: EAST-WEST PIPERACK SEC 1 | F27: 05220 | G27: *S | H27: 100 | I27: 20008C | J27: W10X49 | K27: 1 | L27: =K27*BF27 -> 8.8439536 | M27: TN | R27: Receive | T27: Shake Out | V27: PreAssemble | X27: Erect | Z27: Bolt Up | AB27: Impact | AD27: Punch | AF27: Sell Off | AH27: HVY | AI27: ST-100-001 | AJ27: 1 | AN27: 0.05 | AO27: 0.05 | AP27: 0.15 | AQ27: 0.2 | AR27: 0.2 | AS27: 0.2 | AT27: 0.1 | AU27: 0.05 | AV27: 100 | AW27: N/A | AX27: N/A | AY27: N/A | AZ27: N/A | BA27: N/A | BB27: N/A | BC27: N/A | BD27: =Sheet1!$H$4 -> 15.735716 | BE27: 0.5620306 | BF27: =BD27*BE27 -> 8.8439536
A28: 27 | B28: 1224A25-120-ST-1015 | C28: 0 | D28: *C | E28: EAST-WEST PIPERACK SEC 1 | F28: 05220 | G28: *S | H28: 100 | I28: 20009C | J28: W10 | K28: 1 | L28: =K28*BF28 -> 12.462687 | M28: TN | R28: Receive | T28: Shake Out | V28: PreAssemble | X28: Erect | Z28: Bolt Up | AB28: Impact | AD28: Punch | AF28: Sell Off | AH28: HVY | AI28: ST-100-001 | AJ28: 1 | AN28: 0.05 | AO28: 0.05 | AP28: 0.15 | AQ28: 0.2 | AR28: 0.2 | AS28: 0.2 | AT28: 0.1 | AU28: 0.05 | AV28: 100 | AW28: N/A | AX28: N/A | AY28: N/A | AZ28: N/A | BA28: N/A | BB28: N/A | BC28: N/A | BD28: =Sheet1!$H$4 -> 15.735716 | BE28: 0.792 | BF28: =BD28*BE28 -> 12.462687
A29: 28 | B29: 1224A25-120-ST-1015 | C29: 0 | D29: *C | E29: EAST-WEST PIPERACK SEC 1 | F29: 05220 | G29: *S | H29: 100 | I29: 20010C | J29: W10 | K29: 1 | L29: =K29*BF29 -> 12.462687 | M29: TN | R29: Receive | T29: Shake Out | V29: PreAssemble | X29: Erect | Z29: Bolt Up | AB29: Impact | AD29: Punch | AF29: Sell Off | AH29: HVY | AI29: ST-100-001 | AJ29: 1 | AN29: 0.05 | AO29: 0.05 | AP29: 0.15 | AQ29: 0.2 | AR29: 0.2 | AS29: 0.2 | AT29: 0.1 | AU29: 0.05 | AV29: 100 | AW29: N/A | AX29: N/A | AY29: N/A | AZ29: N/A | BA29: N/A | BB29: N/A | BC29: N/A | BD29: =Sheet1!$H$4 -> 15.735716 | BE29: 0.792 | BF29: =BD29*BE29 -> 12.462687
A30: 29 | B30: 1224A25-120-ST-1015 | C30: 0 | D30: *C | E30: EAST-WEST PIPERACK SEC 1 | F30: 05220 | G30: *S | H30: 100 | I30: 22016B TYPE 2 | K30: 1 | L30: =K30*BF30 -> 31.432092 | M30: TN | R30: Receive | T30: Shake Out | V30: PreAssemble | X30: Erect | Z30: Bolt Up | AB30: Impact | AD30: Punch | AF30: Sell Off | AH30: HVY | AI30: ST-100-001 | AJ30: 1 | AN30: 0.05 | AO30: 0.05 | AP30: 0.15 | AQ30: 0.2 | AR30: 0.2 | AS30: 0.2 | AT30: 0.1 | AU30: 0.05 | AV30: 100 | AW30: N/A | AX30: N/A | AY30: N/A | AZ30: N/A | BA30: N/A | BB30: N/A | BC30: N/A | BD30: =Sheet1!$H$4 -> 15.735716 | BE30: 1.9975 | BF30: =BD30*BE30 -> 31.432092
A31: 30 | B31: 1224A25-120-ST-1015 | C31: 0 | D31: *C | E31: EAST-WEST PIPERACK SEC 1 | F31: 05220 | G31: *S | H31: 100 | I31: 13000PL | K31: 4 | L31: =K31*BF31 -> 0.92116159 | M31: TN | AH31: LGHT | AI31: ST-100-001 | AJ31: 1 | AN31: 0.05 | AO31: 0.05 | AP31: 0.15 | AQ31: 0.2 | AR31: 0.2 | AS31: 0.2 | AT31: 0.1 | AU31: 0.05 | AV31: 100 | AW31: N/A | AX31: N/A | AY31: N/A | AZ31: N/A | BA31: N/A | BB31: N/A | BC31: N/A | BD31: =Sheet1!$H$2 -> 21.859554 | BE31: 0.010535 | BF31: =BD31*BE31 -> 0.2302904
A32: 31 | B32: 12224A25-120-ST-1016 | C32: 0 | D32: *C | E32: EAST-WEST PIPERACK SEC 2 | F32: 05220 | G32: *S | H32: 100 | I32: 10011C | J32: W10X49 | K32: 1 | L32: =K32*BF32 -> 8.8439536 | M32: TN | R32: Receive | T32: Shake Out | V32: PreAssemble | X32: Erect | Z32: Bolt Up | AB32: Impact | AD32: Punch | AF32: Sell Off | AH32: HVY | AI32: ST-100-002 | AJ32: 1 | AN32: 0.05 | AO32: 0.05 | AP32: 0.15 | AQ32: 0.2 | AR32: 0.2 | AS32: 0.2 | AT32: 0.1 | AU32: 0.05 | AV32: 100 | AW32: N/A | AX32: N/A | AY32: N/A | AZ32: N/A | BA32: N/A | BB32: N/A | BC32: N/A | BD32: =Sheet1!$H$4 -> 15.735716 | BE32: 0.5620306 | BF32: =BD32*BE32 -> 8.8439536
A33: 32 | B33: 12224A25-120-ST-1016 | C33: 0 | D33: *C | E33: EAST-WEST PIPERACK SEC 2 | F33: 05220 | G33: *S | H33: 100 | I33: 10012C | J33: W10X49 | K33: 1 | L33: =K33*BF33 -> 8.8439536 | M33: TN | R33: Receive | T33: Shake Out | V33: PreAssemble | X33: Erect | Z33: Bolt Up | AB33: Impact | AD33: Punch | AF33: Sell Off | AH33: HVY | AI33: ST-100-002 | AJ33: 1 | AN33: 0.05 | AO33: 0.05 | AP33: 0.15 | AQ33: 0.2 | AR33: 0.2 | AS33: 0.2 | AT33: 0.1 | AU33: 0.05 | AV33: 100 | AW33: N/A | AX33: N/A | AY33: N/A | AZ33: N/A | BA33: N/A | BB33: N/A | BC33: N/A | BD33: =Sheet1!$H$4 -> 15.735716 | BE33: 0.5620306 | BF33: =BD33*BE33 -> 8.8439536
A34: 33 | B34: 12224A25-120-ST-1016 | C34: 0 | D34: *C | E34: EAST-WEST PIPERACK SEC 2 | F34: 05220 | G34: *S | H34: 100 | I34: 10013C | J34: W10X49 | K34: 1 | L34: =K34*BF34 -> 8.8439536 | M34: TN | R34: Receive | T34: Shake Out | V34: PreAssemble | X34: Erect | Z34: Bolt Up | AB34: Impact | AD34: Punch | AF34: Sell Off | AH34: HVY | AI34: ST-100-002 | AJ34: 1 | AN34: 0.05 | AO34: 0.05 | AP34: 0.15 | AQ34: 0.2 | AR34: 0.2 | AS34: 0.2 | AT34: 0.1 | AU34: 0.05 | AV34: 100 | AW34: N/A | AX34: N/A | AY34: N/A | AZ34: N/A | BA34: N/A | BB34: N/A | BC34: N/A | BD34: =Sheet1!$H$4 -> 15.735716 | BE34: 0.5620306 | BF34: =BD34*BE34 -> 8.8439536
A35: 34 | B35: 12224A25-120-ST-1016 | C35: 0 | D35: *C | E35: EAST-WEST PIPERACK SEC 2 | F35: 05220 | G35: *S | H35: 100 | I35: 10014C | J35: W10X49 | K35: 1 | L35: =K35*BF35 -> 8.8439536 | M35: TN | R35: Receive | T35: Shake Out | V35: PreAssemble | X35: Erect | Z35: Bolt Up | AB35: Impact | AD35: Punch | AF35: Sell Off | AH35: HVY | AI35: ST-100-002 | AJ35: 1 | AN35: 0.05 | AO35: 0.05 | AP35: 0.15 | AQ35: 0.2 | AR35: 0.2 | AS35: 0.2 | AT35: 0.1 | AU35: 0.05 | AV35: 100 | AW35: N/A | AX35: N/A | AY35: N/A | AZ35: N/A | BA35: N/A | BB35: N/A | BC35: N/A | BD35: =Sheet1!$H$4 -> 15.735716 | BE35: 0.5620306 | BF35: =BD35*BE35 -> 8.8439536
A36: 35 | B36: 12224A25-120-ST-1016 | C36: 0 | D36: *C | E36: EAST-WEST PIPERACK SEC 2 | F36: 05220 | G36: *S | H36: 100 | I36: 10015C | J36: W10X49 | K36: 1 | L36: =K36*BF36 -> 8.8439536 | M36: TN | R36: Receive | T36: Shake Out | V36: PreAssemble | X36: Erect | Z36: Bolt Up | AB36: Impact | AD36: Punch | AF36: Sell Off | AH36: HVY | AI36: ST-100-002 | AJ36: 1 | AN36: 0.05 | AO36: 0.05 | AP36: 0.15 | AQ36: 0.2 | AR36: 0.2 | AS36: 0.2 | AT36: 0.1 | AU36: 0.05 | AV36: 100 | AW36: N/A | AX36: N/A | AY36: N/A | AZ36: N/A | BA36: N/A | BB36: N/A | BC36: N/A | BD36: =Sheet1!$H$4 -> 15.735716 | BE36: 0.5620306 | BF36: =BD36*BE36 -> 8.8439536
A37: 36 | B37: 12224A25-120-ST-1016 | C37: 0 | D37: *C | E37: EAST-WEST PIPERACK SEC 2 | F37: 05220 | G37: *S | H37: 100 | I37: 10016C | J37: W10X49 | K37: 1 | L37: =K37*BF37 -> 8.8439536 | M37: TN | R37: Receive | T37: Shake Out | V37: PreAssemble | X37: Erect | Z37: Bolt Up | AB37: Impact | AD37: Punch | AF37: Sell Off | AH37: HVY | AI37: ST-100-002 | AJ37: 1 | AN37: 0.05 | AO37: 0.05 | AP37: 0.15 | AQ37: 0.2 | AR37: 0.2 | AS37: 0.2 | AT37: 0.1 | AU37: 0.05 | AV37: 100 | AW37: N/A | AX37: N/A | AY37: N/A | AZ37: N/A | BA37: N/A | BB37: N/A | BC37: N/A | BD37: =Sheet1!$H$4 -> 15.735716 | BE37: 0.5620306 | BF37: =BD37*BE37 -> 8.8439536
A38: 37 | B38: 12224A25-120-ST-1016 | C38: 0 | D38: *C | E38: EAST-WEST PIPERACK SEC 2 | F38: 05220 | G38: *S | H38: 100 | I38: 10017C | J38: W10X49 | K38: 1 | L38: =K38*BF38 -> 8.8439536 | M38: TN | R38: Receive | T38: Shake Out | V38: PreAssemble | X38: Erect | Z38: Bolt Up | AB38: Impact | AD38: Punch | AF38: Sell Off | AH38: HVY | AI38: ST-100-002 | AJ38: 1 | AN38: 0.05 | AO38: 0.05 | AP38: 0.15 | AQ38: 0.2 | AR38: 0.2 | AS38: 0.2 | AT38: 0.1 | AU38: 0.05 | AV38: 100 | AW38: N/A | AX38: N/A | AY38: N/A | AZ38: N/A | BA38: N/A | BB38: N/A | BC38: N/A | BD38: =Sheet1!$H$4 -> 15.735716 | BE38: 0.5620306 | BF38: =BD38*BE38 -> 8.8439536
A39: 38 | B39: 12224A25-120-ST-1016 | C39: 0 | D39: *C | E39: EAST-WEST PIPERACK SEC 2 | F39: 05220 | G39: *S | H39: 100 | I39: 10018C | J39: W10 | K39: 1 | L39: =K39*BF39 -> 12.462687 | M39: TN | R39: Receive | T39: Shake Out | V39: PreAssemble | X39: Erect | Z39: Bolt Up | AB39: Impact | AD39: Punch | AF39: Sell Off | AH39: HVY | AI39: ST-100-002 | AJ39: 1 | AN39: 0.05 | AO39: 0.05 | AP39: 0.15 | AQ39: 0.2 | AR39: 0.2 | AS39: 0.2 | AT39: 0.1 | AU39: 0.05 | AV39: 100 | AW39: N/A | AX39: N/A | AY39: N/A | AZ39: N/A | BA39: N/A | BB39: N/A | BC39: N/A | BD39: =Sheet1!$H$4 -> 15.735716 | BE39: 0.792 | BF39: =BD39*BE39 -> 12.462687
A40: 39 | B40: 12224A25-120-ST-1016 | C40: 0 | D40: *C | E40: EAST-WEST PIPERACK SEC 2 | F40: 05220 | G40: *S | H40: 100 | I40: 10019C | J40: W10 | K40: 1 | L40: =K40*BF40 -> 12.462687 | M40: TN | R40: Receive | T40: Shake Out | V40: PreAssemble | X40: Erect | Z40: Bolt Up | AB40: Impact | AD40: Punch | AF40: Sell Off | AH40: HVY | AI40: ST-100-002 | AJ40: 1 | AN40: 0.05 | AO40: 0.05 | AP40: 0.15 | AQ40: 0.2 | AR40: 0.2 | AS40: 0.2 | AT40: 0.1 | AU40: 0.05 | AV40: 100 | AW40: N/A | AX40: N/A | AY40: N/A | AZ40: N/A | BA40: N/A | BB40: N/A | BC40: N/A | BD40: =Sheet1!$H$4 -> 15.735716 | BE40: 0.792 | BF40: =BD40*BE40 -> 12.462687
...

Sheet Sheet2
B2: IWP | C2: CAREA | D2: Line Area | E2: Manhours | F2: Footage
B4: ST-100-001 | C4: EAST-WEST PIPERACK SEC 1 | D4: 100 | E4: 464
B5: ST-100-002 | C5: EAST-WEST PIPERACK SEC 2 (BENT 01-108 THRU 01-114) | D5: 100 | E5: 459
B6: ST-100-003 | C6: EAST-WEST PIPERACK SEC 3 (BENT 01-115 THRU 01-121) | D6: 100 | E6: 417
B7: ST-100-004 | C7: EAST-WEST PIPERACK SEC 4 (BENT 01-122 THRU 01-128) | D7: 100 | E7: 385
B8: ST-100-005 | C8: EAST-WEST PIPE BRIDGE 1 (PB 01-101 THRU 01-102) | D8: 100 | E8: 99
B9: ST-100-006 | C9: EAST-WEST PIPE BRIDGE 2 (PB 02-101 THRU 02-102) | D9: 100 | E9: 99
B10: ST-100-007 | C10: EAST-WEST PIPE BRIDGE 3 (PB 03-101 THRU 02-103) | D10: 100 | E10: 99
B11: ST-100-008 | C11: MCC BUILDING PIPERACK (MC 01-101 THRU 01-107) | D11: 404 | E11: 87
B12: ST-200-001 | C12: NORTH-SOUTH PIPERACK SEC 1 (BENT 02-201 THRU 02-203) | D12: 200 | E12: 227
B13: ST-200-002 | C13: NORTH-SOUTH PIPERACK SEC 2 (BENT 01-201 THRU 02-206) | D13: 200 | E13: 291
B14: ST-200-003 | C14: NORTH-SOUTH PIPERACK SEC 3 (BENT 01-207 THRU 02-217) | D14: 200 | E14: 421
B15: ST-200-004 | C15: NORTH -SOUTH BRIDGE 1 (PB 04-201 THRU 04-202) | D15: 200 | E15: 99
... B18: ST-300-003 | C18: NORTH- SOUTH PIPE BRIDGE 1 (PB 05-301 THRU 05-302) | D18: 300 | E18: 99

Sheet Sheet1
B1: Type | C1: Cost Code | D1: Base U/R | E1: PF Adjust | F1: PF U/R | H1: check
B2: Structural- LIGHT | C2: 05220 | D2: 26.363636 | E2: 1.19 | F2: =D2*E2 -> 31.372727 | H2: 21.859554
B3: Structural-MEDUIM | C3: 05220 | D3: 23.636364 | E3: 1.19 | F3: =D3*E3 -> 28.127273 | H3: 18.948477
B4: Structural-HEAVY | C4: 05220 | D4: 20 | E4: 1.19 | F4: =D4*E4 -> 23.8 | H4: 15.735716
