Workbook
Name \M: #REF!
Name \M: #REF!
Name AC: #REF!
Name AC: #REF!
Name ACC: #REF!
Name ACC: #REF!
Name ACT: #REF!
Name ACT: #REF!
Name AQ: #REF!
Name AQ: #REF!
Name BC: #REF!
Name BC: #REF!
Name BQ: #REF!
Name BQ: #REF!
Name CLASS: #REF!
Name CLASS: #REF!
Name cmc: #REF!
Name cmc: #REF!
Name cmc_backup: #REF!
Name cmc_backup: #REF!
Name contingency: #REF!
Name contingency: #REF!
Name contingency_backup: #REF!
Name contingency_backup: #REF!
Name CONTRACT: #REF!
Name CONTRACT: #REF!
Name Cum_Comm: [2]Sheet1!$AP$87:$CD$93
Name DO_LABOR: #REF!
Name DO_LABOR: #REF!
Name DO_LABOR_BACKUP: #REF!
Name DO_LABOR_BACKUP: #REF!
Name DO_MATERIAL: #REF!
Name DO_MATERIAL: #REF!
Name DO_MATERIAL_BACKUP: #REF!
Name DO_MATERIAL_BACKUP: #REF!
Name DO_OTHER: #REF!
Name DO_OTHER: #REF!
Name DO_OTHER_BACKUP: #REF!
Name DO_OTHER_BACKUP: #REF!
Name DO_PLANTEQUIP: #REF!
Name DO_PLANTEQUIP: #REF!
Name DO_PLANTEQUIP_BACKUP: #REF!
Name DO_PLANTEQUIP_BACKUP: #REF!
Name DO_SUBCONTRACTS: #REF!
Name DO_SUBCONTRACTS: #REF!
Name DO_SUBCONTRACTS_BACKUP: #REF!
Name DO_SUBCONTRACTS_BACKUP: #REF!
Name errors: [3]WARNINGS!$C$31
Name escalation: #REF!
Name escalation: #REF!
Name escalation_backup: #REF!
Name escalation_backup: #REF!
Name fee: #REF!
Name fee: #REF!
Name fee_backup: #REF!
Name fee_backup: #REF!
Name Gasoline_Price: 2.1
Name Incr_Comm: [2]Sheet1!$AP$79:$CD$85
Name IO_LABOR: #REF!
Name IO_LABOR: #REF!

Sheet Safety
D2: FRAME 6B POWER GROUP DAILY REPORT GENERAL CONSTRUCTION | J2: Document No.:
J3: Revision No.: | L3: 0
J4: Revision Date:
K6: DATE: | L6: 46035
B8: Safety and Personnel
B9: Safety Topic: | C9: Hot work permits,traffic and parking
B13: Safety Statistics: | D13: Direct | E13: Indirect | F13: Subcontractors | J13: Total Direct | K13: Total Indirect | L13: TOTAL
B14: (Cumm.) Work Hours | D14: =SUM('E&H - Daily Report'!D14+'Audubon - Daily Report'!D14+'RPS - Daily Report'!D14) -> 25845 | E14: =SUM('E&H - Daily Report'!E14+'Audubon - Daily Report'!E14+'RPS - Daily Report'!E14) -> 5378 | F14: =SUM('E&H - Daily Report'!F14+'Audubon - Daily Report'!F14+'RPS - Daily Report'!F14) -> 1141 | J14: =D14 -> 25845 | K14: =SUM(E14:I14) -> 6519 | L14: =SUM(J14:K14) -> 32364
B15: (Period) Safe Work Hours | D15: =SUM('E&H - Daily Report'!D15+'Audubon - Daily Report'!D15+'RPS - Daily Report'!D15) -> 1099 | E15: =SUM('E&H - Daily Report'!E15+'Audubon - Daily Report'!E15+'RPS - Daily Report'!E15) -> 147 | F15: =SUM('E&H - Daily Report'!F15+'Audubon - Daily Report'!F15+'RPS - Daily Report'!F15) -> 291 | J15: =D15 -> 1099 | K15: =SUM(E15:I15) -> 438 | L15: =SUM(J15:K15) -> 1537
B16: Total Safe Work Hours To-Date | D16: =SUM(D15+D14) -> 26944 | E16: =SUM(E15+E14) -> 5525 | F16: =SUM(F15,F14) -> 1432 | G16: =SUM(G15,G14) -> 0 | H16: =SUM(H15,H14) -> 0 | I16: =SUM(I15,I14) -> 0 | J16: =SUM(J15,J14) -> 26944 | K16: =SUM(K15,K14) -> 6957 | L16: =SUM(L14:L15) -> 33901
B18: Incidents: | D18: Period | E18: To Date | F18: Description
B19: First Aids | D19: 0 | E19: 0
B20: Incidents | D20: 0 | E20: 0 | F20: 0
B21: Recordable | D21: 0 | E21: 0
C22: Lost Time | D22: 0 | E22: 0
C23: Property Damage | D23: 0 | E23: 1
B24: Near Misses | D24: 0 | E24: 0
B26: Head Count: | D26: Craft Type | E26: Count | F26: Subcontrator
B27: Total | D27: Indirects | E27: 10 | F27: =SUM('E&H - Daily Report'!F27:F39)+'Audubon - Daily Report'!F27+'RPS - Daily Report'!F27 -> 0
B28: Total | D28: Directs | E28: 121 | F28: =SUM('E&H - Daily Report'!F40:F46)+'Audubon - Daily Report'!F28+'RPS - Daily Report'!F28 -> 1
B29: Request for additional manpower to be mobilized
B30: List trade/name, work area
B31: N/A
B33: Weather Report: MUST INCLUDE ANY IMPACT TO SCHEDULE, STANDOWNS, ETC. | D33: Monday | E33: Tuesday | F33: Wednesday | G33: Thursday | H33: Friday | I33: Saturday | J33: Sunday
B34: Date | D34: 46034 | E34: =D34+1 -> 46035 | F34: =E34+1 -> 46036 | G34: =F34+1 -> 46037 | H34: =G34+1 -> 46038 | I34: =H34+1 -> 46039 | J34: =I34+1 -> 46040
B35: Hi | D35: 63 | E35: 69
B36: Low | D36: 27 | E36: 30
C37: Rain Inches | D37: 0 | E37: 0 | F37: 0 | G37: 0 | H37: 0 | I37: 0 | J37: 0
B39: Weather: | D39: Mon | E39: Tue | F39: Wed | G39: Thu | H39: Fri | I39: Sat | J39: Sun
C40: Date | D40: 44816 | E40: =+D40+1 -> 44817 | F40: =+E40+1 -> 44818 | G40: =+F40+1 -> 44819 | H40: =+G40+1 -> 44820 | I40: =+H40+1 -> 44821 | J40: =+I40+1 -> 44822
C41: Hi | I41: NA | J41: NA
C42: Lo | I42: NA | J42: NA
C43: Rain | D43: 0 | E43: 0 | F43: 0 | G43: 0 | H43: 0 | I43: 0 | J43: 0
D44: Actuals | E44: Actuals | F44: Actuals | G44: Actuals | H44: Actuals | I44: Actuals | J44: Actuals

Sheet Field Report
D2: FRAME 6B POWER GROUP DAILY REPORT GENERAL CONSTRUCTION | J2: Document No.:
J3: Revision No.: | L3: 0
J4: Revision Date:
K6: DATE: | L6: =Safety!L6 -> 46035
B8: Schedule:
B9: Project Completion:
D10: BASELINE SCHEDULE | E10: CURRENT SCHEDULE | F10: VAR FROM SCHD (DAYS +/-) | G10: Status
C11: Award Contract | D11: 45854 | E11: 45859 | F11: =+D11-E11 -> -5
C12: Mobilization | D12: 45931 | E12: 45931 | F12: =+D12-E12 -> 0
C13: Site Work Fill and Compact Start | D13: 45982 | E13: 45973 | F13: =+D13-E13 -> 9
C14: Site Work Fill and Compact Finish | D14: 46003 | E14: 45997 | F14: 2
C15: Laydown Yard Start | D15: 45936 | E15: 45933 | F15: =+D15-E15 -> 3
C16: Laydown Yard Finish | D16: 45990 | E16: 45979 | F16: =+D16-E16 -> 11
C17: Drill Piers Start | D17: 45968 | E17: 45968 | F17: =+D17-E17 -> 0
C18: Drill Pier Finish | D18: 45987 | E18: 45982 | F18: =+D18-E18 -> 5
C19: Sill Slab Start | D19: 45975 | E19: 45971 | F19: =+D19-E19 -> 4
C20: Sill Slab Finish | D20: 45993 | E20: 45983 | F20: =+D20-E20 -> 10
C21: GT/SCR Foundations Start | D21: 45996 | E21: 45987 | F21: =+D21-E21 -> 9
C22: GT/SCR Foundations Complete | D22: 46029 | E22: 46022 | F22: =+D22-E22 -> 7
C23: Helical Piles Start | D23: 45971 | E23: 45972 | F23: =+D23-E23 -> -1
C24: Helical Piles Finish | D24: 45994 | E24: 45996 | F24: =+D24-E24 -> -2
F25: =+D25-E25 -> 0
D27: TO DATE SCHEDULED | E27: TO DATE ACTUAL | F27: VAR FROM TO DATE SCHD PCT | G27: PERCENT GAIN FOR WEEK SCHD | H27: PERCENT GAIN FOR WEEK ACTUAL
C29: UG Piping | F29: =D29-E29 -> 0 | G29: 0 | H29: 0
B30: Duct Banks | F30: =D30-E30 -> 0 | G30: 0 | H30: 0
C31: Civil | F31: =D31-E31 -> 0 | G31: 0 | H31: 0
C32: Piping / Equipment | F32: =D32-E32 -> 0 | G32: 0 | H32: 0
C33: E&I | F33: =D33-E33 -> 0 | G33: 0 | H33: 0
C34: Percent Complete Overall | F34: =D34-E34 -> 0 | G34: 0 | H34: 0
D35: =#REF! -> #REF! | E35: =#REF! -> #REF! | F35: =+E35-D35 -> #REF! | G35: =#REF! -> #REF! | H35: =#REF! -> #REF!
C36: Performance (PF = E / A ) | D36: =#REF! -> #REF! | E36: =#REF! -> #REF! | F36: =+E36-D36 -> #REF! | G36: =#REF! -> #REF! | H36: =#REF! -> #REF!
B38: Work Schedule: | D38: SCHEDULED DAYS LAST WEEK | E38: ACTUAL LAST WEEK | F38: VAR FROM SCHD (LAST WEEK) | G38: VAR FROM SCHD (TO DATE)
C39: Number of Work Days | D39: 7 | E39: 7 | F39: 0 | G39: 0
C40: Total Work Hours | D40: 68 | E40: 68 | F40: 0 | G40: 0
B42: Impacts to Schedule:
D43: No. HOURS AFFECTED
D44: TODAY | E44: TO DATE
C45: Construction | D45: 0 | E45: 0
C46: Evacuations/Exclusions | D46: 0 | E46: 0
C47: Permits | D47: 0 | E47: 0
...

Sheet FCO.RFI
D2: FRAME 6B POWER GROUP DAILY REPORT GENERAL CONSTRUCTION | J2: Document No.:
J3: Revision No.: | L3: 0
J4: Revision Date:
K6: DATE: | L6: =Safety!L6 -> 46035
B8: Engineering:
B9: Engineering Issues/RFI's/NCR's
D10: Due to the nature of the Piperack moving, the Engineers added two piles on the west end to tie the project together. This change order includes all of the labor, material, and time to complete the additional (2).
B15: Field Change Orders (FCO): | D15: Period | E15: To Date
C16: Transmitted | D16: 1 | E16: 1
C17: Approved | D17: 0 | E17: 2
C18: Rejected | D18: 0 | E18: 0
C19: Outstanding | D19: 0 | E19: 0
B21: Contractor | C21: Change Order Number | D21: Description | E21: Status | F21: Date to Client | G21: Hours | H21: Labor $ | I21: Material $ | J21: Subcontract $ | K21: Per Diem | L21: Approved Totals
B22: Audubon | C22: 1 | D22: Added 19 Piles | E22: Approved | F22: 45960 | I22: 61742 | L22: 543042
B23: Audubon | C23: 2 | D23: Added 8 Piles | E23: TBD | F23: TBD | I23: 42752 | L23: 585794
B24: E&H | C24: 3 | D24: Seal Slabs | E24: Approved | F24: 45969
B25: Audubon | C25: 4 | D25: Added 2 Piles | E25: TBD | F25: TBD | G25: TBD | H25: TBD | I25: 11219 | J25: TBD | K25: TBD | L25: 554261
B29: Total | C29: Total | G29: =SUM(G22:G25) -> 0 | H29: =SUM(H22:H25) -> 0 | I29: =SUM(I22:I25) -> 115713 | J29: =SUM(J22:J25) -> 0 | K29: =SUM(K22:K25) -> 0 | L29: =SUM(L22:L25) -> 1683097

Sheet Cnst Equip
D2: FRAME 6B POWER GROUP DAILY REPORT GENERAL CONSTRUCTION | J2: Document No.:
J3: Revision No.: | L3: 0
J4: Revision Date:
K6: DATE: | L6: =Safety!L6 -> 46035
B8: Construction Equipment
C10: Rental Equipment | E10: RPS / Contractor | F10: Qty | G10: On Rent Date | H10: On Rent Finish
C11: Forklift | E11: =IF('E&H - Daily Report'!E137 = 0, "",'E&H - Daily Report'!E137) -> 84 | F11: =IF('E&H - Daily Report'!F137 = 0, "",'E&H - Daily Report'!F137) | G11: =IF('E&H - Daily Report'!G137 = 0, "",'E&H - Daily Report'!G137) | H11: =IF('E&H - Daily Report'!H137 = 0, "",'E&H - Daily Report'!H137)
C12: 12k (55'r each) - laydown | E12: Momentum | F12: =IF('E&H - Daily Report'!F138 = 0, "",'E&H - Daily Report'!F138) | G12: =IF('E&H - Daily Report'!G138 = 0, "",'E&H - Daily Report'!G138) | H12: =IF('E&H - Daily Report'!H138 = 0, "",'E&H - Daily Report'!H138)
C13: 12k (55'r each) - field grub | E13: =IF('E&H - Daily Report'!E139 = 0, "",'E&H - Daily Report'!E139) | F13: =IF('E&H - Daily Report'!F139 = 0, "",'E&H - Daily Report'!F139) | G13: =IF('E&H - Daily Report'!G139 = 0, "",'E&H - Daily Report'!G139) | H13: =IF('E&H - Daily Report'!H139 = 0, "",'E&H - Daily Report'!H139)
C14: 185CFM Air Compressor | E14: =IF('E&H - Daily Report'!E140 = 0, "",'E&H - Daily Report'!E140) | F14: =IF('E&H - Daily Report'!F140 = 0, "",'E&H - Daily Report'!F140) | G14: =IF('E&H - Daily Report'!G140 = 0, "",'E&H - Daily Report'!G140) | H14: =IF('E&H - Daily Report'!H140 = 0, "",'E&H - Daily Report'!H140)
C15: 2000 Gallon Water Truck | E15: Momentum | F15: =IF('E&H - Daily Report'!F141 = 0, "",'E&H - Daily Report'!F141) | G15: =IF('E&H - Daily Report'!G141 = 0, "",'E&H - Daily Report'!G141) | H15: =IF('E&H - Daily Report'!H141 = 0, "",'E&H - Daily Report'!H141)
C16: Concrete Mixer | E16: =IF('E&H - Daily Report'!E142 = 0, "",'E&H - Daily Report'!E142) | F16: =IF('E&H - Daily Report'!F142 = 0, "",'E&H - Daily Report'!F142) | G16: =IF('E&H - Daily Report'!G142 = 0, "",'E&H - Daily Report'!G142) | H16: =IF('E&H - Daily Report'!H142 = 0, "",'E&H - Daily Report'!H142)
C17: Gas Rammer | E17: =IF('E&H - Daily Report'!E143 = 0, "",'E&H - Daily Report'!E143) | F17: =IF('E&H - Daily Report'!F143 = 0, "",'E&H - Daily Report'!F143) | G17: =IF('E&H - Daily Report'!G143 = 0, "",'E&H - Daily Report'!G143) | H17: =IF('E&H - Daily Report'!H143 = 0, "",'E&H - Daily Report'!H143)
C18: Plate Comp | E18: =IF('E&H - Daily Report'!E144 = 0, "",'E&H - Daily Report'!E144) | F18: =IF('E&H - Daily Report'!F144 = 0, "",'E&H - Daily Report'!F144) | G18: =IF('E&H - Daily Report'!G144 = 0, "",'E&H - Daily Report'!G144) | H18: =IF('E&H - Daily Report'!H144 = 0, "",'E&H - Daily Report'!H144)
C19: Light Plants | E19: =IF('E&H - Daily Report'!E145 = 0, "",'E&H - Daily Report'!E145) | F19: =IF('E&H - Daily Report'!F145 = 0, "",'E&H - Daily Report'!F145) | G19: =IF('E&H - Daily Report'!G145 = 0, "",'E&H - Daily Report'!G145) | H19: =IF('E&H - Daily Report'!H145 = 0, "",'E&H - Daily Report'!H145)
C20: Pallet Jack | E20: =IF('E&H - Daily Report'!E146 = 0, "",'E&H - Daily Report'!E146) | F20: =IF('E&H - Daily Report'!F146 = 0, "",'E&H - Daily Report'!F146) | G20: =IF('E&H - Daily Report'!G146 = 0, "",'E&H - Daily Report'!G146) | H20: =IF('E&H - Daily Report'!H146 = 0, "",'E&H - Daily Report'!H146)
C21: Manlift | E21: =IF('E&H - Daily Report'!E147 = 0, "",'E&H - Daily Report'!E147) | F21: =IF('E&H - Daily Report'!F147 = 0, "",'E&H - Daily Report'!F147) | G21: =IF('E&H - Daily Report'!G147 = 0, "",'E&H - Daily Report'!G147) | H21: =IF('E&H - Daily Report'!H147 = 0, "",'E&H - Daily Report'!H147)
C22: 45' Articulating Boom | E22: =IF('E&H - Daily Report'!E148 = 0, "",'E&H - Daily Report'!E148) | F22: =IF('E&H - Daily Report'!F148 = 0, "",'E&H - Daily Report'!F148) | G22: =IF('E&H - Daily Report'!G148 = 0, "",'E&H - Daily Report'!G148) | H22: =IF('E&H - Daily Report'!H148 = 0, "",'E&H - Daily Report'!H148)
C23: 60' Articulating Boom | E23: =IF('E&H - Daily Report'!E149 = 0, "",'E&H - Daily Report'!E149) | F23: =IF('E&H - Daily Report'!F149 = 0, "",'E&H - Daily Report'!F149) | G23: =IF('E&H - Daily Report'!G149 = 0, "",'E&H - Daily Report'!G149) | H23: =IF('E&H - Daily Report'!H149 = 0, "",'E&H - Daily Report'!H149)
C24: 85' Articulating Boom | E24: =IF('E&H - Daily Report'!E150 = 0, "",'E&H - Daily Report'!E150) | F24: =IF('E&H - Daily Report'!F150 = 0, "",'E&H - Daily Report'!F150) | G24: =IF('E&H - Daily Report'!G150 = 0, "",'E&H - Daily Report'!G150) | H24: =IF('E&H - Daily Report'!H150 = 0, "",'E&H - Daily Report'!H150)
C25: 80' Straight Boom | E25: =IF('E&H - Daily Report'!E151 = 0, "",'E&H - Daily Report'!E151) | F25: =IF('E&H - Daily Report'!F151 = 0, "",'E&H - Daily Report'!F151) | G25: =IF('E&H - Daily Report'!G151 = 0, "",'E&H - Daily Report'!G151) | H25: =IF('E&H - Daily Report'!H151 = 0, "",'E&H - Daily Report'!H151)
C26: 85' Articulating Boom | E26: =IF('E&H - Daily Report'!E152 = 0, "",'E&H - Daily Report'!E152) -> RPS / Contractor | F26: =IF('E&H - Daily Report'!F152 = 0, "",'E&H - Daily Report'!F152) -> Qty | G26: =IF('E&H - Daily Report'!G152 = 0, "",'E&H - Daily Report'!G152) -> On Rent Date | H26: =IF('E&H - Daily Report'!H152 = 0, "",'E&H - Daily Report'!H152) -> On Rent Finish
C27: SKID STEER | E27: Momentum | F27: =IF('E&H - Daily Report'!F153 = 0, "",'E&H - Daily Report'!F153) | G27: =IF('E&H - Daily Report'!G153 = 0, "",'E&H - Daily Report'!G153) | H27: =IF('E&H - Daily Report'!H153 = 0, "",'E&H - Daily Report'!H153)
C28: Skid Steer Pallet Forks | E28: =IF('E&H - Daily Report'!E154 = 0, "",'E&H - Daily Report'!E154) | F28: =IF('E&H - Daily Report'!F154 = 0, "",'E&H - Daily Report'!F154) -> 1 | G28: =IF('E&H - Daily Report'!G154 = 0, "",'E&H - Daily Report'!G154) -> 45950 | H28: =IF('E&H - Daily Report'!H154 = 0, "",'E&H - Daily Report'!H154)
C29: Mini Ex (10-11k) | E29: =IF('E&H - Daily Report'!E155 = 0, "",'E&H - Daily Report'!E155) | F29: =IF('E&H - Daily Report'!F155 = 0, "",'E&H - Daily Report'!F155) | G29: =IF('E&H - Daily Report'!G155 = 0, "",'E&H - Daily Report'!G155) | H29: =IF('E&H - Daily Report'!H155 = 0, "",'E&H - Daily Report'!H155)
C30: 10k Track Excavator | E30: =IF('E&H - Daily Report'!E156 = 0, "",'E&H - Daily Report'!E156) | F30: =IF('E&H - Daily Report'!F156 = 0, "",'E&H - Daily Report'!F156) | G30: =IF('E&H - Daily Report'!G156 = 0, "",'E&H - Daily Report'!G156) | H30: =IF('E&H - Daily Report'!H156 = 0, "",'E&H - Daily Report'!H156)
C31: 20k Track Excavator (Cab & Air) | E31: =IF('E&H - Daily Report'!E157 = 0, "",'E&H - Daily Report'!E157) | F31: =IF('E&H - Daily Report'!F157 = 0, "",'E&H - Daily Report'!F157) -> 1 | G31: =IF('E&H - Daily Report'!G157 = 0, "",'E&H - Daily Report'!G157) -> 45950 | H31: =IF('E&H - Daily Report'!H157 = 0, "",'E&H - Daily Report'!H157)
C32: 3 yard loader | E32: =IF('E&H - Daily Report'!E158 = 0, "",'E&H - Daily Report'!E158) | F32: =IF('E&H - Daily Report'!F158 = 0, "",'E&H - Daily Report'!F158) | G32: =IF('E&H - Daily Report'!G158 = 0, "",'E&H - Daily Report'!G158) | H32: =IF('E&H - Daily Report'!H158 = 0, "",'E&H - Daily Report'!H158)
C33: 84" roller | E33: Momentum | F33: =IF('E&H - Daily Report'!F159 = 0, "",'E&H - Daily Report'!F159) | G33: =IF('E&H - Daily Report'!G159 = 0, "",'E&H - Daily Report'!G159) | H33: =IF('E&H - Daily Report'!H159 = 0, "",'E&H - Daily Report'!H159)
C34: 3K W/B Padfoot Roller | E34: =IF('E&H - Daily Report'!E160 = 0, "",'E&H - Daily Report'!E160) | F34: =IF('E&H - Daily Report'!F160 = 0, "",'E&H - Daily Report'!F160) | G34: =IF('E&H - Daily Report'!G160 = 0, "",'E&H - Daily Report'!G160) | H34: =IF('E&H - Daily Report'!H160 = 0, "",'E&H - Daily Report'!H160)
C35: 2500lb Track Loader | E35: =IF('E&H - Daily Report'!E161 = 0, "",'E&H - Daily Report'!E161) | F35: =IF('E&H - Daily Report'!F161 = 0, "",'E&H - Daily Report'!F161) | G35: =IF('E&H - Daily Report'!G161 = 0, "",'E&H - Daily Report'!G161) | H35: =IF('E&H - Daily Report'!H161 = 0, "",'E&H - Daily Report'!H161)
C36: 1900lb Track Loader | E36: =IF('E&H - Daily Report'!E162 = 0, "",'E&H - Daily Report'!E162) | F36: =IF('E&H - Daily Report'!F162 = 0, "",'E&H - Daily Report'!F162) | G36: =IF('E&H - Daily Report'!G162 = 0, "",'E&H - Daily Report'!G162) | H36: =IF('E&H - Daily Report'!H162 = 0, "",'E&H - Daily Report'!H162)
C37: 850P Dozer | E37: Momentum | F37: =IF('E&H - Daily Report'!F163 = 0, "",'E&H - Daily Report'!F163) | G37: =IF('E&H - Daily Report'!G163 = 0, "",'E&H - Daily Report'!G163) | H37: =IF('E&H - Daily Report'!H163 = 0, "",'E&H - Daily Report'!H163)
C38: 750L Dozer | E38: Momentum | F38: =IF('E&H - Daily Report'!F164 = 0, "",'E&H - Daily Report'!F164) | G38: =IF('E&H - Daily Report'!G164 = 0, "",'E&H - Daily Report'!G164) | H38: =IF('E&H - Daily Report'!H164 = 0, "",'E&H - Daily Report'!H164)
C39: 260E ADT | E39: Momentum | F39: =IF('E&H - Daily Report'!F165 = 0, "",'E&H - Daily Report'!F165) | G39: =IF('E&H - Daily Report'!G165 = 0, "",'E&H - Daily Report'!G165) | H39: =IF('E&H - Daily Report'!H165 = 0, "",'E&H - Daily Report'!H165)
C40: 824L Wheel Loader | E40: Momentum | F40: =IF('E&H - Daily Report'!F166 = 0, "",'E&H - Daily Report'!F166) | G40: =IF('E&H - Daily Report'!G166 = 0, "",'E&H - Daily Report'!G166) | H40: =IF('E&H - Daily Report'!H166 = 0, "",'E&H - Daily Report'!H166)
C41: 135P Excavator | E41: Momentum | F41: =IF('E&H - Daily Report'!F167 = 0, "",'E&H - Daily Report'!F167) | G41: =IF('E&H - Daily Report'!G167 = 0, "",'E&H - Daily Report'!G167) | H41: =IF('E&H - Daily Report'!H167 = 0, "",'E&H - Daily Report'!H167)
C42: Bomag BW211 Pad Compactor | E42: Momentum | F42: =IF('E&H - Daily Report'!F168 = 0, "",'E&H - Daily Report'!F168) | G42: =IF('E&H - Daily Report'!G168 = 0, "",'E&H - Daily Report'!G168) | H42: =IF('E&H - Daily Report'!H168 = 0, "",'E&H - Daily Report'!H168)
C43: Bomag BW211 Smooth Compactor | E43: Momentum | F43: =IF('E&H - Daily Report'!F169 = 0, "",'E&H - Daily Report'!F169) -> 1 | G43: =IF('E&H - Daily Report'!G169 = 0, "",'E&H - Daily Report'!G169) -> 45951 | H43: =IF('E&H - Daily Report'!H169 = 0, "",'E&H - Daily Report'!H169)
C44: 850P Dozer | E44: Momentum | F44: =IF('E&H - Daily Report'!F170 = 0, "",'E&H - Daily Report'!F170) | G44: =IF('E&H - Daily Report'!G170 = 0, "",'E&H - Daily Report'!G170) | H44: =IF('E&H - Daily Report'!H170 = 0, "",'E&H - Daily Report'!H170)
...

Sheet QAQC
D2: FRAME 6B POWER GROUP DAILY REPORT GENERAL CONSTRUCTION | J2: Document No.:
J3: Revision No.: | L3: 0
J4: Revision Date:
K6: DATE: | L6: 46035
B8: QA/QC:
B9: Highlights and Activities:
C10: Civil
B11: This should list QC activities/inspections. This content should be on "Completed Activities" | C11: update MTR's documents.
C12: update logs for concrete and density.
C13: inspection on GTG's for point & patch work is complete.
B16: Welding:
C17: Total Field Welds | E17: Welds Progressed to Date | F17: Welds Remaining | G17: % Complete
B18: Field Weld Count | F18: =+C18-E18 -> 0 | G18: 0
C20: Field Weld VT Count | D20: Field Weld RT Count | E20: Total Rejected / Repairs | F20: Reject Rate (Last Week) | G20: Reject Rate (Current)
B21: N.D.E. | E21: 0 | F21: 0 | G21: 0
B24: Non-Conformance Report Status:
C25: NCR's to Date | D25: NCR's Open | E25: NCR's Pending | F25: NCR's Closed
C26: 46011 | F26: 1

Sheet QTY Progress
A3: INSTALLED QUANTITIES REPORT | H3: Period | I3: =Safety!L6 -> 46035
A5: E&H EXCAVATIONS | D5: Period | G5: JTD
A6: Progress Item | B6: UOM | C6: Current Budg | D6: Plan | E6: Actual | F6: % Earned | G6: Plan | H6: Actual | I6: % Earned
A7: Temp Facilities Area | B7: CY | C7: 45714 | D7: ='E&H - QTY Plan'!BZ4 -> 0 | E7: ='E&H - QTY Plan'!BZ5 -> 0 | F7: =E7/C7 -> 0 | G7: =SUM('E&H - QTY Plan'!F4:CH4) -> 26428 | H7: =SUM('E&H - QTY Plan'!F5:CH5) -> 29823 | I7: =H7/C7 -> 0.6523822
A8: Pad Site | B8: CY | C8: 47483 | D8: ='E&H - QTY Plan'!BZ12 -> 0 | E8: ='E&H - QTY Plan'!BZ13 -> 0 | F8: =E8/C8 -> 0 | G8: =SUM('E&H - QTY Plan'!F14:CH14) -> 44000 | H8: =SUM('E&H - QTY Plan'!F13:CH13) -> 47483 | I8: =H8/C8 -> 1
A9: Drill Piers GT | B9: CY | C9: 203 | D9: ='E&H - QTY Plan'!BZ20 -> 0 | E9: ='E&H - QTY Plan'!BZ22 -> 0 | F9: =E9/C9 -> 0 | G9: =SUM('E&H - QTY Plan'!F20:CH20) -> 392 | H9: =SUM('E&H - QTY Plan'!F21:CH21) -> 203 | I9: =H9/C9 -> 1
A10: Drill Piers SCR | B10: CY | C10: 97 | D10: ='E&H - QTY Plan'!BZ28 -> 0 | E10: ='E&H - QTY Plan'!BZ30 -> 0 | F10: =E10/C10 -> 0 | G10: =SUM('E&H - QTY Plan'!F28:CH28) -> 96.6 | H10: =SUM('E&H - QTY Plan'!F29:CH29) -> 96 | I10: =H10/C10 -> 0.98969072
A11: GT Seal Slab | B11: CY | C11: 90 | D11: ='E&H - QTY Plan'!BZ36 -> 0 | E11: ='E&H - QTY Plan'!BZ38 -> 0 | F11: =E11/C11 -> 0 | G11: =SUM('E&H - QTY Plan'!F36:CH36) -> 90 | H11: =SUM('E&H - QTY Plan'!G38:CH38) -> 90 | I11: =H11/C11 -> 1
A12: SCR Seal Slab | B12: CY | C12: 140 | D12: ='E&H - QTY Plan'!BZ44 -> 0 | E12: ='E&H - QTY Plan'!BZ46 -> 0 | F12: =E12/C12 -> 0 | G12: =SUM('E&H - QTY Plan'!F44:CH44) -> 105 | H12: =SUM('E&H - QTY Plan'!G46:CH46) -> 140 | I12: =H12/C12 -> 1
A15: AUDUBON | D15: Period | G15: JTD
A16: Progress Item | B16: UOM | C16: Current Budg | D16: Plan | E16: Actual | F16: % Earned | G16: Plan | H16: Actual | I16: % Earned
A17: Helical Piers | B17: EA | C17: 171 | D17: ='Audubon - QTY Plan'!AX4 -> 0 | E17: ='Audubon - QTY Plan'!AX5 -> 0 | F17: =E17/C17 -> 0 | G17: =SUM('Audubon - QTY Plan'!E4:AH4) -> 128 | H17: =SUM('Audubon - QTY Plan'!E5:AX5) -> 171 | I17: =H17/C17 -> 1
A18: Concrete Pedestals | B18: EA | C18: 171 | D18: ='Audubon - QTY Plan'!AX12 -> 0 | E18: ='Audubon - QTY Plan'!AX13 -> 0 | F18: =E18/C18 -> 0 | G18: =SUM('Audubon - QTY Plan'!E12:AH12) -> 120 | H18: =SUM('Audubon - QTY Plan'!E13:AX13) -> 153 | I18: =H18/C18 -> 0.89473684

Sheet E&H - QTY Plan
W1: Y4
F2: Thru | G2: Monday | H2: Tuesday | I2: Wednesday | J2: Thursday | K2: Friday | L2: Saturday | M2: Sunday | N2: Monday | O2: Tuesday | P2: Wednesday | Q2: Thursday | R2: Friday | S2: Saturday | T2: Sunday | U2: Monday | V2: Tuesday | X2: Thursday | Y2: Friday | Z2: Saturday | AA2: Sunday | AB2: Monday | AC2: Tuesday | AD2: Wednesday | AE2: Thursday | AF2: Friday | AG2: Saturday | AH2: Sunday | AI2: Monday | AJ2: Tuesday | AK2: Wednesday | AL2: Thursday | AM2: Friday | AN2: Saturday | AO2: Sunday | AP2: Monday | AQ2: Tuesday | AR2: Wednesday | AS2: Thursday | AT2: Friday | AU2: Saturday | AV2: Sunday | AW2: Monday | AX2: Tuesday | AY2: Wednesday | AZ2: Thursday | BA2: Friday | BB2: Saturday | BC2: Sunday | BD2: Monday | BE2: Tuesday | BF2: Wednesday | BG2: Thursday | BH2: Friday | BI2: Saturday | BJ2: Sunday | BK2: Monday | BL2: Tuesday | BM2: Wednesday | BN2: Thursday | BO2: Friday | BP2: Saturday | BQ2: Sunday | BR2: Monday | BS2: Tuesday | BT2: Wednesday | BU2: Thursday | BV2: Friday | BW2: Saturday | BX2: Sunday | BY2: Monday | BZ2: Tuesday | CA2: Wednesday | CB2: Thursday | CC2: Friday | CD2: Saturday | CE2: Sunday | CF2: Monday | CG2: Tuesday | CH2: Wednesday | CI2: Thursday | CJ2: Friday | CK2: Saturday | CL2: Sunday | CM2: Monday | CN2: Tuesday | CO2: Wednesday | CP2: Thursday | CQ2: Friday | CR2: Saturday | CS2: Sunday
B3: Discipline | C3: AREA | D3: UOM | F3: 45962 | G3: 45964 | H3: =G3+1 -> 45965 | I3: =H3+1 -> 45966 | J3: =I3+1 -> 45967 | K3: =J3+1 -> 45968 | L3: =K3+1 -> 45969 | M3: =L3+1 -> 45970 | N3: =M3+1 -> 45971 | O3: =N3+1 -> 45972 | ... CS3: =CR3+1 -> 46054 | CT3: Total
A4: 6800 | B4: Sitework | C4: Temp Facilities Area | D4: CY | E4: Plan | F4: 7598 | G4: 1536 | H4: 1628 | I4: 1886 | J4: 1572 | K4: 1572 | L4: 1572 | M4: 0 | N4: 1572 | O4: 1572 | P4: 1572 | Q4: 1572 | R4: 1572 | S4: 1204 | CT4: =SUM(F4:CS4) -> 26428 | CU4: Budgeted
A5: HR | E5: Earned | F5: 7598 | G5: 1536 | H5: 1628 | I5: 2028 | J5: 1965 | K5: 2739 | L5: 1513 | M5: 0 | N5: 1412 | O5: 1959 | P5: 1572 | Q5: 2396 | R5: 2350 | S5: 670 | U5: 281 | V5: 176 | CT5: =SUM(F5:CS5) -> 29823 | CU5: Installed
A6: HR | E6: Forecast | P6: 1075.4392 | Q6: 1075.4392 | R6: 1075.4392 | S6: 823.68243 | U6: 300 | V6: 300 | CT6: =SUM(F6:CS6) -> 4650 | CU6: Forecast
B8: Sitework | C8: Temp Facilities Area | D8: % Complete | E8: Plan | F8: 0.28749811 | G8: 0.058120176 | H8: 0.061601332 | I8: 0.071363705 | J8: 0.059482367 | K8: 0.059482367 | L8: 0.059482367 | M8: 0 | N8: 0.059482367 | O8: 0.059482367 | P8: 0.059482367 | Q8: 0.059482367 | R8: 0.059482367 | S8: 0.045557742 | T8: 0 | U8: 0 | V8: 0 | W8: 0 | CT8: =SUM(F8:CS8) -> 1 | CU8: Budgeted
E9: Earned | F9: 0.28749811 | G9: 0.058120176 | H9: 0.061601332 | I9: 0.076736794 | J9: 0.074352959 | K9: 0.10364008 | L9: 0.057249886 | M9: 0 | N9: 0.053428182 | O9: 0.074125927 | CT9: =SUM(F9:CS9) -> 0.84675344 | CU9: Installed
E10: Forecast | P10: 0.040693173 | Q10: 0.040693173 | R10: 0.040693173 | S10: 0.031167036 | T10: 0 | U10: 0.011351597 | V10: 0.011351597 | W10: 0 | CT10: =SUM(F10:CS10) -> 0.17594975 | CU10: Forecast
A12: HR | B12: Sitework | C12: Pad Site | D12: CY | E12: Plan | K12: 5000 | L12: 5000 | M12: 10000 | N12: 5000 | O12: 5000 | P12: 5000 | CT12: =SUM(F12:CS12) -> 35000 | CU12: Budgeted
A13: HR | E13: Earned | P13: 300 | Q13: 300 | R13: 300 | S13: 300 | U13: 1151 | V13: 1915 | W13: 2238 | X13: 1005 | Y13: 1998 | Z13: 404 | AA13: 0 | AB13: 525 | AC13: 2256 | AD13: 3470 | AG13: 1440 | AH13: 650 | AI13: 1754 | AJ13: 2490 | AK13: 2440 | AL13: 2296 | AM13: 2930 | AN13: 0 | AO13: 0 | AP13: 3624 | AQ13: 3872 | AR13: 0 | AV13: 550 | AW13: 550 | AX13: 550 | AY13: 550 | BR13: 1120 | BS13: 1140 | BT13: 2100 | BU13: 2100 | BV13: 1165 | CT13: =SUM(F13:CS13) -> 47483 | CU13: Installed
A14: HR | E14: Forecast | U14: 2000 | V14: 2000 | W14: 2000 | X14: 2000 | Y14: 2000 | Z14: 2000 | AA14: 1250 | AB14: 2500 | AC14: 2500 | AD14: 1250 | AE14: 1250 | AF14: 1250 | AG14: 1250 | AH14: 1250 | AI14: 2500 | AJ14: 2500 | AK14: 1500 | AL14: 1500 | AM14: 1250 | AN14: 1250 | AO14: 0 | AP14: 1500 | AQ14: 1500 | AR14: 1500 | AS14: 1500 | AT14: 1500 | BR14: 500 | BS14: 500 | BT14: 500 | CT14: =SUM(F14:CS14) -> 44000 | CU14: Forecast
B16: Sitework | C16: Pad Site | D16: % Complete | E16: Plan | F16: 0 | G16: 0 | H16: 0 | I16: 0 | J16: 0 | K16: 0.14285714 | L16: 0.14285714 | M16: 0.28571429 | N16: 0.14285714 | O16: 0.14285714 | P16: 0.14285714 | Q16: 0 | R16: 0 | S16: 0 | T16: 0 | U16: 0 | V16: 0 | W16: 0 | X16: 0 | CT16: =SUM(F16:CS16) -> 1 | CU16: Budgeted
E17: Earned | F17: 0 | G17: 0 | H17: 0 | I17: 0 | J17: 0 | K17: 0 | L17: 0 | M17: 0 | N17: 0 | O17: 0 | P17: 0.0085714286 | Q17: 0.0085714286 | R17: 0.0085714286 | S17: 0.0085714286 | T17: 0 | U17: 0.032885714 | V17: 0.054714286 | W17: 0.063942857 | X17: 0.028714286 | CT17: =SUM(F17:CS17) -> 0.21454286 | CU17: Installed
E18: Forecast | U18: 0.047058824 | V18: 0.047058824 | W18: 0.047058824 | X18: 0.047058824 | Y18: 0.047058824 | Z18: 0.047058824 | AA18: 0.029411765 | AB18: 0.058823529 | AC18: 0.058823529 | AD18: 0.029411765 | AE18: 0.029411765 | AF18: 0.029411765 | AG18: 0.029411765 | AH18: 0.029411765 | AI18: 0.058823529 | AJ18: 0.058823529 | AK18: 0.035294118 | AL18: 0.035294118 | AM18: 0.029411765 | AN18: 0.029411765 | CT18: =SUM(F18:CS18) -> 0.82352941 | CU18: Forecast
A20: 1069 | B20: Civil | C20: Drill Piers GT | D20: CY | E20: Plan | F20: 0 | G20: 0 | H20: 0 | I20: 0 | J20: 0 | K20: 0 | L20: 46 | M20: 0 | N20: 0 | O20: 46 | P20: 0 | Q20: 46 | R20: 0 | S20: 51 | T20: 203 | U20: 0 | V20: 0 | W20: 0 | X20: 0 | Y20: 0 | Z20: 0 | AA20: 0 | AB20: 0 | CT20: =SUM(F20:CS20) -> 392 | CU20: Budgeted
A21: HR | E21: Earned | F21: 0 | G21: 0 | H21: 0 | I21: 0 | J21: 0 | K21: 0 | L21: 46 | M21: 0 | O21: 60 | P21: 0 | Q21: 46 | R21: 0 | S21: 51 | T21: 0 | U21: 0 | V21: 0 | W21: 0 | X21: 0 | Y21: 0 | Z21: 0 | AA21: 0 | AB21: 0 | CT21: =SUM(F21:CS21) -> 203 | CU21: Installed
A22: HR | E22: Forecast | S22: 37 | CT22: =SUM(F22:CS22) -> 37 | CU22: Forecast
B24: Civil | C24: Drill Piers GT | D24: % Complete | E24: Plan | F24: =F17/$CT$4 -> 0 | G24: =G17/$CT$4 -> 0 | H24: =H17/$CT$4 -> 0 | I24: =I17/$CT$4 -> 0 | J24: =J17/$CT$4 -> 0 | K24: =K17/$CT$4 -> 0 | L24: =L20/$CT$20 -> 0.11734694 | M24: =M20/$CT$20 -> 0 | N24: =N20/$CT$20 -> 0 | O24: =O20/$CT$20 -> 0.11734694 | P24: =P20/$CT$20 -> 0 | Q24: =Q20/$CT$20 -> 0.11734694 | R24: =R20/$CT$20 -> 0 | S24: =S20/$CT$20 -> 0.13010204 | ... AB24: =AB20/$CT$20 -> 0 | CT24: =SUM(AU24:CS24) -> 0 | CU24: Budgeted
E25: Earned | F25: =F21/$CT$20 -> 0 | G25: =G21/$CT$20 -> 0 | H25: =H21/$CT$20 -> 0 | I25: =I21/$CT$20 -> 0 | J25: =J21/$CT$20 -> 0 | K25: =K21/$CT$20 -> 0 | L25: =L21/$CT$20 -> 0.11734694 | M25: =M21/$CT$20 -> 0 | ... AB25: =AB21/$CT$20 -> 0 | CT25: =SUM(F25:CS25) -> 0.51785714 | CU25: Installed
E26: Forecast | Q26: =Q22/$CT$20 -> 0 | R26: =R22/$CT$20 -> 0 | S26: =S22/$CT$20 -> 0.094387755 | T26: =T22/$CT$20 -> 0 | U26: =U22/$CT$20 -> 0 | V26: =V22/$CT$20 -> 0 | W26: =W22/$CT$20 -> 0 | X26: =X22/$CT$20 -> 0 | ... AB26: =AB22/$CT$20 -> 0 | CT26: =SUM(F26:CS26) -> 0.094387755 | CU26: Forecast
A28: 758 | B28: Civil | C28: Drill Piers SCR | D28: CY | E28: Plan | F28: 0 | G28: 0 | H28: 0 | I28: 0 | J28: 0 | K28: 0 | L28: 0 | M28: 0 | N28: 0 | O28: 0 | P28: 0 | Q28: 0 | R28: 0 | S28: 0 | T28: 0 | U28: 32.2 | W28: 32.2 | Y28: 32.2 | CT28: =SUM(F28:CS28) -> 96.6 | CU28: Budgeted
A29: HR | E29: Earned | F29: 0 | G29: 0 | H29: 0 | I29: 0 | J29: 0 | K29: 0 | L29: 0 | M29: 0 | N29: 0 | O29: 0 | P29: 0 | Q29: 0 | R29: 0 | S29: 0 | T29: 0 | U29: 32 | V29: 0 | W29: 32 | X29: 0 | Y29: 0 | Z29: 28 | AA29: 0 | AB29: 0 | AK29: 4 | CT29: =SUM(F29:CS29) -> 96 | CU29: Installed
A30: HR | E30: Forecast | U30: 32.2 | W30: 32.2 | Y30: 32.2 | AK30: 4 | CT30: =SUM(F30:CS30) -> 100.6 | CU30: Forecast
B32: Civil | C32: Drill Piers SCR | D32: % Complete | E32: Plan | F32: =F28/$CT$20 -> 0 | G32: =G28/$CT$20 -> 0 | H32: =H28/$CT$20 -> 0 | I32: =I28/$CT$20 -> 0 | J32: =J28/$CT$20 -> 0 | K32: =K28/$CT$20 -> 0 | L32: =L28/$CT$20 -> 0 | M32: =M28/$CT$20 -> 0 | ... T32: =T28/$CT$20 -> 0 | U32: =U28/$CT$28 -> 0.33333333 | V32: =V28/$CT$28 -> 0 | W32: =W28/$CT$28 -> 0.33333333 | X32: =X28/$CT$28 -> 0 | Y32: =Y28/$CT$28 -> 0.33333333 | Z32: =Z28/$CT$28 -> 0 | AA32: =AA28/$CT$28 -> 0 | AB32: =AB28/$CT$28 -> 0 | CT32: =SUM(F32:CS32) -> 1 | CU32: Budgeted
E33: Earned | F33: =F29/$CT$20 -> 0 | G33: =G29/$CT$20 -> 0 | H33: =H29/$CT$20 -> 0 | I33: =I29/$CT$20 -> 0 | J33: =J29/$CT$20 -> 0 | K33: =K29/$CT$20 -> 0 | L33: =L29/$CT$20 -> 0 | M33: =M29/$CT$20 -> 0 | ... AB33: =AB29/$CT$20 -> 0 | CT33: =SUM(F33:CS33) -> 0.23469388 | CU33: Installed
E34: Forecast | U34: =U30/$CT$30 -> 0.32007952 | V34: =V30/$CT$30 -> 0 | W34: =W30/$CT$30 -> 0.32007952 | X34: =X30/$CT$30 -> 0 | Y34: =Y30/$CT$30 -> 0.32007952 | Z34: =Z30/$CT$30 -> 0 | AA34: =AA30/$CT$30 -> 0 | AB34: =AB30/$CT$30 -> 0 | CT34: =SUM(F34:CS34) -> 0.96023857 | CU34: Forecast
A36: HR | B36: Civil | C36: GT Seal Slab | D36: CY | E36: Plan | F36: 0 | G36: 0 | H36: 0 | I36: 0 | J36: 0 | K36: 0 | L36: 0 | M36: 0 | N36: 0 | O36: 0 | P36: 0 | Q36: 0 | R36: 0 | S36: 30 | U36: 30 | W36: 30 | CT36: =SUM(F36:CS36) -> 90 | CU36: Budgeted
A37: HR | E37: Earned | F37: 0 | G37: 0 | H37: 0 | I37: 0 | J37: 0 | K37: 0 | L37: 0 | M37: 0 | N37: 0 | O37: 0 | P37: 0 | Q37: 0 | R37: 0 | S37: 30 | T37: 0 | U37: 30 | V37: 0 | W37: 30 | X37: 0 | Y37: 0 | Z37: 0 | AA37: 0 | AB37: 0 | CT37: =SUM(A37:CS37) -> 90 | CU37: Installed
A38: HR | E38: Forecast | S38: 30 | U38: 30 | W38: 30 | CT38: =SUM(F38:CS38) -> 90 | CU38: Forecast
B40: Civil | C40: GT Seal Slab | D40: % Complete | E40: Plan | F40: =F36/$CT$20 -> 0 | G40: =G36/$CT$20 -> 0 | H40: =H36/$CT$20 -> 0 | I40: =I36/$CT$20 -> 0 | J40: =J36/$CT$20 -> 0 | K40: =K36/$CT$20 -> 0 | L40: =L36/$CT$20 -> 0 | M40: =M36/$CT$20 -> 0 | ... R40: =R36/$CT$20 -> 0 | S40: =S36/$CT$36 -> 0.33333333 | T40: =T36/$CT$20 -> 0 | U40: =U36/$CT$36 -> 0.33333333 | V40: =V36/$CT$28 -> 0 | W40: =W36/$CT$36 -> 0.33333333 | X40: =X36/$CT$28 -> 0 | Y40: =Y36/$CT$28 -> 0 | Z40: =Z36/$CT$28 -> 0 | AA40: =AA36/$CT$28 -> 0 | AB40: =AB36/$CT$28 -> 0 | CT40: =SUM(F40:CS40) -> 1 | CU40: Budgeted
E41: Earned | F41: =F37/$CT$20 -> 0 | G41: =G37/$CT$20 -> 0 | H41: =H37/$CT$20 -> 0 | I41: =I37/$CT$20 -> 0 | J41: =J37/$CT$20 -> 0 | K41: =K37/$CT$20 -> 0 | L41: =L37/$CT$20 -> 0 | M41: =M37/$CT$20 -> 0 | ... AB41: =AB37/$CT$20 -> 0 | CT41: =SUM(F41:CS41) -> 0.22959184 | CU41: Installed
E42: Forecast | CT42: =SUM(F42:CS42) -> 0 | CU42: Forecast
A44: HR | B44: Civil | C44: SCR Seal Slab | D44: CY | E44: Plan | F44: 0 | G44: 0 | H44: 0 | I44: 0 | J44: 0 | K44: 0 | L44: 0 | M44: 0 | N44: 0 | O44: 0 | P44: 0 | Q44: 0 | R44: 0 | S44: 0 | T44: 0 | U44: 0 | V44: 0 | X44: 70 | Z44: 35 | CT44: =SUM(F44:CS44) -> 105 | CU44: Budgeted
A45: HR | E45: Earned | F45: 0 | G45: 0 | H45: 0 | I45: 0 | J45: 0 | K45: 0 | L45: 0 | M45: 0 | N45: 0 | O45: 0 | P45: 0 | Q45: 0 | R45: 0 | S45: 0 | T45: 0 | U45: 0 | Z45: 35 | AC45: 35 | AK45: 35 | CT45: =SUM(F45:CS45) -> 105 | CU45: Installed
A46: HR | E46: Forecast | Z46: 35 | AB46: 70 | AK46: 35 | CT46: =SUM(F46:CS46) -> 140 | CU46: Forecast
B48: Civil | C48: SCR Seal Slab | D48: % Complete | E48: Plan | F48: =F44/$CT$20 -> 0 | G48: =G44/$CT$20 -> 0 | H48: =H44/$CT$20 -> 0 | I48: =I44/$CT$20 -> 0 | J48: =J44/$CT$20 -> 0 | K48: =K44/$CT$20 -> 0 | L48: =L44/$CT$20 -> 0 | M48: =M44/$CT$20 -> 0 | ... R48: =R44/$CT$20 -> 0 | S48: =S44/$CT$36 -> 0 | T48: =T44/$CT$20 -> 0 | U48: =U44/$CT$36 -> 0 | V48: =V44/$CT$44 -> 0 | W48: =W44/$CT$44 -> 0 | X48: =X44/$CT$44 -> 0.66666667 | Y48: =Y44/$CT$44 -> 0 | Z48: =Z44/$CT$44 -> 0.33333333 | AA48: =AA44/$CT$44 -> 0 | AB48: =AB44/$CT$44 -> 0 | CT48: =SUM(F48:CS48) -> 1 | CU48: Budgeted
E49: Earned | F49: =F45/$CT$20 -> 0 | G49: =G45/$CT$20 -> 0 | H49: =H45/$CT$20 -> 0 | I49: =I45/$CT$20 -> 0 | J49: =J45/$CT$20 -> 0 | K49: =K45/$CT$20 -> 0 | L49: =L45/$CT$20 -> 0 | M49: =M45/$CT$20 -> 0 | ... AB49: =AB45/$CT$20 -> 0 | CT49: =SUM(F49:CS49) -> 0.089285714 | CU49: Installed
E50: Forecast | CT50: =SUM(F50:CS50) -> 0 | CU50: Forecast
A52: MH | B52: OVERALL | C52: OVERALL | D52: OVERALL | E52: Plan | F52: =F4+F12+F20+F28+F36+F44 -> 7598 | G52: =G4+G12+G20+G28+G36+G44 -> 1536 | H52: =H4+H12+H20+H28+H36+H44 -> 1628 | I52: =I4+I12+I20+I28+I36+I44 -> 1886 | J52: =J4+J12+J20+J28+J36+J44 -> 1572 | K52: =K4+K12+K20+K28+K36+K44 -> 6572 | L52: =L4+L12+L20+L28+L36+L44 -> 6618 | M52: =M4+M12+M20+M28+M36+M44 -> 10000 | ... AO52: =AO4+AO12+AO20+AO28+AO36+AO44 -> 0 | CT52: =SUM(F52:CS52) -> 62111.6 | CU52: Budgeted
...

Sheet Audubon - QTY Plan
E2: Saturday | F2: Monday | G2: Tuesday | H2: Wednesday | I2: Thursday | J2: Friday | K2: Saturday | L2: Sunday | M2: Monday | N2: Tuesday | O2: Wednesday | P2: Thursday | Q2: Friday | R2: Saturday | S2: Sunday | T2: Monday | U2: Tuesday | V2: Wednesday | W2: Thursday | X2: Friday | Y2: Saturday | Z2: Sunday | AA2: Monday | AB2: Tuesday | AC2: Wednesday | AD2: Monday | AE2: Tuesday | AF2: Wednesday | AG2: Thursday | AH2: Friday | AI2: Saturday | AJ2: Sunday | AK2: Monday | AL2: Tuesday | AM2: Wednesday | AN2: Thursday | AO2: Friday | AP2: Saturday | AQ2: Sunday | AR2: Monday | AS2: Tuesday | AT2: Wednesday | AU2: Thursday | AV2: Friday | AW2: Saturday | AX2: Sunday
A3: Discipline | B3: AREA | C3: UOM | E3: 45962 | F3: 45964 | G3: =F3+1 -> 45965 | H3: =G3+1 -> 45966 | I3: =H3+1 -> 45967 | J3: =I3+1 -> 45968 | K3: =J3+1 -> 45969 | L3: =K3+1 -> 45970 | M3: =L3+1 -> 45971 | N3: =M3+1 -> 45972 | ... AC3: =AB3+1 -> 45987 | AD3: =AC3+5 -> 45992 | AE3: =AD3+1 -> 45993 | AF3: =AE3+1 -> 45994 | AG3: =AF3+1 -> 45995 | AH3: =AG3+1 -> 45996 | AI3: =AH3+1 -> 45997 | AJ3: =AI3+1 -> 45998 | AK3: =AJ3+1 -> 45999 | AL3: =AK3+1 -> 46000 | ... AX3: =AW3+1 -> 46012 | AY3: Total
A4: Civil | B4: Helical Piers | C4: EA | D4: Plan | E4: 0 | F4: 0 | G4: 0 | H4: 0 | I4: 0 | J4: 0 | K4: 0 | L4: 0 | M4: 10 | N4: 10 | O4: 10 | P4: 10 | Q4: 10 | R4: 10 | S4: 0 | T4: 10 | U4: 10 | V4: 10 | Z4: 10 | AA4: 10 | AB4: 8 | AC4: 0 | AE4: 5 | AF4: 5 | AL4: 11 | AM4: 16 | AN4: 7 | AO4: 9 | AY4: =SUM(E4:AX4) -> 171 | AZ4: Budgeted
D5: Earned | E5: 0 | F5: 0 | G5: 0 | H5: 0 | I5: 0 | J5: 0 | K5: 0 | L5: 0 | M5: 0 | N5: 10 | O5: 34 | P5: 21 | Q5: 11 | R5: 18 | S5: 0 | T5: 7 | U5: 15 | V5: 12 | W5: 0 | X5: 0 | Y5: 0 | Z5: 0 | AA5: 0 | AB5: 0 | AC5: 0 | AD5: 0 | AE5: 0 | AF5: 0 | AG5: 0 | AH5: 0 | AI5: 0 | AL5: 11 | AM5: 16 | AN5: 7 | AO5: 9 | AY5: =SUM(E5:AX5) -> 171 | AZ5: Earned
D6: Forecast | N6: 9 | P6: 8.9473684 | Q6: 8.9473684 | R6: 8.9473684 | S6: 0 | T6: 8.9473684 | U6: 8.9473684 | V6: 8.9473684 | W6: 8.9473684 | X6: 8.9473684 | Y6: 8.9473684 | Z6: 8.9473684 | AA6: 8.9473684 | AB6: 7.1578947 | AC6: 0 | AD6: 4.4736842 | AE6: 4.4736842 | AF6: 4.4736842 | AL6: 11 | AM6: 16 | AN6: 7 | AO6: 9 | AY6: =SUM(E6:AX6) -> 171 | AZ6: Forecast
A8: Civil | B8: Helical Piers | C8: % Complete | D8: Plan | E8: 0 | F8: 0 | G8: 0 | H8: 0 | I8: 0 | J8: 0 | K8: 0 | L8: 0 | M8: 0.058479532 | N8: 0.058479532 | O8: 0.058479532 | P8: 0.058479532 | Q8: 0.058479532 | R8: 0.058479532 | S8: 0 | T8: 0.058479532 | U8: 0.058479532 | V8: 0.058479532 | W8: 0 | X8: 0 | Y8: 0 | Z8: 0.058479532 | AA8: 0.058479532 | AB8: 0.046783626 | AC8: 0 | AD8: 0 | AE8: 0.029239766 | AF8: 0.029239766 | AG8: 0 | AH8: 0 | AI8: 0 | AJ8: 0 | AK8: 0 | AL8: 0.064327485 | AM8: 0.093567251 | AN8: 0.040935673 | AO8: 0.052631579 | AP8: 0 | AQ8: 0 | AR8: 0 | AS8: 0 | AY8: =SUM(E8:AX8) -> 1 | AZ8: Budgeted
D9: Earned | E9: 0 | F9: 0 | G9: 0 | H9: 0 | I9: 0 | J9: 0 | K9: 0 | L9: 0 | M9: 0 | N9: 0.058479532 | O9: 0.19883041 | P9: 0.12280702 | Q9: 0.064327485 | R9: 0.10526316 | S9: 0 | T9: 0.040935673 | U9: 0.087719298 | V9: 0.070175439 | W9: 0 | X9: 0 | Y9: 0 | Z9: 0 | AA9: 0 | AB9: 0 | AC9: 0 | AD9: 0 | AE9: 0 | AF9: 0 | AG9: 0 | AH9: 0 | AI9: 0 | AJ9: 0 | AK9: 0 | AL9: 0.064327485 | AM9: 0.093567251 | AN9: 0.040935673 | AO9: 0.052631579 | AP9: =AP5/$AY$5 -> 0 | AQ9: =AQ5/$AY$5 -> 0 | AR9: =AR5/$AY$5 -> 0 | AS9: =AS5/$AY$5 -> 0 | AT9: =AT5/$AY$5 -> 0 | AY9: =SUM(E9:AX9) -> 1 | AZ9: Earned
D10: Forecast | M10: 0 | N10: 0.052631579 | O10: 0 | P10: 0.052323792 | Q10: 0.052323792 | R10: 0.052323792 | S10: 0 | T10: 0.052323792 | U10: 0.052323792 | V10: 0.052323792 | W10: 0.052323792 | X10: 0.052323792 | Y10: 0.052323792 | Z10: 0.052323792 | AA10: 0.052323792 | AB10: 0.041859034 | AC10: 0 | AD10: 0.026161896 | AE10: 0.026161896 | AF10: 0.026161896 | AG10: 0 | AH10: 0 | AI10: 0 | AJ10: 0 | AK10: 0 | AL10: 0.064327485 | AM10: 0.093567251 | AN10: 0.040935673 | AO10: 0.052631579 | AP10: =AP6/$AY$4 -> 0 | AQ10: =AQ6/$AY$4 -> 0 | AR10: =AR6/$AY$4 -> 0 | AS10: =AS6/$AY$4 -> 0 | AT10: =AT6/$AY$4 -> 0 | AY10: =SUM(E10:AX10) -> 1 | AZ10: Forecast
A12: Civil | B12: Concrete Pedestals | C12: EA | D12: Plan | E12: 0 | F12: 0 | G12: 0 | H12: 0 | I12: 0 | J12: 0 | K12: 0 | L12: 0 | M12: 0 | N12: 0 | O12: 0 | P12: 0 | Q12: 20 | R12: 0 | S12: 0 | T12: 0 | U12: 0 | V12: 20 | W12: 0 | X12: 0 | Y12: 20 | Z12: 0 | AA12: 0 | AB12: 20 | AC12: 0 | AD12: 0 | AE12: 20 | AF12: 0 | AG12: 0 | AH12: 20 | AI12: 0 | AJ12: 0 | AL12: 0 | AO12: 9 | AS12: 22 | AT12: 20 | AY12: =SUM(E12:AX12) -> 171 | AZ12: Budgeted
D13: Earned | E13: 0 | F13: 0 | G13: 0 | H13: 0 | I13: 0 | J13: 0 | K13: 0 | L13: 0 | M13: 0 | N13: 0 | O13: 0 | P13: 0 | Q13: 20 | R13: 0 | S13: 0 | T13: 0 | U13: 0 | V13: 20 | W13: 0 | X13: 0 | Y13: 16 | Z13: 0 | AA13: 0 | AB13: 28 | AC13: 0 | AD13: 0 | AE13: 20 | AF13: 0 | AG13: 0 | AH13: 24 | AI13: 0 | AJ13: 0 | AK13: 0 | AL13: 0 | AM13: 0 | AO13: 9 | AS13: 16 | AY13: =SUM(E13:AX13) -> 153 | AZ13: Earned
D14: Forecast | Q14: 20 | U14: 0 | V14: 20 | W14: 0 | X14: 0 | Y14: 20 | Z14: 0 | AA14: 0 | AB14: 20 | AC14: 0 | AD14: 0 | AE14: 20 | AF14: 0 | AG14: 0 | AH14: 20 | AI14: 0 | AJ14: 0 | AO14: 9 | AS14: 22 | AT14: 20 | AY14: =SUM(E14:AX14) -> 171 | AZ14: Forecast
A16: Civil | B16: Concrete Pedestals | C16: % Complete | D16: Plan | E16: 0 | F16: 0 | G16: 0 | H16: 0 | I16: 0 | J16: 0 | K16: 0 | L16: 0 | M16: 0 | N16: 0 | O16: 0 | P16: 0 | Q16: 0.11695906 | R16: 0 | S16: 0 | T16: 0 | U16: 0 | V16: 0.11695906 | W16: 0 | X16: 0 | Y16: 0.11695906 | Z16: 0 | AA16: 0 | AB16: 0.11695906 | AC16: 0 | AD16: 0 | AE16: 0.11695906 | AF16: 0 | AG16: 0 | AH16: 0.11695906 | AI16: 0 | AJ16: 0 | AK16: 0 | AL16: 0 | AM16: 0 | AN16: 0 | AO16: 0.052631579 | AP16: 0 | AQ16: 0 | AR16: 0 | AS16: 0.12865497 | AT16: 0.11695906 | AY16: =SUM(E16:AX16) -> 1 | AZ16: Budgeted
D17: Earned | E17: 0 | F17: 0 | G17: 0 | H17: 0 | I17: 0 | J17: 0 | K17: 0 | L17: 0 | M17: 0 | N17: 0 | O17: 0 | P17: 0 | Q17: 0.11695906 | R17: 0 | S17: 0 | T17: 0 | U17: 0 | V17: 0.11695906 | W17: 0 | X17: 0 | Y17: 0.093567251 | Z17: 0 | AA17: 0 | AB17: 0.16374269 | AC17: 0 | AD17: 0 | AE17: 0.11695906 | AF17: 0 | AG17: 0 | AH17: 0.14035088 | AI17: 0 | AJ17: 0 | AK17: 0 | AL17: 0 | AM17: 0 | AN17: 0 | AO17: 0.052631579 | AP17: 0 | AQ17: 0 | AR17: 0 | AS17: 0.093567251 | AT17: 0 | AY17: =SUM(E17:AX17) -> 0.89473684 | AZ17: Earned
D18: Forecast | Q18: 0.11695906 | R18: 0 | S18: 0 | T18: 0 | U18: 0 | V18: 0.11695906 | W18: 0 | X18: 0 | Y18: 0.11695906 | Z18: 0 | AA18: 0 | AB18: 0.11695906 | AC18: 0 | AD18: 0 | AE18: 0.11695906 | AF18: 0 | AG18: 0 | AH18: 0.11695906 | AI18: 0 | AJ18: 0 | AK18: 0 | AL18: 0 | AM18: 0 | AN18: 0 | AO18: 0.052631579 | AP18: 0 | AQ18: 0 | AR18: 0 | AS18: 0.12865497 | AT18: 0.11695906 | AY18: =SUM(E18:AX18) -> 1 | AZ18: Forecast

Sheet E&H - Daily Report
D2: FRAME 6B POWER GROUP DAILY REPORT GENERAL CONSTRUCTION | J2: Document No.:
J3: Revision No.: | L3: 0
J4: Revision Date:
H6: PO# | I6: 15209 | K6: DATE: | L6: 46339
B8: Safety and Personnel
B9: Safety Topic: | C9: Cold weather work
B13: Safety Statistics: | D13: Direct | E13: Indirect | F13: Subcontractors | J13: Total Direct | K13: Total Indirect | L13: TOTAL
B14: Previous Safe (Cumm.) Work Hours | D14: 19744 | E14: 2009 | J14: =D14 -> 19744 | K14: =SUM(E14:I14) -> 2009 | L14: =SUM(J14:K14) -> 21753
B15: This Week (Period) Safe Work Hours | D15: 854 | E15: 96 | J15: =D15 -> 854 | K15: =SUM(E15:I15) -> 96 | L15: =SUM(J15:K15) -> 950
B16: Total Safe Work Hours To-Date | D16: =SUM(D15+D14) -> 20598 | E16: =SUM(E15+E14) -> 2105 | F16: =SUM(F15,F14) -> 0 | G16: =SUM(G15,G14) -> 0 | H16: =SUM(H15,H14) -> 0 | I16: =SUM(I15,I14) -> 0 | J16: =SUM(J15,J14) -> 20598 | K16: =SUM(K15,K14) -> 2105 | L16: =SUM(L14:L15) -> 22703
B18: Incidents: | D18: Period | E18: To Date | F18: Description
B19: First Aids | D19: 0 | E19: 0
B20: Incidents | D20: 0 | E20: 0
B21: Recordable | D21: 0 | E21: 0
C22: Lost Time | D22: 0 | E22: 0
C23: Property Damage | D23: 0 | E23: 1
B24: Near Misses | D24: 0 | E24: 0
B26: Head Count: | D26: Craft Type | E26: Count | F26: Subcontrator | G26: Hrs | I26: Per Diem (Y/N)
D27: Sr. Project Management | E27: 1 | G27: 0 | I27: Y
D28: Superintendent - Civil | E28: 1 | G28: 12 | I28: Y
D29: Site Manager | E29: 1 | G29: 12 | I29: Y
D30: Superintendent - Piping | E30: 1 | I30: Y
D31: Superintendent - Mech | E31: 1 | G31: 12 | I31: Y
D32: Superintendent - E&I
D33: Planner
D34: Project Scheduler
D35: Quality Manager | E35: 1 | G35: 12 | I35: Y
D36: HSE Supervisor | E36: 2 | G36: 12 | I36: Y
D37: Office Manager
D38: Timekeeper
D39: Warehouse GF | E39: 1 | G39: 12 | I39: Y
D40: Warehouseman | E40: 1 | G40: 12 | I40: Y
D41: Warehouse Crew | E41: 3 | G41: 36 | I41: Y
D42: Operators J1 | E42: 2 | G42: 24 | I42: Y
D43: Operators J2
D44: Tool Room Attendant | E44: 1 | G44: 12 | I44: Y
D45: Civil GF | E45: 1 | G45: 12 | I45: Y
D46: Civil J1 | E46: 24 | G46: 276 | I46: Y
D47: Civil J2 | E47: 14 | G47: 132 | I47: Y
D48: Pipe GF | E48: 1 | G48: 12 | I48: Y
...

Sheet Audubon - Daily Report
D2: FRAME 6B POWER GROUP DAILY REPORT GENERAL CONSTRUCTION | J2: Document No.:
J3: Revision No.: | L3: 0
J4: Revision Date:
K6: DATE: | L6: 46008
B8: Safety and Personnel
B9: Safety Topic: | C9: Materials handling
B13: Safety Statistics: | D13: Direct | E13: Indirect | F13: Subcontractors | J13: Total Direct | K13: Total Indirect | L13: TOTAL
B14: (Cumm.) Work Hours | D14: 2059 | E14: 775 | F14: 253 | J14: =D14 -> 2059 | K14: =SUM(E14:I14) -> 1028 | L14: =SUM(J14:K14) -> 3087
B15: (Period) Safe Work Hours | D15: 55 | E15: 11 | F15: 11 | J15: =D15 -> 55 | K15: =SUM(E15:I15) -> 22 | L15: =SUM(J15:K15) -> 77
B16: Total Safe Work Hours To-Date | D16: =SUM(D15+D14) -> 2114 | E16: =SUM(E15+E14) -> 786 | F16: =SUM(F15,F14) -> 264 | G16: =SUM(G15,G14) -> 0 | H16: =SUM(H15,H14) -> 0 | I16: =SUM(I15,I14) -> 0 | J16: =SUM(J15,J14) -> 2114 | K16: =SUM(K15,K14) -> 1050 | L16: =SUM(L14:L15) -> 3164
B18: Incidents: | D18: Period | E18: To Date | F18: Description
B19: First Aids | D19: 0 | E19: 0
B20: Incidents | D20: 0 | E20: 0
B21: Recordable | D21: 0 | E21: 0
C22: Lost Time | D22: 0 | E22: 0
C23: Property Damage | D23: 0 | E23: 0
B24: Near Misses | D24: 0 | E24: 0
B26: Head Count: | D26: Craft Type | E26: Count | F26: Subcontrator | G26: Hrs | I26: Per Diem (Y/N)
B27: Total | D27: Indirects | E27: 2 | G27: 11
B28: Total | D28: Directs | E28: 5 | F28: 1 | G28: 11
B29: Request for additional manpower to be mobilized
B30: List trade/name, work area
B31: N/A
B33: Weather Report: MUST INCLUDE ANY IMPACT TO SCHEDULE, STANDOWNS, ETC. | D33: Monday | E33: Tuesday | F33: Wednesday | G33: Thursday | H33: Friday | I33: Saturday | J33: Sunday
B34: Date | D34: 45971 | E34: =D34+1 -> 45972 | F34: =E34+1 -> 45973 | G34: =F34+1 -> 45974 | H34: =G34+1 -> 45975 | I34: =H34+1 -> 45976 | J34: =I34+1 -> 45977
B35: Hi | D35: 65 | E35: 72
B36: Low | D36: 45 | E36: 46
C37: Rain Inches
B39: Weather: | D39: Mon | E39: Tue | F39: Wed | G39: Thu | H39: Fri | I39: Sat | J39: Sun
C40: Date | D40: 44816 | E40: =+D40+1 -> 44817 | F40: =+E40+1 -> 44818 | G40: =+F40+1 -> 44819 | H40: =+G40+1 -> 44820 | I40: =+H40+1 -> 44821 | J40: =+I40+1 -> 44822
C41: Hi | I41: NA | J41: NA
C42: Lo | I42: NA | J42: NA
C43: Rain | D43: 0 | E43: 0 | F43: 0 | G43: 0 | H43: 0 | I43: 0 | J43: 0
D44: Actuals | E44: Actuals | F44: Actuals | G44: Actuals | H44: Actuals | I44: Actuals | J44: Actuals
B45: Engineering:
B46: Engineering Issues/RFI's/NCR's
D47: Piperack Pile Locations
B52: Field Change Orders (FCO): | D52: Period | E52: To Date
C53: Transmitted | D53: 0 | E53: 0
C54: Approved | D54: 0 | E54: 0
...

Sheet RPS - Daily Report
D2: FRAME 6B POWER GROUP DAILY REPORT GENERAL CONSTRUCTION | J2: Document No.:
J3: Revision No.: | L3: 0
J4: Revision Date:
K6: DATE: | L6: 45999
B8: Safety and Personnel
B9: Safety Topic: | C9: MUSTER POINTS
B13: Safety Statistics: | D13: Direct | E13: Indirect | F13: Subcontractors | J13: Total Direct | K13: Total Indirect | L13: TOTAL
B14: (Cumm.) Work Hours | D14: =2310+144+144+228+228+133+228+228+209+190 -> 4042 | E14: =1925+96+96+96+96+35+72+72+66+40 -> 2594 | F14: =50+50+50+50+50+30+50+190+88+280 -> 888 | J14: =D14 -> 4042 | K14: =SUM(E14:I14) -> 3482 | L14: =SUM(J14:K14) -> 7524
B15: (Period) Safe Work Hours | D15: 190 | E15: 40 | F15: 280 | J15: =D15 -> 190 | K15: =SUM(E15:I15) -> 320 | L15: =SUM(J15:K15) -> 510
B16: Total Safe Work Hours To-Date | D16: =SUM(D15+D14) -> 4232 | E16: =SUM(E15+E14) -> 2634 | F16: =SUM(F15,F14) -> 1168 | G16: =SUM(G15,G14) -> 0 | H16: =SUM(H15,H14) -> 0 | I16: =SUM(I15,I14) -> 0 | J16: =SUM(J15,J14) -> 4232 | K16: =SUM(K15,K14) -> 3802 | L16: =SUM(L14:L15) -> 8034
B18: Incidents: | D18: Period | E18: To Date | F18: Description
B19: First Aids | D19: 0 | E19: 0
B20: Incidents | D20: 0 | E20: 0
B21: Recordable | D21: 0 | E21: 0
C22: Lost Time | D22: 0 | E22: 0
C23: Property Damage | D23: 0 | E23: 0
B24: Near Misses | D24: 0 | E24: 0
B26: Head Count: | D26: Craft Type | E26: Count | F26: Subcontrator | G26: Hrs | I26: Per Diem (Y/N)
B27: Total | D27: Indirects | E27: 4 | G27: 10
B28: Total | D28: Directs | E28: 19 | G28: 10
B29: Request for additional manpower to be mobilized
B30: List trade/name, work area
B31: N/A
B33: Weather Report: MUST INCLUDE ANY IMPACT TO SCHEDULE, STANDOWNS, ETC. | D33: Monday | E33: Tuesday | F33: Wednesday | G33: Thursday | H33: Friday | I33: Saturday | J33: Sunday
B34: Date | D34: 45971 | E34: =D34+1 -> 45972 | F34: =E34+1 -> 45973 | G34: =F34+1 -> 45974 | H34: =G34+1 -> 45975 | I34: =H34+1 -> 45976 | J34: =I34+1 -> 45977
B35: Hi | D35: 65 | E35: 72
B36: Low | D36: 45 | E36: 46
C37: Rain Inches
B39: Weather: | D39: Mon | E39: Tue | F39: Wed | G39: Thu | H39: Fri | I39: Sat | J39: Sun
C40: Date | D40: 44816 | E40: =+D40+1 -> 44817 | F40: =+E40+1 -> 44818 | G40: =+F40+1 -> 44819 | H40: =+G40+1 -> 44820 | I40: =+H40+1 -> 44821 | J40: =+I40+1 -> 44822
C41: Hi | I41: NA | J41: NA
C42: Lo | I42: NA | J42: NA
C43: Rain | D43: 0 | E43: 0 | F43: 0 | G43: 0 | H43: 0 | I43: 0 | J43: 0
D44: Actuals | E44: Actuals | F44: Actuals | G44: Actuals | H44: Actuals | I44: Actuals | J44: Actuals
B45: Engineering:
B46: Engineering Issues/RFI's/NCR's
B52: Field Change Orders (FCO): | D52: Period | E52: To Date
C53: Transmitted | D53: 0 | E53: 0
C54: Approved | D54: 0 | E54: 0
C55: Rejected | D55: 0 | E55: 0
...
