Workbook
Name Database_Area: #REF!
Name Database_Area: #REF!
Name OPENED_OR_CLOSED: #REF!
Name OPENED_OR_CLOSED: #REF!

Sheet Pipe Audit
A1: RECORD # | B1: DRAWING | C1: Rev | D1: SCHED_ID | E1: Cost Area | F1: Cost Code | G1: SYS | H1: Line Area | I1: SPOOL / FR | J1: SIZE | K1: FLD QTY Ftg | L1: IFC WHRS | M1: UOM | N1: Pipe Spec | O1: Earned Qtys Footage | P1: Earned IFC WHRS | Q1: Rec' 2% | R1: M1 Desc | S1: Stage 3% | T1: M2 Desc | U1: Erect/ Install 20% | V1: M3 Desc | W1: Conn 30% | X1: M4 Desc | Y1: Support/ Jeep Trace 10% | Z1: M5 Desc | AA1: Punch 10% | AB1: M6 Desc | AC1: Test 15% | AD1: M7 Desc | AE1: Post 10% | AF1: M8 Desc | AG1: TEST PKG 1 | AH1: CWP | AI1: IWP_ No | AJ1: SPOOLS | AK1: FOREMAN | AL1: GF | AM1: WHRS_ UNIT | AN1: M1 | AO1: M2 | AP1: M3 | AQ1: M4 | AR1: M5 | AS1: M6 | AT1: M7 | AU1: M8 | AV1: VAR Area | AW1: paint_ spec | AX1: Insul Spec | AY1: Heat Trace Spec | AZ1: TA_ BANK | BA1: TA_ BAY | BB1: TA_ LEVEL | BC1: INT | BD1: TOTAL CONSTRUCTION WHRS | BE1: EARNED CONSTRUCTION WHRS | BF1: REMAINING CONSTRUCTION HRS | BG1: EARNED PUNCH WHRS | BH1: EARNED TEST WHRS | BI1: EARNED POST WHRS | BJ1: TEST & POST WHRS | BK1: EARNED PUNCH, TEST, POST HRS | BL1: Earned Erected A/G Footage | BM1: Construction HRS % Complete | BN1: TOTAL CONSTRUCTION QTYS | BO1: EARNED CONSTRUCTION QTYS | BP1: REMAINING CONSTRUCTION QTYS
O2: =P2/AM2 -> #DIV/0! | P2: =L2*Q2*AN2+L2*S2*AO2+L2*U2*AP2+L2*W2*AQ2+L2*Y2*AR2+L2*AA2*AS2+L2*AC2*AT2+L2*AE2*AU2 -> 0 | BD2: =$L2*$AN2+$L2*$AO2+$L2*$AP2+$L2*$AQ2+$L2*$AR2 -> 0 | BE2: =$L2*$Q2*$AN2+$L2*$S2*$AO2+$L2*$U2*$AP2+$L2*$W2*$AQ2+$L2*$Y2*$AR2 -> 0 | BF2: =BD2-BE2 -> 0 | BG2: =L2*AA2*AS2 -> 0 | BH2: =L2*AC2*AT2 -> 0 | BI2: =L2*AE2*AU2 -> 0 | BJ2: =BH2+BI2 -> 0 | BK2: =BG2+BH2+BI2 -> 0 | BL2: =K2*U2 -> 0 | BM2: =BE2/BD2 -> #DIV/0! | BN2: =$K2*$AN2+$K2*$AO2+$K2*$AP2+$K2*$AQ2+$K2*$AR2 -> 0 | BO2: =$K2*$Q2*$AN2+$K2*$S2*$AO2+$K2*$U2*$AP2+$K2*$W2*$AQ2+$K2*$Y2*$AR2 -> 0 | BP2: =BN2-BO2 -> 0
A3: 1 | B3: 120-DR-590-SHT01 | C3: 1 | D3: CN-2760 | F3: 08331 | G3: DR | H3: DRAINS DRR DRIPS RETURN | I3: 120-DR-590-SHT01-1 | J3: 02 | K3: 131 | L3: 5.06 | M3: LF | N3: 01HDPE | O3: =P3/AM3 -> #DIV/0! | P3: =L3*Q3*AN3+L3*S3*AO3+L3*U3*AP3+L3*W3*AQ3+L3*Y3*AR3+L3*AA3*AS3+L3*AC3*AT3+L3*AE3*AU3 -> 10.12 | Q3: 100 | R3: Receive | T3: Stage | V3: Erect | X3: Connect | Z3: Jeep/Trace | AB3: Mech. Sell Off | AD3: Test | AF3: Post | AJ3: 1 | AK3: Bob | AN3: 0.02 | AO3: 0.03 | AP3: 0.2 | AQ3: 0.3 | AR3: 0.1 | AS3: 0.1 | AT3: 0.15 | AU3: 0.1 | AV3: 120 | AW3: N/A | AX3: N/A | AY3: N/A | BD3: =#REF!*#REF!+#REF!*#REF!+#REF!*#REF!+#REF!*#REF!+#REF!*#REF! -> #REF! | BE3: =#REF!*#REF!*#REF!+#REF!*#REF!*#REF!+#REF!*#REF!*#REF!+#REF!*#REF!*#REF!+#REF!*#REF!*#REF! -> #REF! | BF3: =BD3-BE3 -> #REF! | BG3: =#REF!*#REF!*#REF! -> #REF! | BH3: =#REF!*#REF!*#REF! -> #REF! | BI3: =#REF!*#REF!*#REF! -> #REF! | BJ3: =BH3+BI3 -> #REF! | BK3: =BG3+BH3+BI3 -> #REF! | BL3: =#REF!*#REF! -> #REF! | BM3: =BE3/BD3 -> #REF! | BN3: =#REF!*#REF!+#REF!*#REF!+#REF!*#REF!+#REF!*#REF!+#REF!*#REF! -> #REF! | BO3: =#REF!*#REF!*#REF!+#REF!*#REF!*#REF!+#REF!*#REF!*#REF!+#REF!*#REF!*#REF!+#REF!*#REF!*#REF! -> #REF! | BP3: =BN3-BO3 -> #REF!
A4: 2 | B4: 120-DR-590-SHT02 | C4: 0 | D4: CN-2760 | F4: 08331 | G4: DR | H4: DRAINS DRR DRIPS RETURN | I4: 120-DR-590-SHT02-1 | J4: 02 | K4: 208 | M4: LF | N4: 01HDPE | O4: =P4/AM4 -> #DIV/0! | P4: =L4*Q4*AN4+L4*S4*AO4+L4*U4*AP4+L4*W4*AQ4+L4*Y4*AR4+L4*AA4*AS4+L4*AC4*AT4+L4*AE4*AU4 -> 0 | R4: Receive | T4: Stage | V4: Erect | X4: Connect | Z4: Jeep/Trace | AB4: Mech. Sell Off | AD4: Test | AF4: Post | AJ4: 1 | AK4: Jose | AN4: 0.02 | AO4: 0.03 | AP4: 0.2 | AQ4: 0.3 | AR4: 0.1 | AS4: 0.1 | AT4: 0.15 | AU4: 0.1 | AV4: 120 | AW4: N/A | AX4: N/A | AY4: N/A | BD4: =#REF!*#REF!+#REF!*#REF!+#REF!*#REF!+#REF!*#REF!+#REF!*#REF! -> #REF! | BE4: =#REF!*#REF!*#REF!+#REF!*#REF!*#REF!+#REF!*#REF!*#REF!+#REF!*#REF!*#REF!+#REF!*#REF!*#REF! -> #REF! | BF4: =BD4-BE4 -> #REF! | BG4: =#REF!*#REF!*#REF! -> #REF! | BH4: =#REF!*#REF!*#REF! -> #REF! | BI4: =#REF!*#REF!*#REF! -> #REF! | BJ4: =BH4+BI4 -> #REF! | BK4: =BG4+BH4+BI4 -> #REF! | BL4: =#REF!*#REF! -> #REF! | BM4: =BE4/BD4 -> #REF! | BN4: =#REF!*#REF!+#REF!*#REF!+#REF!*#REF!+#REF!*#REF!+#REF!*#REF! -> #REF! | BO4: =#REF!*#REF!*#REF!+#REF!*#REF!*#REF!+#REF!*#REF!*#REF!+#REF!*#REF!*#REF!+#REF!*#REF!*#REF! -> #REF! | BP4: =BN4-BO4 -> #REF!
A5: 3 | B5: 120-DR-591-SHT01 | C5: 1 | D5: CN-2760 | F5: 08331 | G5: DR | H5: DRAINS DRR DRIPS RETURN | I5: 120-DR-591-SHT01-1 | J5: 02 | K5: 137 | M5: LF | N5: 01HDPE | O5: =P5/AM5 -> #DIV/0! | P5: =L5*Q5*AN5+L5*S5*AO5+L5*U5*AP5+L5*W5*AQ5+L5*Y5*AR5+L5*AA5*AS5+L5*AC5*AT5+L5*AE5*AU5 -> 0 | R5: Receive | T5: Stage | V5: Erect | X5: Connect | Z5: Jeep/Trace | AB5: Mech. Sell Off | AD5: Test | AF5: Post | AJ5: 1 | AK5: Juan | AN5: 0.02 | AO5: 0.03 | AP5: 0.2 | AQ5: 0.3 | AR5: 0.1 | AS5: 0.1 | AT5: 0.15 | AU5: 0.1 | AV5: 120 | AW5: N/A | AX5: N/A | AY5: N/A | BD5: =#REF!*#REF!+#REF!*#REF!+#REF!*#REF!+#REF!*#REF!+#REF!*#REF! -> #REF! | BE5: =#REF!*#REF!*#REF!+#REF!*#REF!*#REF!+#REF!*#REF!*#REF!+#REF!*#REF!*#REF!+#REF!*#REF!*#REF! -> #REF! | BF5: =BD5-BE5 -> #REF! | BG5: =#REF!*#REF!*#REF! -> #REF! | BH5: =#REF!*#REF!*#REF! -> #REF! | BI5: =#REF!*#REF!*#REF! -> #REF! | BJ5: =BH5+BI5 -> #REF! | BK5: =BG5+BH5+BI5 -> #REF! | BL5: =#REF!*#REF! -> #REF! | BM5: =BE5/BD5 -> #REF! | BN5: =#REF!*#REF!+#REF!*#REF!+#REF!*#REF!+#REF!*#REF!+#REF!*#REF! -> #REF! | BO5: =#REF!*#REF!*#REF!+#REF!*#REF!*#REF!+#REF!*#REF!*#REF!+#REF!*#REF!*#REF!+#REF!*#REF!*#REF! -> #REF! | BP5: =BN5-BO5 -> #REF!
A6: 4 | B6: 120-DR-591-SHT02 | C6: 0 | D6: CN-2760 | F6: 08331 | G6: DR | H6: DRAINS DRR DRIPS RETURN | I6: 120-DR-591-SHT02-1 | J6: 02 | K6: 218 | M6: LF | N6: 01HDPE | O6: =P6/AM6 -> #DIV/0! | P6: =L6*Q6*AN6+L6*S6*AO6+L6*U6*AP6+L6*W6*AQ6+L6*Y6*AR6+L6*AA6*AS6+L6*AC6*AT6+L6*AE6*AU6 -> 0 | R6: Receive | T6: Stage | V6: Erect | X6: Connect | Z6: Jeep/Trace | AB6: Mech. Sell Off | AD6: Test | AF6: Post | AJ6: 1 | AK6: Jerry | AN6: 0.02 | AO6: 0.03 | AP6: 0.2 | AQ6: 0.3 | AR6: 0.1 | AS6: 0.1 | AT6: 0.15 | AU6: 0.1 | AV6: 120 | AW6: N/A | AX6: N/A | AY6: N/A | BD6: =#REF!*#REF!+#REF!*#REF!+#REF!*#REF!+#REF!*#REF!+#REF!*#REF! -> #REF! | BE6: =#REF!*#REF!*#REF!+#REF!*#REF!*#REF!+#REF!*#REF!*#REF!+#REF!*#REF!*#REF!+#REF!*#REF!*#REF! -> #REF! | BF6: =BD6-BE6 -> #REF! | BG6: =#REF!*#REF!*#REF! -> #REF! | BH6: =#REF!*#REF!*#REF! -> #REF! | BI6: =#REF!*#REF!*#REF! -> #REF! | BJ6: =BH6+BI6 -> #REF! | BK6: =BG6+BH6+BI6 -> #REF! | BL6: =#REF!*#REF! -> #REF! | BM6: =BE6/BD6 -> #REF! | BN6: =#REF!*#REF!+#REF!*#REF!+#REF!*#REF!+#REF!*#REF!+#REF!*#REF! -> #REF! | BO6: =#REF!*#REF!*#REF!+#REF!*#REF!*#REF!+#REF!*#REF!*#REF!+#REF!*#REF!*#REF!+#REF!*#REF!*#REF! -> #REF! | BP6: =BN6-BO6 -> #REF!
A7: 5 | B7: 120-GTD-501-SHT01 | C7: 0 | D7: CN-2880 | F7: 08331 | G7: GTD | H7: GAS TURBINE DRAINS | I7: 120-GTD-501-SHT01-1 | J7: 02 | K7: 8 | M7: LF | N7: 01HDPE | O7: =P7/AM7 -> #DIV/0! | P7: =L7*Q7*AN7+L7*S7*AO7+L7*U7*AP7+L7*W7*AQ7+L7*Y7*AR7+L7*AA7*AS7+L7*AC7*AT7+L7*AE7*AU7 -> 0 | R7: Receive | T7: Stage | V7: Erect | X7: Connect | Z7: Jeep/Trace | AB7: Mech. Sell Off | AD7: Test | AF7: Post | AI7: PI-401-002 | AJ7: 1 | AK7: Sandra | AN7: 0.02 | AO7: 0.03 | AP7: 0.2 | AQ7: 0.3 | AR7: 0.1 | AS7: 0.1 | AT7: 0.15 | AU7: 0.1 | AV7: 401 | AW7: N/A | AX7: N/A | AY7: N/A | BD7: =#REF!*#REF!+#REF!*#REF!+#REF!*#REF!+#REF!*#REF!+#REF!*#REF! -> #REF! | BE7: =#REF!*#REF!*#REF!+#REF!*#REF!*#REF!+#REF!*#REF!*#REF!+#REF!*#REF!*#REF!+#REF!*#REF!*#REF! -> #REF! | BF7: =BD7-BE7 -> #REF! | BG7: =#REF!*#REF!*#REF! -> #REF! | BH7: =#REF!*#REF!*#REF! -> #REF! | BI7: =#REF!*#REF!*#REF! -> #REF! | BJ7: =BH7+BI7 -> #REF! | BK7: =BG7+BH7+BI7 -> #REF! | BL7: =#REF!*#REF! -> #REF! | BM7: =BE7/BD7 -> #REF! | BN7: =#REF!*#REF!+#REF!*#REF!+#REF!*#REF!+#REF!*#REF!+#REF!*#REF! -> #REF! | BO7: =#REF!*#REF!*#REF!+#REF!*#REF!*#REF!+#REF!*#REF!*#REF!+#REF!*#REF!*#REF!+#REF!*#REF!*#REF! -> #REF! | BP7: =BN7-BO7 -> #REF!
A8: 6 | B8: 120-GTD-501-SHT01 | C8: 0 | D8: CN-2880 | F8: 08332 | G8: GTD | H8: GAS TURBINE DRAINS | I8: 120-GTD-501-SHT01-2 | J8: 06 | K8: 44 | M8: LF | N8: 01HDPE | O8: =P8/AM8 -> #DIV/0! | P8: =L8*Q8*AN8+L8*S8*AO8+L8*U8*AP8+L8*W8*AQ8+L8*Y8*AR8+L8*AA8*AS8+L8*AC8*AT8+L8*AE8*AU8 -> 0 | R8: Receive | T8: Stage | V8: Erect | X8: Connect | Z8: Jeep/Trace | AB8: Mech. Sell Off | AD8: Test | AF8: Post | AI8: PI-401-002 | AJ8: 1 | AK8: Bob | AN8: 0.02 | AO8: 0.03 | AP8: 0.2 | AQ8: 0.3 | AR8: 0.1 | AS8: 0.1 | AT8: 0.15 | AU8: 0.1 | AV8: 401 | AW8: N/A | AX8: N/A | AY8: N/A | BD8: =#REF!*#REF!+#REF!*#REF!+#REF!*#REF!+#REF!*#REF!+#REF!*#REF! -> #REF! | BE8: =#REF!*#REF!*#REF!+#REF!*#REF!*#REF!+#REF!*#REF!*#REF!+#REF!*#REF!*#REF!+#REF!*#REF!*#REF! -> #REF! | BF8: =BD8-BE8 -> #REF! | BG8: =#REF!*#REF!*#REF! -> #REF! | BH8: =#REF!*#REF!*#REF! -> #REF! | BI8: =#REF!*#REF!*#REF! -> #REF! | BJ8: =BH8+BI8 -> #REF! | BK8: =BG8+BH8+BI8 -> #REF! | BL8: =#REF!*#REF! -> #REF! | BM8: =BE8/BD8 -> #REF! | BN8: =#REF!*#REF!+#REF!*#REF!+#REF!*#REF!+#REF!*#REF!+#REF!*#REF! -> #REF! | BO8: =#REF!*#REF!*#REF!+#REF!*#REF!*#REF!+#REF!*#REF!*#REF!+#REF!*#REF!*#REF!+#REF!*#REF!*#REF! -> #REF! | BP8: =BN8-BO8 -> #REF!
A9: 7 | B9: 120-GTD-501-SHT02 | C9: 0 | D9: CN-2880 | F9: 08332 | G9: GTD | H9: GAS TURBINE DRAINS | I9: 120-GTD-501-SHT02-1 | J9: 06 | K9: 33 | M9: LF | N9: 01HDPE | O9: =P9/AM9 -> #DIV/0! | P9: =L9*Q9*AN9+L9*S9*AO9+L9*U9*AP9+L9*W9*AQ9+L9*Y9*AR9+L9*AA9*AS9+L9*AC9*AT9+L9*AE9*AU9 -> 0 | R9: Receive | T9: Stage | V9: Erect | X9: Connect | Z9: Jeep/Trace | AB9: Mech. Sell Off | AD9: Test | AF9: Post | AI9: PI-401-002 | AJ9: 1 | AK9: Jose | AN9: 0.02 | AO9: 0.03 | AP9: 0.2 | AQ9: 0.3 | AR9: 0.1 | AS9: 0.1 | AT9: 0.15 | AU9: 0.1 | AV9: 401 | AW9: N/A | AX9: N/A | AY9: N/A | BD9: =#REF!*#REF!+#REF!*#REF!+#REF!*#REF!+#REF!*#REF!+#REF!*#REF! -> #REF! | BE9: =#REF!*#REF!*#REF!+#REF!*#REF!*#REF!+#REF!*#REF!*#REF!+#REF!*#REF!*#REF!+#REF!*#REF!*#REF! -> #REF! | BF9: =BD9-BE9 -> #REF! | BG9: =#REF!*#REF!*#REF! -> #REF! | BH9: =#REF!*#REF!*#REF! -> #REF! | BI9: =#REF!*#REF!*#REF! -> #REF! | BJ9: =BH9+BI9 -> #REF! | BK9: =BG9+BH9+BI9 -> #REF! | BL9: =#REF!*#REF! -> #REF! | BM9: =BE9/BD9 -> #REF! | BN9: =#REF!*#REF!+#REF!*#REF!+#REF!*#REF!+#REF!*#REF!+#REF!*#REF! -> #REF! | BO9: =#REF!*#REF!*#REF!+#REF!*#REF!*#REF!+#REF!*#REF!*#REF!+#REF!*#REF!*#REF!+#REF!*#REF!*#REF! -> #REF! | BP9: =BN9-BO9 -> #REF!
A10: 8 | B10: 120-GTD-501-SHT03 | C10: 0 | D10: CN-2880 | F10: 08332 | G10: GTD | H10: GAS TURBINE DRAINS | I10: 120-GTD-501-SHT03-1 | J10: 06 | K10: 120 | M10: LF | N10: 01HDPE | O10: =P10/AM10 -> #DIV/0! | P10: =L10*Q10*AN10+L10*S10*AO10+L10*U10*AP10+L10*W10*AQ10+L10*Y10*AR10+L10*AA10*AS10+L10*AC10*AT10+L10*AE10*AU10 -> 0 | R10: Receive | T10: Stage | V10: Erect | X10: Connect | Z10: Jeep/Trace | AB10: Mech. Sell Off | AD10: Test | AF10: Post | AI10: PI-401-002 | AJ10: 1 | AK10: Juan | AN10: 0.02 | AO10: 0.03 | AP10: 0.2 | AQ10: 0.3 | AR10: 0.1 | AS10: 0.1 | AT10: 0.15 | AU10: 0.1 | AV10: 401 | AW10: N/A | AX10: N/A | AY10: N/A | BD10: =#REF!*#REF!+#REF!*#REF!+#REF!*#REF!+#REF!*#REF!+#REF!*#REF! -> #REF! | BE10: =#REF!*#REF!*#REF!+#REF!*#REF!*#REF!+#REF!*#REF!*#REF!+#REF!*#REF!*#REF!+#REF!*#REF!*#REF! -> #REF! | BF10: =BD10-BE10 -> #REF! | BG10: =#REF!*#REF!*#REF! -> #REF! | BH10: =#REF!*#REF!*#REF! -> #REF! | BI10: =#REF!*#REF!*#REF! -> #REF! | BJ10: =BH10+BI10 -> #REF! | BK10: =BG10+BH10+BI10 -> #REF! | BL10: =#REF!*#REF! -> #REF! | BM10: =BE10/BD10 -> #REF! | BN10: =#REF!*#REF!+#REF!*#REF!+#REF!*#REF!+#REF!*#REF!+#REF!*#REF! -> #REF! | BO10: =#REF!*#REF!*#REF!+#REF!*#REF!*#REF!+#REF!*#REF!*#REF!+#REF!*#REF!*#REF!+#REF!*#REF!*#REF! -> #REF! | BP10: =BN10-BO10 -> #REF!
A11: 9 | B11: 120-GTD-519-SHT01 | C11: 0 | D11: CN-2880 | F11: 08331 | G11: GTD | H11: GAS TURBINE DRAINS | I11: 120-GTD-519-SHT01-1 | J11: 02 | K11: 9 | M11: LF | N11: 01HDPE | O11: =P11/AM11 -> #DIV/0! | P11: =L11*Q11*AN11+L11*S11*AO11+L11*U11*AP11+L11*W11*AQ11+L11*Y11*AR11+L11*AA11*AS11+L11*AC11*AT11+L11*AE11*AU11 -> 0 | R11: Receive | T11: Stage | V11: Erect | X11: Connect | Z11: Jeep/Trace | AB11: Mech. Sell Off | AD11: Test | AF11: Post | AJ11: 1 | AK11: Jerry | AN11: 0.02 | AO11: 0.03 | AP11: 0.2 | AQ11: 0.3 | AR11: 0.1 | AS11: 0.1 | AT11: 0.15 | AU11: 0.1 | AV11: 120 | AW11: N/A | AX11: N/A | AY11: N/A | BD11: =#REF!*#REF!+#REF!*#REF!+#REF!*#REF!+#REF!*#REF!+#REF!*#REF! -> #REF! | BE11: =#REF!*#REF!*#REF!+#REF!*#REF!*#REF!+#REF!*#REF!*#REF!+#REF!*#REF!*#REF!+#REF!*#REF!*#REF! -> #REF! | BF11: =BD11-BE11 -> #REF! | BG11: =#REF!*#REF!*#REF! -> #REF! | BH11: =#REF!*#REF!*#REF! -> #REF! | BI11: =#REF!*#REF!*#REF! -> #REF! | BJ11: =BH11+BI11 -> #REF! | BK11: =BG11+BH11+BI11 -> #REF! | BL11: =#REF!*#REF! -> #REF! | BM11: =BE11/BD11 -> #REF! | BN11: =#REF!*#REF!+#REF!*#REF!+#REF!*#REF!+#REF!*#REF!+#REF!*#REF! -> #REF! | BO11: =#REF!*#REF!*#REF!+#REF!*#REF!*#REF!+#REF!*#REF!*#REF!+#REF!*#REF!*#REF!+#REF!*#REF!*#REF! -> #REF! | BP11: =BN11-BO11 -> #REF!
A12: 10 | B12: 120-GTD-519-SHT01 | C12: 0 | D12: CN-2880 | F12: 08332 | G12: GTD | H12: GAS TURBINE DRAINS | I12: 120-GTD-519-SHT01-2 | J12: 06 | K12: 24 | M12: LF | N12: 01HDPE | O12: =P12/AM12 -> #DIV/0! | P12: =L12*Q12*AN12+L12*S12*AO12+L12*U12*AP12+L12*W12*AQ12+L12*Y12*AR12+L12*AA12*AS12+L12*AC12*AT12+L12*AE12*AU12 -> 0 | R12: Receive | T12: Stage | V12: Erect | X12: Connect | Z12: Jeep/Trace | AB12: Mech. Sell Off | AD12: Test | AF12: Post | AJ12: 1 | AK12: Sandra | AN12: 0.02 | AO12: 0.03 | AP12: 0.2 | AQ12: 0.3 | AR12: 0.1 | AS12: 0.1 | AT12: 0.15 | AU12: 0.1 | AV12: 120 | AW12: N/A | AX12: N/A | AY12: N/A | BD12: =#REF!*#REF!+#REF!*#REF!+#REF!*#REF!+#REF!*#REF!+#REF!*#REF! -> #REF! | BE12: =#REF!*#REF!*#REF!+#REF!*#REF!*#REF!+#REF!*#REF!*#REF!+#REF!*#REF!*#REF!+#REF!*#REF!*#REF! -> #REF! | BF12: =BD12-BE12 -> #REF! | BG12: =#REF!*#REF!*#REF! -> #REF! | BH12: =#REF!*#REF!*#REF! -> #REF! | BI12: =#REF!*#REF!*#REF! -> #REF! | BJ12: =BH12+BI12 -> #REF! | BK12: =BG12+BH12+BI12 -> #REF! | BL12: =#REF!*#REF! -> #REF! | BM12: =BE12/BD12 -> #REF! | BN12: =#REF!*#REF!+#REF!*#REF!+#REF!*#REF!+#REF!*#REF!+#REF!*#REF! -> #REF! | BO12: =#REF!*#REF!*#REF!+#REF!*#REF!*#REF!+#REF!*#REF!*#REF!+#REF!*#REF!*#REF!+#REF!*#REF!*#REF! -> #REF! | BP12: =BN12-BO12 -> #REF!
A13: 11 | B13: 120-GTD-519-SHT02 | C13: 0 | D13: CN-2880 | F13: 08332 | G13: GTD | H13: GAS TURBINE DRAINS | I13: 120-GTD-519-SHT02-1 | J13: 06 | K13: 47 | M13: LF | N13: 01HDPE | O13: =P13/AM13 -> #DIV/0! | P13: =L13*Q13*AN13+L13*S13*AO13+L13*U13*AP13+L13*W13*AQ13+L13*Y13*AR13+L13*AA13*AS13+L13*AC13*AT13+L13*AE13*AU13 -> 0 | R13: Receive | T13: Stage | V13: Erect | X13: Connect | Z13: Jeep/Trace | AB13: Mech. Sell Off | AD13: Test | AF13: Post | AJ13: 1 | AK13: Bob | AN13: 0.02 | AO13: 0.03 | AP13: 0.2 | AQ13: 0.3 | AR13: 0.1 | AS13: 0.1 | AT13: 0.15 | AU13: 0.1 | AV13: 120 | AW13: N/A | AX13: N/A | AY13: N/A | BD13: =#REF!*#REF!+#REF!*#REF!+#REF!*#REF!+#REF!*#REF!+#REF!*#REF! -> #REF! | BE13: =#REF!*#REF!*#REF!+#REF!*#REF!*#REF!+#REF!*#REF!*#REF!+#REF!*#REF!*#REF!+#REF!*#REF!*#REF! -> #REF! | BF13: =BD13-BE13 -> #REF! | BG13: =#REF!*#REF!*#REF! -> #REF! | BH13: =#REF!*#REF!*#REF! -> #REF! | BI13: =#REF!*#REF!*#REF! -> #REF! | BJ13: =BH13+BI13 -> #REF! | BK13: =BG13+BH13+BI13 -> #REF! | BL13: =#REF!*#REF! -> #REF! | BM13: =BE13/BD13 -> #REF! | BN13: =#REF!*#REF!+#REF!*#REF!+#REF!*#REF!+#REF!*#REF!+#REF!*#REF! -> #REF! | BO13: =#REF!*#REF!*#REF!+#REF!*#REF!*#REF!+#REF!*#REF!*#REF!+#REF!*#REF!*#REF!+#REF!*#REF!*#REF! -> #REF! | BP13: =BN13-BO13 -> #REF!
A14: 12 | B14: 120-GTD-519-SHT03 | C14: 0 | D14: CN-2880 | F14: 08332 | G14: GTD | H14: GAS TURBINE DRAINS | I14: 120-GTD-519-SHT03-1 | J14: 06 | K14: 105 | M14: LF | N14: 01HDPE | O14: =P14/AM14 -> #DIV/0! | P14: =L14*Q14*AN14+L14*S14*AO14+L14*U14*AP14+L14*W14*AQ14+L14*Y14*AR14+L14*AA14*AS14+L14*AC14*AT14+L14*AE14*AU14 -> 0 | R14: Receive | T14: Stage | V14: Erect | X14: Connect | Z14: Jeep/Trace | AB14: Mech. Sell Off | AD14: Test | AF14: Post | AJ14: 1 | AK14: Jose | AN14: 0.02 | AO14: 0.03 | AP14: 0.2 | AQ14: 0.3 | AR14: 0.1 | AS14: 0.1 | AT14: 0.15 | AU14: 0.1 | AV14: 120 | AW14: N/A | AX14: N/A | AY14: N/A | BD14: =#REF!*#REF!+#REF!*#REF!+#REF!*#REF!+#REF!*#REF!+#REF!*#REF! -> #REF! | BE14: =#REF!*#REF!*#REF!+#REF!*#REF!*#REF!+#REF!*#REF!*#REF!+#REF!*#REF!*#REF!+#REF!*#REF!*#REF! -> #REF! | BF14: =BD14-BE14 -> #REF! | BG14: =#REF!*#REF!*#REF! -> #REF! | BH14: =#REF!*#REF!*#REF! -> #REF! | BI14: =#REF!*#REF!*#REF! -> #REF! | BJ14: =BH14+BI14 -> #REF! | BK14: =BG14+BH14+BI14 -> #REF! | BL14: =#REF!*#REF! -> #REF! | BM14: =BE14/BD14 -> #REF! | BN14: =#REF!*#REF!+#REF!*#REF!+#REF!*#REF!+#REF!*#REF!+#REF!*#REF! -> #REF! | BO14: =#REF!*#REF!*#REF!+#REF!*#REF!*#REF!+#REF!*#REF!*#REF!+#REF!*#REF!*#REF!+#REF!*#REF!*#REF! -> #REF! | BP14: =BN14-BO14 -> #REF!
A15: 13 | B15: 120-GTD-537-SHT01 | C15: 0 | D15: CN-2880 | F15: 08331 | G15: GTD | H15: GAS TURBINE DRAINS | I15: 120-GTD-537-SHT01-1 | J15: 02 | K15: 8 | M15: LF | N15: 01HDPE | O15: =P15/AM15 -> #DIV/0! | P15: =L15*Q15*AN15+L15*S15*AO15+L15*U15*AP15+L15*W15*AQ15+L15*Y15*AR15+L15*AA15*AS15+L15*AC15*AT15+L15*AE15*AU15 -> 0 | R15: Receive | T15: Stage | V15: Erect | X15: Connect | Z15: Jeep/Trace | AB15: Mech. Sell Off | AD15: Test | AF15: Post | AJ15: 1 | AK15: Juan | AN15: 0.02 | AO15: 0.03 | AP15: 0.2 | AQ15: 0.3 | AR15: 0.1 | AS15: 0.1 | AT15: 0.15 | AU15: 0.1 | AV15: 120 | AW15: N/A | AX15: N/A | AY15: N/A | BD15: =#REF!*#REF!+#REF!*#REF!+#REF!*#REF!+#REF!*#REF!+#REF!*#REF! -> #REF! | BE15: =#REF!*#REF!*#REF!+#REF!*#REF!*#REF!+#REF!*#REF!*#REF!+#REF!*#REF!*#REF!+#REF!*#REF!*#REF! -> #REF! | BF15: =BD15-BE15 -> #REF! | BG15: =#REF!*#REF!*#REF! -> #REF! | BH15: =#REF!*#REF!*#REF! -> #REF! | BI15: =#REF!*#REF!*#REF! -> #REF! | BJ15: =BH15+BI15 -> #REF! | BK15: =BG15+BH15+BI15 -> #REF! | BL15: =#REF!*#REF! -> #REF! | BM15: =BE15/BD15 -> #REF! | BN15: =#REF!*#REF!+#REF!*#REF!+#REF!*#REF!+#REF!*#REF!+#REF!*#REF! -> #REF! | BO15: =#REF!*#REF!*#REF!+#REF!*#REF!*#REF!+#REF!*#REF!*#REF!+#REF!*#REF!*#REF!+#REF!*#REF!*#REF! -> #REF! | BP15: =BN15-BO15 -> #REF!
A16: 14 | B16: 120-GTD-537-SHT01 | C16: 0 | D16: CN-2880 | F16: 08332 | G16: GTD | H16: GAS TURBINE DRAINS | I16: 120-GTD-537-SHT01-2 | J16: 06 | K16: 44 | M16: LF | N16: 01HDPE | O16: =P16/AM16 -> #DIV/0! | P16: =L16*Q16*AN16+L16*S16*AO16+L16*U16*AP16+L16*W16*AQ16+L16*Y16*AR16+L16*AA16*AS16+L16*AC16*AT16+L16*AE16*AU16 -> 0 | R16: Receive | T16: Stage | V16: Erect | X16: Connect | Z16: Jeep/Trace | AB16: Mech. Sell Off | AD16: Test | AF16: Post | AJ16: 1 | AK16: Jerry | AN16: 0.02 | AO16: 0.03 | AP16: 0.2 | AQ16: 0.3 | AR16: 0.1 | AS16: 0.1 | AT16: 0.15 | AU16: 0.1 | AV16: 120 | AW16: N/A | AX16: N/A | AY16: N/A | BD16: =#REF!*#REF!+#REF!*#REF!+#REF!*#REF!+#REF!*#REF!+#REF!*#REF! -> #REF! | BE16: =#REF!*#REF!*#REF!+#REF!*#REF!*#REF!+#REF!*#REF!*#REF!+#REF!*#REF!*#REF!+#REF!*#REF!*#REF! -> #REF! | BF16: =BD16-BE16 -> #REF! | BG16: =#REF!*#REF!*#REF! -> #REF! | BH16: =#REF!*#REF!*#REF! -> #REF! | BI16: =#REF!*#REF!*#REF! -> #REF! | BJ16: =BH16+BI16 -> #REF! | BK16: =BG16+BH16+BI16 -> #REF! | BL16: =#REF!*#REF! -> #REF! | BM16: =BE16/BD16 -> #REF! | BN16: =#REF!*#REF!+#REF!*#REF!+#REF!*#REF!+#REF!*#REF!+#REF!*#REF! -> #REF! | BO16: =#REF!*#REF!*#REF!+#REF!*#REF!*#REF!+#REF!*#REF!*#REF!+#REF!*#REF!*#REF!+#REF!*#REF!*#REF! -> #REF! | BP16: =BN16-BO16 -> #REF!
A17: 15 | B17: 120-GTD-537-SHT02 | C17: 0 | D17: CN-2880 | F17: 08332 | G17: GTD | H17: GAS TURBINE DRAINS | I17: 120-GTD-537-SHT02-1 | J17: 06 | K17: 29 | M17: LF | N17: 01HDPE | O17: =P17/AM17 -> #DIV/0! | P17: =L17*Q17*AN17+L17*S17*AO17+L17*U17*AP17+L17*W17*AQ17+L17*Y17*AR17+L17*AA17*AS17+L17*AC17*AT17+L17*AE17*AU17 -> 0 | R17: Receive | T17: Stage | V17: Erect | X17: Connect | Z17: Jeep/Trace | AB17: Mech. Sell Off | AD17: Test | AF17: Post | AJ17: 1 | AK17: Sandra | AN17: 0.02 | AO17: 0.03 | AP17: 0.2 | AQ17: 0.3 | AR17: 0.1 | AS17: 0.1 | AT17: 0.15 | AU17: 0.1 | AV17: 120 | AW17: N/A | AX17: N/A | AY17: N/A | BD17: =#REF!*#REF!+#REF!*#REF!+#REF!*#REF!+#REF!*#REF!+#REF!*#REF! -> #REF! | BE17: =#REF!*#REF!*#REF!+#REF!*#REF!*#REF!+#REF!*#REF!*#REF!+#REF!*#REF!*#REF!+#REF!*#REF!*#REF! -> #REF! | BF17: =BD17-BE17 -> #REF! | BG17: =#REF!*#REF!*#REF! -> #REF! | BH17: =#REF!*#REF!*#REF! -> #REF! | BI17: =#REF!*#REF!*#REF! -> #REF! | BJ17: =BH17+BI17 -> #REF! | BK17: =BG17+BH17+BI17 -> #REF! | BL17: =#REF!*#REF! -> #REF! | BM17: =BE17/BD17 -> #REF! | BN17: =#REF!*#REF!+#REF!*#REF!+#REF!*#REF!+#REF!*#REF!+#REF!*#REF! -> #REF! | BO17: =#REF!*#REF!*#REF!+#REF!*#REF!*#REF!+#REF!*#REF!*#REF!+#REF!*#REF!*#REF!+#REF!*#REF!*#REF! -> #REF! | BP17: =BN17-BO17 -> #REF!
A18: 16 | B18: 120-GTD-537-SHT03 | C18: 0 | D18: CN-2880 | F18: 08332 | G18: GTD | H18: GAS TURBINE DRAINS | I18: 120-GTD-537-SHT03-1 | J18: 06 | K18: 97 | M18: LF | N18: 01HDPE | O18: =P18/AM18 -> #DIV/0! | P18: =L18*Q18*AN18+L18*S18*AO18+L18*U18*AP18+L18*W18*AQ18+L18*Y18*AR18+L18*AA18*AS18+L18*AC18*AT18+L18*AE18*AU18 -> 0 | R18: Receive | T18: Stage | V18: Erect | X18: Connect | Z18: Jeep/Trace | AB18: Mech. Sell Off | AD18: Test | AF18: Post | AJ18: 1 | AK18: Bob | AN18: 0.02 | AO18: 0.03 | AP18: 0.2 | AQ18: 0.3 | AR18: 0.1 | AS18: 0.1 | AT18: 0.15 | AU18: 0.1 | AV18: 120 | AW18: N/A | AX18: N/A | AY18: N/A | BD18: =#REF!*#REF!+#REF!*#REF!+#REF!*#REF!+#REF!*#REF!+#REF!*#REF! -> #REF! | BE18: =#REF!*#REF!*#REF!+#REF!*#REF!*#REF!+#REF!*#REF!*#REF!+#REF!*#REF!*#REF!+#REF!*#REF!*#REF! -> #REF! | BF18: =BD18-BE18 -> #REF! | BG18: =#REF!*#REF!*#REF! -> #REF! | BH18: =#REF!*#REF!*#REF! -> #REF! | BI18: =#REF!*#REF!*#REF! -> #REF! | BJ18: =BH18+BI18 -> #REF! | BK18: =BG18+BH18+BI18 -> #REF! | BL18: =#REF!*#REF! -> #REF! | BM18: =BE18/BD18 -> #REF! | BN18: =#REF!*#REF!+#REF!*#REF!+#REF!*#REF!+#REF!*#REF!+#REF!*#REF! -> #REF! | BO18: =#REF!*#REF!*#REF!+#REF!*#REF!*#REF!+#REF!*#REF!*#REF!+#REF!*#REF!*#REF!+#REF!*#REF!*#REF! -> #REF! | BP18: =BN18-BO18 -> #REF!
A19: 17 | B19: 120-GTD-537-SHT04 | C19: 0 | D19: CN-2880 | F19: 08332 | G19: GTD | H19: GAS TURBINE DRAINS | I19: 120-GTD-537-SHT04-1 | J19: 06 | K19: 32 | M19: LF | N19: 01HDPE | O19: =P19/AM19 -> #DIV/0! | P19: =L19*Q19*AN19+L19*S19*AO19+L19*U19*AP19+L19*W19*AQ19+L19*Y19*AR19+L19*AA19*AS19+L19*AC19*AT19+L19*AE19*AU19 -> 0 | R19: Receive | T19: Stage | V19: Erect | X19: Connect | Z19: Jeep/Trace | AB19: Mech. Sell Off | AD19: Test | AF19: Post | AJ19: 1 | AK19: Jose | AN19: 0.02 | AO19: 0.03 | AP19: 0.2 | AQ19: 0.3 | AR19: 0.1 | AS19: 0.1 | AT19: 0.15 | AU19: 0.1 | AV19: 120 | AW19: N/A | AX19: N/A | AY19: N/A | BD19: =#REF!*#REF!+#REF!*#REF!+#REF!*#REF!+#REF!*#REF!+#REF!*#REF! -> #REF! | BE19: =#REF!*#REF!*#REF!+#REF!*#REF!*#REF!+#REF!*#REF!*#REF!+#REF!*#REF!*#REF!+#REF!*#REF!*#REF! -> #REF! | BF19: =BD19-BE19 -> #REF! | BG19: =#REF!*#REF!*#REF! -> #REF! | BH19: =#REF!*#REF!*#REF! -> #REF! | BI19: =#REF!*#REF!*#REF! -> #REF! | BJ19: =BH19+BI19 -> #REF! | BK19: =BG19+BH19+BI19 -> #REF! | BL19: =#REF!*#REF! -> #REF! | BM19: =BE19/BD19 -> #REF! | BN19: =#REF!*#REF!+#REF!*#REF!+#REF!*#REF!+#REF!*#REF!+#REF!*#REF! -> #REF! | BO19: =#REF!*#REF!*#REF!+#REF!*#REF!*#REF!+#REF!*#REF!*#REF!+#REF!*#REF!*#REF!+#REF!*#REF!*#REF! -> #REF! | BP19: =BN19-BO19 -> #REF!
A20: 18 | B20: 120-IA-1210-SHT01 | C20: 0 | D20: CN-2910 | F20: 08211 | G20: IA | H20: INSTRUMENT AIR | I20: 120-IA-1210-SHT01-1 | J20: 02 | K20: 32 | M20: LF | N20: 01CS150 | O20: =P20/AM20 -> #DIV/0! | P20: =L20*Q20*AN20+L20*S20*AO20+L20*U20*AP20+L20*W20*AQ20+L20*Y20*AR20+L20*AA20*AS20+L20*AC20*AT20+L20*AE20*AU20 -> 0 | R20: Receive | T20: Stage | V20: Erect | X20: Connect | Z20: Supts | AB20: Punch | AD20: Test | AF20: Post | AI20: PI-401-003 | AJ20: 1 | AK20: Juan | AN20: 0.02 | AO20: 0.03 | AP20: 0.2 | AQ20: 0.3 | AR20: 0.1 | AS20: 0.1 | AT20: 0.15 | AU20: 0.1 | AV20: 401 | AW20: CTCE1000-D014 | AX20: N/A | AY20: N/A | BD20: =#REF!*#REF!+#REF!*#REF!+#REF!*#REF!+#REF!*#REF!+#REF!*#REF! -> #REF! | BE20: =#REF!*#REF!*#REF!+#REF!*#REF!*#REF!+#REF!*#REF!*#REF!+#REF!*#REF!*#REF!+#REF!*#REF!*#REF! -> #REF! | BF20: =BD20-BE20 -> #REF! | BG20: =#REF!*#REF!*#REF! -> #REF! | BH20: =#REF!*#REF!*#REF! -> #REF! | BI20: =#REF!*#REF!*#REF! -> #REF! | BJ20: =BH20+BI20 -> #REF! | BK20: =BG20+BH20+BI20 -> #REF! | BL20: =#REF!*#REF! -> #REF! | BM20: =BE20/BD20 -> #REF! | BN20: =#REF!*#REF!+#REF!*#REF!+#REF!*#REF!+#REF!*#REF!+#REF!*#REF! -> #REF! | BO20: =#REF!*#REF!*#REF!+#REF!*#REF!*#REF!+#REF!*#REF!*#REF!+#REF!*#REF!*#REF!+#REF!*#REF!*#REF! -> #REF! | BP20: =BN20-BO20 -> #REF!
A21: 19 | B21: 120-IA-1210-SHT02 | C21: 0 | D21: CN-2910 | F21: 08211 | G21: IA | H21: INSTRUMENT AIR | I21: 120-IA-1210-SHT02-1 | J21: 02 | K21: 63 | M21: LF | N21: 01CS150 | O21: =P21/AM21 -> #DIV/0! | P21: =L21*Q21*AN21+L21*S21*AO21+L21*U21*AP21+L21*W21*AQ21+L21*Y21*AR21+L21*AA21*AS21+L21*AC21*AT21+L21*AE21*AU21 -> 0 | R21: Receive | T21: Stage | V21: Erect | X21: Connect | Z21: Supts | AB21: Punch | AD21: Test | AF21: Post | AI21: PI-401-003 | AJ21: 1 | AK21: Jerry | AN21: 0.02 | AO21: 0.03 | AP21: 0.2 | AQ21: 0.3 | AR21: 0.1 | AS21: 0.1 | AT21: 0.15 | AU21: 0.1 | AV21: 401 | AW21: CTCE1000-D014 | AX21: N/A | AY21: N/A | BD21: =#REF!*#REF!+#REF!*#REF!+#REF!*#REF!+#REF!*#REF!+#REF!*#REF! -> #REF! | BE21: =#REF!*#REF!*#REF!+#REF!*#REF!*#REF!+#REF!*#REF!*#REF!+#REF!*#REF!*#REF!+#REF!*#REF!*#REF! -> #REF! | BF21: =BD21-BE21 -> #REF! | BG21: =#REF!*#REF!*#REF! -> #REF! | BH21: =#REF!*#REF!*#REF! -> #REF! | BI21: =#REF!*#REF!*#REF! -> #REF! | BJ21: =BH21+BI21 -> #REF! | BK21: =BG21+BH21+BI21 -> #REF! | BL21: =#REF!*#REF! -> #REF! | BM21: =BE21/BD21 -> #REF! | BN21: =#REF!*#REF!+#REF!*#REF!+#REF!*#REF!+#REF!*#REF!+#REF!*#REF! -> #REF! | BO21: =#REF!*#REF!*#REF!+#REF!*#REF!*#REF!+#REF!*#REF!*#REF!+#REF!*#REF!*#REF!+#REF!*#REF!*#REF! -> #REF! | BP21: =BN21-BO21 -> #REF!
A22: 20 | B22: 120-IA-1210-SHT03 | C22: 0 | D22: CN-2910 | F22: 08211 | G22: IA | H22: INSTRUMENT AIR | I22: 120-IA-1210-SHT03-1 | J22: 02 | K22: 53 | M22: LF | N22: 01CS150 | O22: =P22/AM22 -> #DIV/0! | P22: =L22*Q22*AN22+L22*S22*AO22+L22*U22*AP22+L22*W22*AQ22+L22*Y22*AR22+L22*AA22*AS22+L22*AC22*AT22+L22*AE22*AU22 -> 0 | R22: Receive | T22: Stage | V22: Erect | X22: Connect | Z22: Supts | AB22: Punch | AD22: Test | AF22: Post | AI22: PI-401-003 | AJ22: 1 | AK22: Sandra | AN22: 0.02 | AO22: 0.03 | AP22: 0.2 | AQ22: 0.3 | AR22: 0.1 | AS22: 0.1 | AT22: 0.15 | AU22: 0.1 | AV22: 401 | AW22: CTCE1000-D014 | AX22: N/A | AY22: N/A | BD22: =#REF!*#REF!+#REF!*#REF!+#REF!*#REF!+#REF!*#REF!+#REF!*#REF! -> #REF! | BE22: =#REF!*#REF!*#REF!+#REF!*#REF!*#REF!+#REF!*#REF!*#REF!+#REF!*#REF!*#REF!+#REF!*#REF!*#REF! -> #REF! | BF22: =BD22-BE22 -> #REF! | BG22: =#REF!*#REF!*#REF! -> #REF! | BH22: =#REF!*#REF!*#REF! -> #REF! | BI22: =#REF!*#REF!*#REF! -> #REF! | BJ22: =BH22+BI22 -> #REF! | BK22: =BG22+BH22+BI22 -> #REF! | BL22: =#REF!*#REF! -> #REF! | BM22: =BE22/BD22 -> #REF! | BN22: =#REF!*#REF!+#REF!*#REF!+#REF!*#REF!+#REF!*#REF!+#REF!*#REF! -> #REF! | BO22: =#REF!*#REF!*#REF!+#REF!*#REF!*#REF!+#REF!*#REF!*#REF!+#REF!*#REF!*#REF!+#REF!*#REF!*#REF! -> #REF! | BP22: =BN22-BO22 -> #REF!
A23: 21 | B23: 120-IA-1210-SHT04 | C23: 0 | D23: CN-2910 | F23: 08211 | G23: IA | H23: INSTRUMENT AIR | I23: 120-IA-1210-SHT04-1 | J23: 02 | K23: 80 | M23: LF | N23: 01CS150 | O23: =P23/AM23 -> #DIV/0! | P23: =L23*Q23*AN23+L23*S23*AO23+L23*U23*AP23+L23*W23*AQ23+L23*Y23*AR23+L23*AA23*AS23+L23*AC23*AT23+L23*AE23*AU23 -> 0 | R23: Receive | T23: Stage | V23: Erect | X23: Connect | Z23: Supts | AB23: Punch | AD23: Test | AF23: Post | AI23: PI-401-003 | AJ23: 1 | AK23: Bob | AN23: 0.02 | AO23: 0.03 | AP23: 0.2 | AQ23: 0.3 | AR23: 0.1 | AS23: 0.1 | AT23: 0.15 | AU23: 0.1 | AV23: 401 | AW23: CTCE1000-D014 | AX23: N/A | AY23: N/A | BD23: =#REF!*#REF!+#REF!*#REF!+#REF!*#REF!+#REF!*#REF!+#REF!*#REF! -> #REF! | BE23: =#REF!*#REF!*#REF!+#REF!*#REF!*#REF!+#REF!*#REF!*#REF!+#REF!*#REF!*#REF!+#REF!*#REF!*#REF! -> #REF! | BF23: =BD23-BE23 -> #REF! | BG23: =#REF!*#REF!*#REF! -> #REF! | BH23: =#REF!*#REF!*#REF! -> #REF! | BI23: =#REF!*#REF!*#REF! -> #REF! | BJ23: =BH23+BI23 -> #REF! | BK23: =BG23+BH23+BI23 -> #REF! | BL23: =#REF!*#REF! -> #REF! | BM23: =BE23/BD23 -> #REF! | BN23: =#REF!*#REF!+#REF!*#REF!+#REF!*#REF!+#REF!*#REF!+#REF!*#REF! -> #REF! | BO23: =#REF!*#REF!*#REF!+#REF!*#REF!*#REF!+#REF!*#REF!*#REF!+#REF!*#REF!*#REF!+#REF!*#REF!*#REF! -> #REF! | BP23: =BN23-BO23 -> #REF!
A24: 22 | B24: 120-IA-1210-SHT05 | C24: 0 | D24: CN-2910 | F24: 08211 | G24: IA | H24: INSTRUMENT AIR | I24: 120-IA-1210-SHT05-1 | J24: 02 | K24: 54 | M24: LF | N24: 01CS150 | O24: =P24/AM24 -> #DIV/0! | P24: =L24*Q24*AN24+L24*S24*AO24+L24*U24*AP24+L24*W24*AQ24+L24*Y24*AR24+L24*AA24*AS24+L24*AC24*AT24+L24*AE24*AU24 -> 0 | R24: Receive | T24: Stage | V24: Erect | X24: Connect | Z24: Supts | AB24: Punch | AD24: Test | AF24: Post | AI24: PI-401-003 | AJ24: 1 | AK24: Jose | AN24: 0.02 | AO24: 0.03 | AP24: 0.2 | AQ24: 0.3 | AR24: 0.1 | AS24: 0.1 | AT24: 0.15 | AU24: 0.1 | AV24: 401 | AW24: CTCE1000-D014 | AX24: N/A | AY24: N/A | BD24: =#REF!*#REF!+#REF!*#REF!+#REF!*#REF!+#REF!*#REF!+#REF!*#REF! -> #REF! | BE24: =#REF!*#REF!*#REF!+#REF!*#REF!*#REF!+#REF!*#REF!*#REF!+#REF!*#REF!*#REF!+#REF!*#REF!*#REF! -> #REF! | BF24: =BD24-BE24 -> #REF! | BG24: =#REF!*#REF!*#REF! -> #REF! | BH24: =#REF!*#REF!*#REF! -> #REF! | BI24: =#REF!*#REF!*#REF! -> #REF! | BJ24: =BH24+BI24 -> #REF! | BK24: =BG24+BH24+BI24 -> #REF! | BL24: =#REF!*#REF! -> #REF! | BM24: =BE24/BD24 -> #REF! | BN24: =#REF!*#REF!+#REF!*#REF!+#REF!*#REF!+#REF!*#REF!+#REF!*#REF! -> #REF! | BO24: =#REF!*#REF!*#REF!+#REF!*#REF!*#REF!+#REF!*#REF!*#REF!+#REF!*#REF!*#REF!+#REF!*#REF!*#REF! -> #REF! | BP24: =BN24-BO24 -> #REF!
A25: 23 | B25: 120-IA-1230-SHT01 | C25: 0 | D25: CN-2910 | F25: 08211 | G25: IA | H25: INSTRUMENT AIR | I25: 120-IA-1230-SHT01-1 | J25: 02 | K25: 43 | M25: LF | N25: 01CS150 | O25: =P25/AM25 -> #DIV/0! | P25: =L25*Q25*AN25+L25*S25*AO25+L25*U25*AP25+L25*W25*AQ25+L25*Y25*AR25+L25*AA25*AS25+L25*AC25*AT25+L25*AE25*AU25 -> 0 | R25: Receive | T25: Stage | V25: Erect | X25: Connect | Z25: Supts | AB25: Punch | AD25: Test | AF25: Post | AJ25: 1 | AK25: Juan | AN25: 0.02 | AO25: 0.03 | AP25: 0.2 | AQ25: 0.3 | AR25: 0.1 | AS25: 0.1 | AT25: 0.15 | AU25: 0.1 | AV25: 120 | AW25: CTCE1000-D014 | AX25: N/A | AY25: N/A | BD25: =#REF!*#REF!+#REF!*#REF!+#REF!*#REF!+#REF!*#REF!+#REF!*#REF! -> #REF! | BE25: =#REF!*#REF!*#REF!+#REF!*#REF!*#REF!+#REF!*#REF!*#REF!+#REF!*#REF!*#REF!+#REF!*#REF!*#REF! -> #REF! | BF25: =BD25-BE25 -> #REF! | BG25: =#REF!*#REF!*#REF! -> #REF! | BH25: =#REF!*#REF!*#REF! -> #REF! | BI25: =#REF!*#REF!*#REF! -> #REF! | BJ25: =BH25+BI25 -> #REF! | BK25: =BG25+BH25+BI25 -> #REF! | BL25: =#REF!*#REF! -> #REF! | BM25: =BE25/BD25 -> #REF! | BN25: =#REF!*#REF!+#REF!*#REF!+#REF!*#REF!+#REF!*#REF!+#REF!*#REF! -> #REF! | BO25: =#REF!*#REF!*#REF!+#REF!*#REF!*#REF!+#REF!*#REF!*#REF!+#REF!*#REF!*#REF!+#REF!*#REF!*#REF! -> #REF! | BP25: =BN25-BO25 -> #REF!
A26: 24 | B26: 120-IA-1230-SHT02 | C26: 0 | D26: CN-2910 | F26: 08211 | G26: IA | H26: INSTRUMENT AIR | I26: 120-IA-1230-SHT02-1 | J26: 02 | K26: 53 | M26: LF | N26: 01CS150 | O26: =P26/AM26 -> #DIV/0! | P26: =L26*Q26*AN26+L26*S26*AO26+L26*U26*AP26+L26*W26*AQ26+L26*Y26*AR26+L26*AA26*AS26+L26*AC26*AT26+L26*AE26*AU26 -> 0 | R26: Receive | T26: Stage | V26: Erect | X26: Connect | Z26: Supts | AB26: Punch | AD26: Test | AF26: Post | AJ26: 1 | AK26: Jerry | AN26: 0.02 | AO26: 0.03 | AP26: 0.2 | AQ26: 0.3 | AR26: 0.1 | AS26: 0.1 | AT26: 0.15 | AU26: 0.1 | AV26: 120 | AW26: CTCE1000-D014 | AX26: N/A | AY26: N/A | BD26: =#REF!*#REF!+#REF!*#REF!+#REF!*#REF!+#REF!*#REF!+#REF!*#REF! -> #REF! | BE26: =#REF!*#REF!*#REF!+#REF!*#REF!*#REF!+#REF!*#REF!*#REF!+#REF!*#REF!*#REF!+#REF!*#REF!*#REF! -> #REF! | BF26: =BD26-BE26 -> #REF! | BG26: =#REF!*#REF!*#REF! -> #REF! | BH26: =#REF!*#REF!*#REF! -> #REF! | BI26: =#REF!*#REF!*#REF! -> #REF! | BJ26: =BH26+BI26 -> #REF! | BK26: =BG26+BH26+BI26 -> #REF! | BL26: =#REF!*#REF! -> #REF! | BM26: =BE26/BD26 -> #REF! | BN26: =#REF!*#REF!+#REF!*#REF!+#REF!*#REF!+#REF!*#REF!+#REF!*#REF! -> #REF! | BO26: =#REF!*#REF!*#REF!+#REF!*#REF!*#REF!+#REF!*#REF!*#REF!+#REF!*#REF!*#REF!+#REF!*#REF!*#REF! -> #REF! | BP26: =BN26-BO26 -> #REF!
A27: 25 | B27: 120-IA-1230-SHT03 | C27: 0 | D27: CN-2910 | F27: 08211 | G27: IA | H27: INSTRUMENT AIR | I27: 120-IA-1230-SHT03-1 | J27: 02 | K27: 82 | M27: LF | N27: 01CS150 | O27: =P27/AM27 -> #DIV/0! | P27: =L27*Q27*AN27+L27*S27*AO27+L27*U27*AP27+L27*W27*AQ27+L27*Y27*AR27+L27*AA27*AS27+L27*AC27*AT27+L27*AE27*AU27 -> 0 | R27: Receive | T27: Stage | V27: Erect | X27: Connect | Z27: Supts | AB27: Punch | AD27: Test | AF27: Post | AJ27: 1 | AK27: Sandra | AN27: 0.02 | AO27: 0.03 | AP27: 0.2 | AQ27: 0.3 | AR27: 0.1 | AS27: 0.1 | AT27: 0.15 | AU27: 0.1 | AV27: 120 | AW27: CTCE1000-D014 | AX27: N/A | AY27: N/A | BD27: =#REF!*#REF!+#REF!*#REF!+#REF!*#REF!+#REF!*#REF!+#REF!*#REF! -> #REF! | BE27: =#REF!*#REF!*#REF!+#REF!*#REF!*#REF!+#REF!*#REF!*#REF!+#REF!*#REF!*#REF!+#REF!*#REF!*#REF! -> #REF! | BF27: =BD27-BE27 -> #REF! | BG27: =#REF!*#REF!*#REF! -> #REF! | BH27: =#REF!*#REF!*#REF! -> #REF! | BI27: =#REF!*#REF!*#REF! -> #REF! | BJ27: =BH27+BI27 -> #REF! | BK27: =BG27+BH27+BI27 -> #REF! | BL27: =#REF!*#REF! -> #REF! | BM27: =BE27/BD27 -> #REF! | BN27: =#REF!*#REF!+#REF!*#REF!+#REF!*#REF!+#REF!*#REF!+#REF!*#REF! -> #REF! | BO27: =#REF!*#REF!*#REF!+#REF!*#REF!*#REF!+#REF!*#REF!*#REF!+#REF!*#REF!*#REF!+#REF!*#REF!*#REF! -> #REF! | BP27: =BN27-BO27 -> #REF!
A28: 26 | B28: 120-IA-1230-SHT04 | C28: 0 | D28: CN-2910 | F28: 08211 | G28: IA | H28: INSTRUMENT AIR | I28: 120-IA-1230-SHT04-1 | J28: 02 | K28: 50 | M28: LF | N28: 01CS150 | O28: =P28/AM28 -> #DIV/0! | P28: =L28*Q28*AN28+L28*S28*AO28+L28*U28*AP28+L28*W28*AQ28+L28*Y28*AR28+L28*AA28*AS28+L28*AC28*AT28+L28*AE28*AU28 -> 0 | R28: Receive | T28: Stage | V28: Erect | X28: Connect | Z28: Supts | AB28: Punch | AD28: Test | AF28: Post | AJ28: 1 | AK28: Bob | AN28: 0.02 | AO28: 0.03 | AP28: 0.2 | AQ28: 0.3 | AR28: 0.1 | AS28: 0.1 | AT28: 0.15 | AU28: 0.1 | AV28: 120 | AW28: CTCE1000-D014 | AX28: N/A | AY28: N/A | BD28: =#REF!*#REF!+#REF!*#REF!+#REF!*#REF!+#REF!*#REF!+#REF!*#REF! -> #REF! | BE28: =#REF!*#REF!*#REF!+#REF!*#REF!*#REF!+#REF!*#REF!*#REF!+#REF!*#REF!*#REF!+#REF!*#REF!*#REF! -> #REF! | BF28: =BD28-BE28 -> #REF! | BG28: =#REF!*#REF!*#REF! -> #REF! | BH28: =#REF!*#REF!*#REF! -> #REF! | BI28: =#REF!*#REF!*#REF! -> #REF! | BJ28: =BH28+BI28 -> #REF! | BK28: =BG28+BH28+BI28 -> #REF! | BL28: =#REF!*#REF! -> #REF! | BM28: =BE28/BD28 -> #REF! | BN28: =#REF!*#REF!+#REF!*#REF!+#REF!*#REF!+#REF!*#REF!+#REF!*#REF! -> #REF! | BO28: =#REF!*#REF!*#REF!+#REF!*#REF!*#REF!+#REF!*#REF!*#REF!+#REF!*#REF!*#REF!+#REF!*#REF!*#REF! -> #REF! | BP28: =BN28-BO28 -> #REF!
A29: 27 | B29: 120-IA-1230-SHT05 | C29: 0 | D29: CN-2910 | F29: 08211 | G29: IA | H29: INSTRUMENT AIR | I29: 120-IA-1230-SHT05-1 | J29: 02 | K29: 31 | M29: LF | N29: 01CS150 | O29: =P29/AM29 -> #DIV/0! | P29: =L29*Q29*AN29+L29*S29*AO29+L29*U29*AP29+L29*W29*AQ29+L29*Y29*AR29+L29*AA29*AS29+L29*AC29*AT29+L29*AE29*AU29 -> 0 | R29: Receive | T29: Stage | V29: Erect | X29: Connect | Z29: Supts | AB29: Punch | AD29: Test | AF29: Post | AJ29: 1 | AK29: Jose | AN29: 0.02 | AO29: 0.03 | AP29: 0.2 | AQ29: 0.3 | AR29: 0.1 | AS29: 0.1 | AT29: 0.15 | AU29: 0.1 | AV29: 120 | AW29: CTCE1000-D014 | AX29: N/A | AY29: N/A | BD29: =#REF!*#REF!+#REF!*#REF!+#REF!*#REF!+#REF!*#REF!+#REF!*#REF! -> #REF! | BE29: =#REF!*#REF!*#REF!+#REF!*#REF!*#REF!+#REF!*#REF!*#REF!+#REF!*#REF!*#REF!+#REF!*#REF!*#REF! -> #REF! | BF29: =BD29-BE29 -> #REF! | BG29: =#REF!*#REF!*#REF! -> #REF! | BH29: =#REF!*#REF!*#REF! -> #REF! | BI29: =#REF!*#REF!*#REF! -> #REF! | BJ29: =BH29+BI29 -> #REF! | BK29: =BG29+BH29+BI29 -> #REF! | BL29: =#REF!*#REF! -> #REF! | BM29: =BE29/BD29 -> #REF! | BN29: =#REF!*#REF!+#REF!*#REF!+#REF!*#REF!+#REF!*#REF!+#REF!*#REF! -> #REF! | BO29: =#REF!*#REF!*#REF!+#REF!*#REF!*#REF!+#REF!*#REF!*#REF!+#REF!*#REF!*#REF!+#REF!*#REF!*#REF! -> #REF! | BP29: =BN29-BO29 -> #REF!
A30: 28 | B30: 120-GCW-802-SHT01 | C30: 0 | D30: CN-2850 | F30: 08331 | G30: GCW | H30: GLYCOL COOLING WATER | I30: 120-GCW-802-SHT01-1 | J30: 02 | K30: 146 | M30: LF | N30: 01HDPE | O30: =P30/AM30 -> #DIV/0! | P30: =L30*Q30*AN30+L30*S30*AO30+L30*U30*AP30+L30*W30*AQ30+L30*Y30*AR30+L30*AA30*AS30+L30*AC30*AT30+L30*AE30*AU30 -> 0 | R30: Receive | T30: Stage | V30: Erect | X30: Connect | Z30: Jeep/Trace | AB30: Mech. Sell Off | AD30: Test | AF30: Post | AI30: PI-401-002 | AJ30: 1 | AK30: Juan | AN30: 0.02 | AO30: 0.03 | AP30: 0.2 | AQ30: 0.3 | AR30: 0.1 | AS30: 0.1 | AT30: 0.15 | AU30: 0.1 | AV30: 401 | AW30: N/A | AX30: N/A | AY30: N/A | BD30: =#REF!*#REF!+#REF!*#REF!+#REF!*#REF!+#REF!*#REF!+#REF!*#REF! -> #REF! | BE30: =#REF!*#REF!*#REF!+#REF!*#REF!*#REF!+#REF!*#REF!*#REF!+#REF!*#REF!*#REF!+#REF!*#REF!*#REF! -> #REF! | BF30: =BD30-BE30 -> #REF! | BG30: =#REF!*#REF!*#REF! -> #REF! | BH30: =#REF!*#REF!*#REF! -> #REF! | BI30: =#REF!*#REF!*#REF! -> #REF! | BJ30: =BH30+BI30 -> #REF! | BK30: =BG30+BH30+BI30 -> #REF! | BL30: =#REF!*#REF! -> #REF! | BM30: =BE30/BD30 -> #REF! | BN30: =#REF!*#REF!+#REF!*#REF!+#REF!*#REF!+#REF!*#REF!+#REF!*#REF! -> #REF! | BO30: =#REF!*#REF!*#REF!+#REF!*#REF!*#REF!+#REF!*#REF!*#REF!+#REF!*#REF!*#REF!+#REF!*#REF!*#REF! -> #REF! | BP30: =BN30-BO30 -> #REF!
A31: 29 | B31: 120-GCW-802-SHT02 | C31: 0 | D31: CN-2850 | F31: 08332 | G31: GCW | H31: GLYCOL COOLING WATER | I31: 120-GCW-802-SHT02-1 | J31: 08 | K31: 21 | M31: LF | N31: 01HDPE | O31: =P31/AM31 -> #DIV/0! | P31: =L31*Q31*AN31+L31*S31*AO31+L31*U31*AP31+L31*W31*AQ31+L31*Y31*AR31+L31*AA31*AS31+L31*AC31*AT31+L31*AE31*AU31 -> 0 | R31: Receive | T31: Stage | V31: Erect | X31: Connect | Z31: Jeep/Trace | AB31: Mech. Sell Off | AD31: Test | AF31: Post | AI31: PI-401-002 | AJ31: 1 | AK31: Jerry | AN31: 0.02 | AO31: 0.03 | AP31: 0.2 | AQ31: 0.3 | AR31: 0.1 | AS31: 0.1 | AT31: 0.15 | AU31: 0.1 | AV31: 401 | AW31: N/A | AX31: N/A | AY31: N/A | BD31: =#REF!*#REF!+#REF!*#REF!+#REF!*#REF!+#REF!*#REF!+#REF!*#REF! -> #REF! | BE31: =#REF!*#REF!*#REF!+#REF!*#REF!*#REF!+#REF!*#REF!*#REF!+#REF!*#REF!*#REF!+#REF!*#REF!*#REF! -> #REF! | BF31: =BD31-BE31 -> #REF! | BG31: =#REF!*#REF!*#REF! -> #REF! | BH31: =#REF!*#REF!*#REF! -> #REF! | BI31: =#REF!*#REF!*#REF! -> #REF! | BJ31: =BH31+BI31 -> #REF! | BK31: =BG31+BH31+BI31 -> #REF! | BL31: =#REF!*#REF! -> #REF! | BM31: =BE31/BD31 -> #REF! | BN31: =#REF!*#REF!+#REF!*#REF!+#REF!*#REF!+#REF!*#REF!+#REF!*#REF! -> #REF! | BO31: =#REF!*#REF!*#REF!+#REF!*#REF!*#REF!+#REF!*#REF!*#REF!+#REF!*#REF!*#REF!+#REF!*#REF!*#REF! -> #REF! | BP31: =BN31-BO31 -> #REF!
A32: 30 | B32: 120-IA-1227-SHT01 | C32: 0 | D32: CN-2910 | F32: 08211 | G32: IA | H32: INSTRUMENT AIR | I32: 120-IA-1227-SHT01-1 | J32: 02 | K32: 63 | M32: LF | N32: 01CS150 | O32: =P32/AM32 -> #DIV/0! | P32: =L32*Q32*AN32+L32*S32*AO32+L32*U32*AP32+L32*W32*AQ32+L32*Y32*AR32+L32*AA32*AS32+L32*AC32*AT32+L32*AE32*AU32 -> 0 | R32: Receive | T32: Stage | V32: Erect | X32: Connect | Z32: Supts | AB32: Punch | AD32: Test | AF32: Post | AI32: PI-401-004 | AJ32: 1 | AK32: Sandra | AN32: 0.02 | AO32: 0.03 | AP32: 0.2 | AQ32: 0.3 | AR32: 0.1 | AS32: 0.1 | AT32: 0.15 | AU32: 0.1 | AV32: 401 | AW32: CTCE1000-D014 | AX32: N/A | AY32: N/A | BD32: =#REF!*#REF!+#REF!*#REF!+#REF!*#REF!+#REF!*#REF!+#REF!*#REF! -> #REF! | BE32: =#REF!*#REF!*#REF!+#REF!*#REF!*#REF!+#REF!*#REF!*#REF!+#REF!*#REF!*#REF!+#REF!*#REF!*#REF! -> #REF! | BF32: =BD32-BE32 -> #REF! | BG32: =#REF!*#REF!*#REF! -> #REF! | BH32: =#REF!*#REF!*#REF! -> #REF! | BI32: =#REF!*#REF!*#REF! -> #REF! | BJ32: =BH32+BI32 -> #REF! | BK32: =BG32+BH32+BI32 -> #REF! | BL32: =#REF!*#REF! -> #REF! | BM32: =BE32/BD32 -> #REF! | BN32: =#REF!*#REF!+#REF!*#REF!+#REF!*#REF!+#REF!*#REF!+#REF!*#REF! -> #REF! | BO32: =#REF!*#REF!*#REF!+#REF!*#REF!*#REF!+#REF!*#REF!*#REF!+#REF!*#REF!*#REF!+#REF!*#REF!*#REF! -> #REF! | BP32: =BN32-BO32 -> #REF!
A33: 31 | B33: 120-IA-1227-SHT02 | C33: 0 | D33: CN-2910 | F33: 08211 | G33: IA | H33: INSTRUMENT AIR | I33: 120-IA-1227-SHT02-1 | J33: 02 | K33: 38 | M33: LF | N33: 01CS150 | O33: =P33/AM33 -> #DIV/0! | P33: =L33*Q33*AN33+L33*S33*AO33+L33*U33*AP33+L33*W33*AQ33+L33*Y33*AR33+L33*AA33*AS33+L33*AC33*AT33+L33*AE33*AU33 -> 0 | R33: Receive | T33: Stage | V33: Erect | X33: Connect | Z33: Supts | AB33: Punch | AD33: Test | AF33: Post | AJ33: 1 | AK33: Bob | AN33: 0.02 | AO33: 0.03 | AP33: 0.2 | AQ33: 0.3 | AR33: 0.1 | AS33: 0.1 | AT33: 0.15 | AU33: 0.1 | AV33: 120 | AW33: CTCE1000-D014 | AX33: N/A | AY33: N/A | BD33: =#REF!*#REF!+#REF!*#REF!+#REF!*#REF!+#REF!*#REF!+#REF!*#REF! -> #REF! | BE33: =#REF!*#REF!*#REF!+#REF!*#REF!*#REF!+#REF!*#REF!*#REF!+#REF!*#REF!*#REF!+#REF!*#REF!*#REF! -> #REF! | BF33: =BD33-BE33 -> #REF! | BG33: =#REF!*#REF!*#REF! -> #REF! | BH33: =#REF!*#REF!*#REF! -> #REF! | BI33: =#REF!*#REF!*#REF! -> #REF! | BJ33: =BH33+BI33 -> #REF! | BK33: =BG33+BH33+BI33 -> #REF! | BL33: =#REF!*#REF! -> #REF! | BM33: =BE33/BD33 -> #REF! | BN33: =#REF!*#REF!+#REF!*#REF!+#REF!*#REF!+#REF!*#REF!+#REF!*#REF! -> #REF! | BO33: =#REF!*#REF!*#REF!+#REF!*#REF!*#REF!+#REF!*#REF!*#REF!+#REF!*#REF!*#REF!+#REF!*#REF!*#REF! -> #REF! | BP33: =BN33-BO33 -> #REF!
A34: 32 | B34: 120-IA-1227-SHT03 | C34: 0 | D34: CN-2910 | F34: 08211 | G34: IA | H34: INSTRUMENT AIR | I34: 120-IA-1227-SHT03-1 | J34: 02 | K34: 81 | M34: LF | N34: 01CS150 | O34: =P34/AM34 -> #DIV/0! | P34: =L34*Q34*AN34+L34*S34*AO34+L34*U34*AP34+L34*W34*AQ34+L34*Y34*AR34+L34*AA34*AS34+L34*AC34*AT34+L34*AE34*AU34 -> 0 | R34: Receive | T34: Stage | V34: Erect | X34: Connect | Z34: Supts | AB34: Punch | AD34: Test | AF34: Post | AJ34: 1 | AK34: Jose | AN34: 0.02 | AO34: 0.03 | AP34: 0.2 | AQ34: 0.3 | AR34: 0.1 | AS34: 0.1 | AT34: 0.15 | AU34: 0.1 | AV34: 120 | AW34: CTCE1000-D014 | AX34: N/A | AY34: N/A | BD34: =#REF!*#REF!+#REF!*#REF!+#REF!*#REF!+#REF!*#REF!+#REF!*#REF! -> #REF! | BE34: =#REF!*#REF!*#REF!+#REF!*#REF!*#REF!+#REF!*#REF!*#REF!+#REF!*#REF!*#REF!+#REF!*#REF!*#REF! -> #REF! | BF34: =BD34-BE34 -> #REF! | BG34: =#REF!*#REF!*#REF! -> #REF! | BH34: =#REF!*#REF!*#REF! -> #REF! | BI34: =#REF!*#REF!*#REF! -> #REF! | BJ34: =BH34+BI34 -> #REF! | BK34: =BG34+BH34+BI34 -> #REF! | BL34: =#REF!*#REF! -> #REF! | BM34: =BE34/BD34 -> #REF! | BN34: =#REF!*#REF!+#REF!*#REF!+#REF!*#REF!+#REF!*#REF!+#REF!*#REF! -> #REF! | BO34: =#REF!*#REF!*#REF!+#REF!*#REF!*#REF!+#REF!*#REF!*#REF!+#REF!*#REF!*#REF!+#REF!*#REF!*#REF! -> #REF! | BP34: =BN34-BO34 -> #REF!
A35: 33 | B35: 120-IA-1227-SHT04 | C35: 0 | D35: CN-2910 | F35: 08211 | G35: IA | H35: INSTRUMENT AIR | I35: 120-IA-1227-SHT04-1 | J35: 02 | K35: 38 | M35: LF | N35: 01CS150 | O35: =P35/AM35 -> #DIV/0! | P35: =L35*Q35*AN35+L35*S35*AO35+L35*U35*AP35+L35*W35*AQ35+L35*Y35*AR35+L35*AA35*AS35+L35*AC35*AT35+L35*AE35*AU35 -> 0 | R35: Receive | T35: Stage | V35: Erect | X35: Connect | Z35: Supts | AB35: Punch | AD35: Test | AF35: Post | AJ35: 1 | AK35: Juan | AN35: 0.02 | AO35: 0.03 | AP35: 0.2 | AQ35: 0.3 | AR35: 0.1 | AS35: 0.1 | AT35: 0.15 | AU35: 0.1 | AV35: 120 | AW35: CTCE1000-D014 | AX35: N/A | AY35: N/A | BD35: =#REF!*#REF!+#REF!*#REF!+#REF!*#REF!+#REF!*#REF!+#REF!*#REF! -> #REF! | BE35: =#REF!*#REF!*#REF!+#REF!*#REF!*#REF!+#REF!*#REF!*#REF!+#REF!*#REF!*#REF!+#REF!*#REF!*#REF! -> #REF! | BF35: =BD35-BE35 -> #REF! | BG35: =#REF!*#REF!*#REF! -> #REF! | BH35: =#REF!*#REF!*#REF! -> #REF! | BI35: =#REF!*#REF!*#REF! -> #REF! | BJ35: =BH35+BI35 -> #REF! | BK35: =BG35+BH35+BI35 -> #REF! | BL35: =#REF!*#REF! -> #REF! | BM35: =BE35/BD35 -> #REF! | BN35: =#REF!*#REF!+#REF!*#REF!+#REF!*#REF!+#REF!*#REF!+#REF!*#REF! -> #REF! | BO35: =#REF!*#REF!*#REF!+#REF!*#REF!*#REF!+#REF!*#REF!*#REF!+#REF!*#REF!*#REF!+#REF!*#REF!*#REF! -> #REF! | BP35: =BN35-BO35 -> #REF!
A36: 34 | B36: 120-DR-587-SHT01 | C36: 0 | D36: CN-2760 | F36: 08331 | G36: DR | H36: DRAINS DRR DRIPS RETURN | I36: 120-DR-587-SHT01-1 | J36: 02 | K36: 139 | M36: LF | N36: 01HDPE | O36: =P36/AM36 -> #DIV/0! | P36: =L36*Q36*AN36+L36*S36*AO36+L36*U36*AP36+L36*W36*AQ36+L36*Y36*AR36+L36*AA36*AS36+L36*AC36*AT36+L36*AE36*AU36 -> 0 | R36: Receive | T36: Stage | V36: Erect | X36: Connect | Z36: Jeep/Trace | AB36: Mech. Sell Off | AD36: Test | AF36: Post | AI36: PI-401-002 | AJ36: 1 | AK36: Jerry | AN36: 0.02 | AO36: 0.03 | AP36: 0.2 | AQ36: 0.3 | AR36: 0.1 | AS36: 0.1 | AT36: 0.15 | AU36: 0.1 | AV36: 401 | AW36: N/A | AX36: N/A | AY36: N/A | BD36: =#REF!*#REF!+#REF!*#REF!+#REF!*#REF!+#REF!*#REF!+#REF!*#REF! -> #REF! | BE36: =#REF!*#REF!*#REF!+#REF!*#REF!*#REF!+#REF!*#REF!*#REF!+#REF!*#REF!*#REF!+#REF!*#REF!*#REF! -> #REF! | BF36: =BD36-BE36 -> #REF! | BG36: =#REF!*#REF!*#REF! -> #REF! | BH36: =#REF!*#REF!*#REF! -> #REF! | BI36: =#REF!*#REF!*#REF! -> #REF! | BJ36: =BH36+BI36 -> #REF! | BK36: =BG36+BH36+BI36 -> #REF! | BL36: =#REF!*#REF! -> #REF! | BM36: =BE36/BD36 -> #REF! | BN36: =#REF!*#REF!+#REF!*#REF!+#REF!*#REF!+#REF!*#REF!+#REF!*#REF! -> #REF! | BO36: =#REF!*#REF!*#REF!+#REF!*#REF!*#REF!+#REF!*#REF!*#REF!+#REF!*#REF!*#REF!+#REF!*#REF!*#REF! -> #REF! | BP36: =BN36-BO36 -> #REF!
A37: 35 | B37: 120-DR-587-SHT02 | C37: 0 | D37: CN-2760 | F37: 08331 | G37: DR | H37: DRAINS DRR DRIPS RETURN | I37: 120-DR-587-SHT02-1 | J37: 02 | K37: 210 | M37: LF | N37: 01HDPE | O37: =P37/AM37 -> #DIV/0! | P37: =L37*Q37*AN37+L37*S37*AO37+L37*U37*AP37+L37*W37*AQ37+L37*Y37*AR37+L37*AA37*AS37+L37*AC37*AT37+L37*AE37*AU37 -> 0 | R37: Receive | T37: Stage | V37: Erect | X37: Connect | Z37: Jeep/Trace | AB37: Mech. Sell Off | AD37: Test | AF37: Post | AI37: PI-401-002 | AJ37: 1 | AK37: Sandra | AN37: 0.02 | AO37: 0.03 | AP37: 0.2 | AQ37: 0.3 | AR37: 0.1 | AS37: 0.1 | AT37: 0.15 | AU37: 0.1 | AV37: 401 | AW37: N/A | AX37: N/A | AY37: N/A | BD37: =#REF!*#REF!+#REF!*#REF!+#REF!*#REF!+#REF!*#REF!+#REF!*#REF! -> #REF! | BE37: =#REF!*#REF!*#REF!+#REF!*#REF!*#REF!+#REF!*#REF!*#REF!+#REF!*#REF!*#REF!+#REF!*#REF!*#REF! -> #REF! | BF37: =BD37-BE37 -> #REF! | BG37: =#REF!*#REF!*#REF! -> #REF! | BH37: =#REF!*#REF!*#REF! -> #REF! | BI37: =#REF!*#REF!*#REF! -> #REF! | BJ37: =BH37+BI37 -> #REF! | BK37: =BG37+BH37+BI37 -> #REF! | BL37: =#REF!*#REF! -> #REF! | BM37: =BE37/BD37 -> #REF! | BN37: =#REF!*#REF!+#REF!*#REF!+#REF!*#REF!+#REF!*#REF!+#REF!*#REF! -> #REF! | BO37: =#REF!*#REF!*#REF!+#REF!*#REF!*#REF!+#REF!*#REF!*#REF!+#REF!*#REF!*#REF!+#REF!*#REF!*#REF! -> #REF! | BP37: =BN37-BO37 -> #REF!
A38: 36 | B38: 120-NH3-2103-SHT01 | C38: 0 | D38: CN-2970 | F38: 08332 | G38: NH3 | H38: AMMONIA | I38: 120-NH3-2103-SHT01-1 | J38: 03 | K38: 107 | M38: LF | N38: 01HDPE | O38: =P38/AM38 -> #DIV/0! | P38: =L38*Q38*AN38+L38*S38*AO38+L38*U38*AP38+L38*W38*AQ38+L38*Y38*AR38+L38*AA38*AS38+L38*AC38*AT38+L38*AE38*AU38 -> 0 | R38: Receive | T38: Stage | V38: Erect | X38: Connect | Z38: Jeep/Trace | AB38: Mech. Sell Off | AD38: Test | AF38: Post | AI38: PI-401-001 | AJ38: 1 | AK38: Bob | AN38: 0.02 | AO38: 0.03 | AP38: 0.2 | AQ38: 0.3 | AR38: 0.1 | AS38: 0.1 | AT38: 0.15 | AU38: 0.1 | AV38: 401 | AW38: N/A | AX38: N/A | AY38: N/A | BD38: =#REF!*#REF!+#REF!*#REF!+#REF!*#REF!+#REF!*#REF!+#REF!*#REF! -> #REF! | BE38: =#REF!*#REF!*#REF!+#REF!*#REF!*#REF!+#REF!*#REF!*#REF!+#REF!*#REF!*#REF!+#REF!*#REF!*#REF! -> #REF! | BF38: =BD38-BE38 -> #REF! | BG38: =#REF!*#REF!*#REF! -> #REF! | BH38: =#REF!*#REF!*#REF! -> #REF! | BI38: =#REF!*#REF!*#REF! -> #REF! | BJ38: =BH38+BI38 -> #REF! | BK38: =BG38+BH38+BI38 -> #REF! | BL38: =#REF!*#REF! -> #REF! | BM38: =BE38/BD38 -> #REF! | BN38: =#REF!*#REF!+#REF!*#REF!+#REF!*#REF!+#REF!*#REF!+#REF!*#REF! -> #REF! | BO38: =#REF!*#REF!*#REF!+#REF!*#REF!*#REF!+#REF!*#REF!*#REF!+#REF!*#REF!*#REF!+#REF!*#REF!*#REF! -> #REF! | BP38: =BN38-BO38 -> #REF!
A39: 37 | B39: 120-NH3-2103-SHT02 | C39: 0 | D39: CN-2970 | F39: 08332 | G39: NH3 | H39: AMMONIA | I39: 120-NH3-2103-SHT02-1 | J39: 03 | K39: 400 | M39: LF | N39: 01HDPE | O39: =P39/AM39 -> #DIV/0! | P39: =L39*Q39*AN39+L39*S39*AO39+L39*U39*AP39+L39*W39*AQ39+L39*Y39*AR39+L39*AA39*AS39+L39*AC39*AT39+L39*AE39*AU39 -> 0 | R39: Receive | T39: Stage | V39: Erect | X39: Connect | Z39: Jeep/Trace | AB39: Mech. Sell Off | AD39: Test | AF39: Post | AI39: PI-401-001 | AJ39: 1 | AK39: Jose | AN39: 0.02 | AO39: 0.03 | AP39: 0.2 | AQ39: 0.3 | AR39: 0.1 | AS39: 0.1 | AT39: 0.15 | AU39: 0.1 | AV39: 401 | AW39: N/A | AX39: N/A | AY39: N/A | BD39: =#REF!*#REF!+#REF!*#REF!+#REF!*#REF!+#REF!*#REF!+#REF!*#REF! -> #REF! | BE39: =#REF!*#REF!*#REF!+#REF!*#REF!*#REF!+#REF!*#REF!*#REF!+#REF!*#REF!*#REF!+#REF!*#REF!*#REF! -> #REF! | BF39: =BD39-BE39 -> #REF! | BG39: =#REF!*#REF!*#REF! -> #REF! | BH39: =#REF!*#REF!*#REF! -> #REF! | BI39: =#REF!*#REF!*#REF! -> #REF! | BJ39: =BH39+BI39 -> #REF! | BK39: =BG39+BH39+BI39 -> #REF! | BL39: =#REF!*#REF! -> #REF! | BM39: =BE39/BD39 -> #REF! | BN39: =#REF!*#REF!+#REF!*#REF!+#REF!*#REF!+#REF!*#REF!+#REF!*#REF! -> #REF! | BO39: =#REF!*#REF!*#REF!+#REF!*#REF!*#REF!+#REF!*#REF!*#REF!+#REF!*#REF!*#REF!+#REF!*#REF!*#REF! -> #REF! | BP39: =BN39-BO39 -> #REF!
A40: 38 | B40: 120-NH3-2103-SHT03 | C40: 0 | D40: CN-2970 | F40: 08332 | G40: NH3 | H40: AMMONIA | I40: 120-NH3-2103-SHT03-1 | J40: 03 | K40: 71 | M40: LF | N40: 01HDPE | O40: =P40/AM40 -> #DIV/0! | P40: =L40*Q40*AN40+L40*S40*AO40+L40*U40*AP40+L40*W40*AQ40+L40*Y40*AR40+L40*AA40*AS40+L40*AC40*AT40+L40*AE40*AU40 -> 0 | R40: Receive | T40: Stage | V40: Erect | X40: Connect | Z40: Jeep/Trace | AB40: Mech. Sell Off | AD40: Test | AF40: Post | AJ40: 1 | AK40: Juan | AN40: 0.02 | AO40: 0.03 | AP40: 0.2 | AQ40: 0.3 | AR40: 0.1 | AS40: 0.1 | AT40: 0.15 | AU40: 0.1 | AV40: 120 | AW40: N/A | AX40: N/A | AY40: N/A | BD40: =#REF!*#REF!+#REF!*#REF!+#REF!*#REF!+#REF!*#REF!+#REF!*#REF! -> #REF! | BE40: =#REF!*#REF!*#REF!+#REF!*#REF!*#REF!+#REF!*#REF!*#REF!+#REF!*#REF!*#REF!+#REF!*#REF!*#REF! -> #REF! | BF40: =BD40-BE40 -> #REF! | BG40: =#REF!*#REF!*#REF! -> #REF! | BH40: =#REF!*#REF!*#REF! -> #REF! | BI40: =#REF!*#REF!*#REF! -> #REF! | BJ40: =BH40+BI40 -> #REF! | BK40: =BG40+BH40+BI40 -> #REF! | BL40: =#REF!*#REF! -> #REF! | BM40: =BE40/BD40 -> #REF! | BN40: =#REF!*#REF!+#REF!*#REF!+#REF!*#REF!+#REF!*#REF!+#REF!*#REF! -> #REF! | BO40: =#REF!*#REF!*#REF!+#REF!*#REF!*#REF!+#REF!*#REF!*#REF!+#REF!*#REF!*#REF!+#REF!*#REF!*#REF! -> #REF! | BP40: =BN40-BO40 -> #REF!
...

Sheet By Cost Code
E1: ISO SIGN OFFS WITH TEST PACKAGES
A2: Week Ending | D2: UNIT | E2: TOTAL | F2: TOTAL HOURS | G2: EARNED FOOTAGE | H2: JOB SUBTOTAL | I2: TOTAL | J2: DAILY TOTAL | K2: Weekly Total Hours Earned
D3: RATES | E3: FOOTAGE | I3: TOTAL | J3: DAILY TOTAL
A5: SPOOL - Carbon Steel Pipe 2.5" and Under | B5: 8111 | C5: 08111P | D5: =F5/E5 -> #DIV/0! | E5: =SUMIF('Pipe Audit'!$F$3:$F$82,$B5,'Pipe Audit'!$K$3:$K$82)+SUMIF('Pipe Audit'!$F$3:$F$82,$C5,'Pipe Audit'!$K$3:$K$82) -> 0 | F5: =SUMIF('Pipe Audit'!$F$3:$F$82,$B5,'Pipe Audit'!$L$3:$L$82)+SUMIF('Pipe Audit'!$F$3:$F$82,$C5,'Pipe Audit'!$L$3:$L$82) -> 0 | G5: =SUMIF('Pipe Audit'!$F$3:$F$82,$B5,'Pipe Audit'!$O$3:$O$82)+SUMIF('Pipe Audit'!$F$3:$F$82,$C5,'Pipe Audit'!$O$3:$O$82) -> 0 | H5: =SUMIF('Pipe Audit'!$F$3:$F$82,$B5,'Pipe Audit'!$P$3:$P$82)+SUMIF('Pipe Audit'!$F$3:$F$82,$C5,'Pipe Audit'!$P$3:$P$82) -> 0 | I5: 0 | J5: =SUM(H5-I5) -> 0 | K5: 0 | L5: =SUM(H5-K5) -> 0 | M5: 8111
A6: SPOOL - Carbon Steel Pipe 3" to 10" | B6: 8112 | C6: 08112P | D6: =F6/E6 -> #DIV/0! | E6: =SUMIF('Pipe Audit'!$F$3:$F$82,$B6,'Pipe Audit'!$K$3:$K$82)+SUMIF('Pipe Audit'!$F$3:$F$82,$C6,'Pipe Audit'!$K$3:$K$82) -> 0 | F6: =SUMIF('Pipe Audit'!$F$3:$F$82,$B6,'Pipe Audit'!$L$3:$L$82)+SUMIF('Pipe Audit'!$F$3:$F$82,$C6,'Pipe Audit'!$L$3:$L$82) -> 0 | G6: =SUMIF('Pipe Audit'!$F$3:$F$82,$B6,'Pipe Audit'!$O$3:$O$82)+SUMIF('Pipe Audit'!$F$3:$F$82,$C6,'Pipe Audit'!$O$3:$O$82) -> 0 | H6: =SUMIF('Pipe Audit'!$F$3:$F$82,$B6,'Pipe Audit'!$P$3:$P$82)+SUMIF('Pipe Audit'!$F$3:$F$82,$C6,'Pipe Audit'!$P$3:$P$82) -> 0 | I6: 0 | J6: =SUM(H6-I6) -> 0 | K6: 0 | L6: =SUM(H6-K6) -> 0 | M6: 8112
A7: SPOOL - Carbon Steel Pipe 12" and Over | B7: 8113 | C7: 08113P | D7: =F7/E7 -> #DIV/0! | E7: =SUMIF('Pipe Audit'!$F$3:$F$82,$B7,'Pipe Audit'!$K$3:$K$82)+SUMIF('Pipe Audit'!$F$3:$F$82,$C7,'Pipe Audit'!$K$3:$K$82) -> 0 | F7: =SUMIF('Pipe Audit'!$F$3:$F$82,$B7,'Pipe Audit'!$L$3:$L$82)+SUMIF('Pipe Audit'!$F$3:$F$82,$C7,'Pipe Audit'!$L$3:$L$82) -> 0 | G7: =SUMIF('Pipe Audit'!$F$3:$F$82,$B7,'Pipe Audit'!$O$3:$O$82)+SUMIF('Pipe Audit'!$F$3:$F$82,$C7,'Pipe Audit'!$O$3:$O$82) -> 0 | H7: =SUMIF('Pipe Audit'!$F$3:$F$82,$B7,'Pipe Audit'!$P$3:$P$82)+SUMIF('Pipe Audit'!$F$3:$F$82,$C7,'Pipe Audit'!$P$3:$P$82) -> 0 | I7: 0 | J7: =SUM(H7-I7) -> 0 | K7: 0 | L7: =SUM(H7-K7) -> 0 | M7: 8113
A8: SPOOL - Alloy Pipe 2.5" and Under | B8: 8121 | C8: 08121P | D8: =F8/E8 -> #DIV/0! | E8: =SUMIF('Pipe Audit'!$F$3:$F$82,$B8,'Pipe Audit'!$K$3:$K$82)+SUMIF('Pipe Audit'!$F$3:$F$82,$C8,'Pipe Audit'!$K$3:$K$82) -> 0 | F8: =SUMIF('Pipe Audit'!$F$3:$F$82,$B8,'Pipe Audit'!$L$3:$L$82)+SUMIF('Pipe Audit'!$F$3:$F$82,$C8,'Pipe Audit'!$L$3:$L$82) -> 0 | G8: =SUMIF('Pipe Audit'!$F$3:$F$82,$B8,'Pipe Audit'!$O$3:$O$82)+SUMIF('Pipe Audit'!$F$3:$F$82,$C8,'Pipe Audit'!$O$3:$O$82) -> 0 | H8: =SUMIF('Pipe Audit'!$F$3:$F$82,$B8,'Pipe Audit'!$P$3:$P$82)+SUMIF('Pipe Audit'!$F$3:$F$82,$C8,'Pipe Audit'!$P$3:$P$82) -> 0 | I8: 0 | J8: =SUM(H8-I8) -> 0 | K8: 0 | L8: =SUM(H8-K8) -> 0 | M8: 8121
A9: SPOOL - Alloy Pipe 3" to 10" | B9: 8122 | C9: 08122P | D9: =F9/E9 -> #DIV/0! | E9: =SUMIF('Pipe Audit'!$F$3:$F$82,$B9,'Pipe Audit'!$K$3:$K$82)+SUMIF('Pipe Audit'!$F$3:$F$82,$C9,'Pipe Audit'!$K$3:$K$82) -> 0 | F9: =SUMIF('Pipe Audit'!$F$3:$F$82,$B9,'Pipe Audit'!$L$3:$L$82)+SUMIF('Pipe Audit'!$F$3:$F$82,$C9,'Pipe Audit'!$L$3:$L$82) -> 0 | G9: =SUMIF('Pipe Audit'!$F$3:$F$82,$B9,'Pipe Audit'!$O$3:$O$82)+SUMIF('Pipe Audit'!$F$3:$F$82,$C9,'Pipe Audit'!$O$3:$O$82) -> 0 | H9: =SUMIF('Pipe Audit'!$F$3:$F$82,$B9,'Pipe Audit'!$P$3:$P$82)+SUMIF('Pipe Audit'!$F$3:$F$82,$C9,'Pipe Audit'!$P$3:$P$82) -> 0 | I9: 0 | J9: =SUM(H9-I9) -> 0 | K9: 0 | L9: =SUM(H9-K9) -> 0 | M9: 8122
A10: SPOOL - Alloy Pipe Pipe 12" and Over | B10: 8123 | C10: 08123P | D10: =F10/E10 -> #DIV/0! | E10: =SUMIF('Pipe Audit'!$F$3:$F$82,$B10,'Pipe Audit'!$K$3:$K$82)+SUMIF('Pipe Audit'!$F$3:$F$82,$C10,'Pipe Audit'!$K$3:$K$82) -> 0 | F10: =SUMIF('Pipe Audit'!$F$3:$F$82,$B10,'Pipe Audit'!$L$3:$L$82)+SUMIF('Pipe Audit'!$F$3:$F$82,$C10,'Pipe Audit'!$L$3:$L$82) -> 0 | G10: =SUMIF('Pipe Audit'!$F$3:$F$82,$B10,'Pipe Audit'!$O$3:$O$82)+SUMIF('Pipe Audit'!$F$3:$F$82,$C10,'Pipe Audit'!$O$3:$O$82) -> 0 | H10: =SUMIF('Pipe Audit'!$F$3:$F$82,$B10,'Pipe Audit'!$P$3:$P$82)+SUMIF('Pipe Audit'!$F$3:$F$82,$C10,'Pipe Audit'!$P$3:$P$82) -> 0 | I10: 0 | J10: =SUM(H10-I10) -> 0 | K10: 0 | L10: =SUM(H10-K10) -> 0 | M10: 8123
A11: Field Run - C/S Pipe 2.5" and Under | B11: 8211 | C11: 08211P | D11: =F11/E11 -> 0 | E11: =SUMIF('Pipe Audit'!$F$3:$F$82,$B11,'Pipe Audit'!$K$3:$K$82)+SUMIF('Pipe Audit'!$F$3:$F$82,$C11,'Pipe Audit'!$K$3:$K$82) -> 1885 | F11: =SUMIF('Pipe Audit'!$F$3:$F$82,$B11,'Pipe Audit'!$L$3:$L$82)+SUMIF('Pipe Audit'!$F$3:$F$82,$C11,'Pipe Audit'!$L$3:$L$82) -> 0 | G11: =SUMIF('Pipe Audit'!$F$3:$F$82,$B11,'Pipe Audit'!$O$3:$O$82)+SUMIF('Pipe Audit'!$F$3:$F$82,$C11,'Pipe Audit'!$O$3:$O$82) -> #DIV/0! | H11: =SUMIF('Pipe Audit'!$F$3:$F$82,$B11,'Pipe Audit'!$P$3:$P$82)+SUMIF('Pipe Audit'!$F$3:$F$82,$C11,'Pipe Audit'!$P$3:$P$82) -> 0 | I11: 0 | J11: =SUM(H11-I11) -> 0 | K11: 0 | L11: =SUM(H11-K11) -> 0 | M11: 8211
A12: Field Run - C/S Pipe 3" to 10" | B12: 8212 | C12: 08212P | D12: =F12/E12 -> 0 | E12: =SUMIF('Pipe Audit'!$F$3:$F$82,$B12,'Pipe Audit'!$K$3:$K$82)+SUMIF('Pipe Audit'!$F$3:$F$82,$C12,'Pipe Audit'!$K$3:$K$82) -> 1795 | F12: =SUMIF('Pipe Audit'!$F$3:$F$82,$B12,'Pipe Audit'!$L$3:$L$82)+SUMIF('Pipe Audit'!$F$3:$F$82,$C12,'Pipe Audit'!$L$3:$L$82) -> 0 | G12: =SUMIF('Pipe Audit'!$F$3:$F$82,$B12,'Pipe Audit'!$O$3:$O$82)+SUMIF('Pipe Audit'!$F$3:$F$82,$C12,'Pipe Audit'!$O$3:$O$82) -> #DIV/0! | H12: =SUMIF('Pipe Audit'!$F$3:$F$82,$B12,'Pipe Audit'!$P$3:$P$82)+SUMIF('Pipe Audit'!$F$3:$F$82,$C12,'Pipe Audit'!$P$3:$P$82) -> 0 | I12: 0 | J12: =SUM(H12-I12) -> 0 | K12: 0 | L12: =SUM(H12-K12) -> 0 | M12: 8212
A13: Field Run - C/S Pipe 12" and Over | B13: 8213 | C13: 08213P | D13: =F13/E13 -> #DIV/0! | E13: =SUMIF('Pipe Audit'!$F$3:$F$82,$B13,'Pipe Audit'!$K$3:$K$82)+SUMIF('Pipe Audit'!$F$3:$F$82,$C13,'Pipe Audit'!$K$3:$K$82) -> 0 | F13: =SUMIF('Pipe Audit'!$F$3:$F$82,$B13,'Pipe Audit'!$L$3:$L$82)+SUMIF('Pipe Audit'!$F$3:$F$82,$C13,'Pipe Audit'!$L$3:$L$82) -> 0 | G13: =SUMIF('Pipe Audit'!$F$3:$F$82,$B13,'Pipe Audit'!$O$3:$O$82)+SUMIF('Pipe Audit'!$F$3:$F$82,$C13,'Pipe Audit'!$O$3:$O$82) -> 0 | H13: =SUMIF('Pipe Audit'!$F$3:$F$82,$B13,'Pipe Audit'!$P$3:$P$82)+SUMIF('Pipe Audit'!$F$3:$F$82,$C13,'Pipe Audit'!$P$3:$P$82) -> 0 | I13: 0 | J13: =SUM(H13-I13) -> 0 | K13: 0 | L13: =SUM(H13-K13) -> 0 | M13: 8213
A14: Field Run - Alloy Pipe 2.5" and Under | B14: 8221 | C14: 08221P | D14: =F14/E14 -> #DIV/0! | E14: =SUMIF('Pipe Audit'!$F$3:$F$82,$B14,'Pipe Audit'!$K$3:$K$82)+SUMIF('Pipe Audit'!$F$3:$F$82,$C14,'Pipe Audit'!$K$3:$K$82) -> 0 | F14: =SUMIF('Pipe Audit'!$F$3:$F$82,$B14,'Pipe Audit'!$L$3:$L$82)+SUMIF('Pipe Audit'!$F$3:$F$82,$C14,'Pipe Audit'!$L$3:$L$82) -> 0 | G14: =SUMIF('Pipe Audit'!$F$3:$F$82,$B14,'Pipe Audit'!$O$3:$O$82)+SUMIF('Pipe Audit'!$F$3:$F$82,$C14,'Pipe Audit'!$O$3:$O$82) -> 0 | H14: =SUMIF('Pipe Audit'!$F$3:$F$82,$B14,'Pipe Audit'!$P$3:$P$82)+SUMIF('Pipe Audit'!$F$3:$F$82,$C14,'Pipe Audit'!$P$3:$P$82) -> 0 | I14: 0 | J14: =SUM(H14-I14) -> 0 | K14: 0 | L14: =SUM(H14-K14) -> 0 | M14: 8221
A15: Field Run - Alloy Pipe 3" to 10" | B15: 8222 | C15: 08222P | D15: =F15/E15 -> #DIV/0! | E15: =SUMIF('Pipe Audit'!$F$3:$F$82,$B15,'Pipe Audit'!$K$3:$K$82)+SUMIF('Pipe Audit'!$F$3:$F$82,$C15,'Pipe Audit'!$K$3:$K$82) -> 0 | F15: =SUMIF('Pipe Audit'!$F$3:$F$82,$B15,'Pipe Audit'!$L$3:$L$82)+SUMIF('Pipe Audit'!$F$3:$F$82,$C15,'Pipe Audit'!$L$3:$L$82) -> 0 | G15: =SUMIF('Pipe Audit'!$F$3:$F$82,$B15,'Pipe Audit'!$O$3:$O$82)+SUMIF('Pipe Audit'!$F$3:$F$82,$C15,'Pipe Audit'!$O$3:$O$82) -> 0 | H15: =SUMIF('Pipe Audit'!$F$3:$F$82,$B15,'Pipe Audit'!$P$3:$P$82)+SUMIF('Pipe Audit'!$F$3:$F$82,$C15,'Pipe Audit'!$P$3:$P$82) -> 0 | I15: 0 | J15: =SUM(H15-I15) -> 0 | K15: 0 | L15: =SUM(H15-K15) -> 0 | M15: 8222
A16: Field Run - Alloy Pipe 12" and Over | B16: 8223 | C16: 08223P | D16: =F16/E16 -> #DIV/0! | E16: =SUMIF('Pipe Audit'!$F$3:$F$82,$B16,'Pipe Audit'!$K$3:$K$82)+SUMIF('Pipe Audit'!$F$3:$F$82,$C16,'Pipe Audit'!$K$3:$K$82) -> 0 | F16: =SUMIF('Pipe Audit'!$F$3:$F$82,$B16,'Pipe Audit'!$L$3:$L$82)+SUMIF('Pipe Audit'!$F$3:$F$82,$C16,'Pipe Audit'!$L$3:$L$82) -> 0 | G16: =SUMIF('Pipe Audit'!$F$3:$F$82,$B16,'Pipe Audit'!$O$3:$O$82)+SUMIF('Pipe Audit'!$F$3:$F$82,$C16,'Pipe Audit'!$O$3:$O$82) -> 0 | H16: =SUMIF('Pipe Audit'!$F$3:$F$82,$B16,'Pipe Audit'!$P$3:$P$82)+SUMIF('Pipe Audit'!$F$3:$F$82,$C16,'Pipe Audit'!$P$3:$P$82) -> 0 | I16: 0 | J16: =SUM(H16-I16) -> 0 | K16: 0 | L16: =SUM(H16-K16) -> 0 | M16: 8223
... A21: FLARE VENDOR PIPING | B21: 8500 | C21: 08500P | D21: =F21/E21 -> #DIV/0! | E21: =SUMIF('Pipe Audit'!$F$3:$F$82,$B21,'Pipe Audit'!$K$3:$K$82)+SUMIF('Pipe Audit'!$F$3:$F$82,$C21,'Pipe Audit'!$K$3:$K$82) -> 0 | F21: =SUMIF('Pipe Audit'!$F$3:$F$82,$B21,'Pipe Audit'!$L$3:$L$82)+SUMIF('Pipe Audit'!$F$3:$F$82,$C21,'Pipe Audit'!$L$3:$L$82) -> 0 | G21: =SUMIF('Pipe Audit'!$F$3:$F$82,$B21,'Pipe Audit'!$O$3:$O$82)+SUMIF('Pipe Audit'!$F$3:$F$82,$C21,'Pipe Audit'!$O$3:$O$82) -> 0 | H21: =SUMIF('Pipe Audit'!$F$3:$F$82,$B21,'Pipe Audit'!$P$3:$P$82)+SUMIF('Pipe Audit'!$F$3:$F$82,$C21,'Pipe Audit'!$P$3:$P$82) -> 0 | I21: 0 | J21: =SUM(H21-I21) -> 0 | K21: 0 | L21: =SUM(H21-K21) -> 0 | M21: 8500
A22: FCO Work | B22: 8000 | C22: 8000 | E22: =SUMIF('Pipe Audit'!$F$3:$F$82,$B22,'Pipe Audit'!$K$3:$K$82) -> 0 | F22: =SUMIF('Pipe Audit'!$F$3:$F$82,$B22,'Pipe Audit'!$L$3:$L$82) -> 0 | G22: =SUMIF('Pipe Audit'!$F$3:$F$82,$B22,'Pipe Audit'!$O$3:$O$82) -> 0 | J22: =SUM(H22-I22) -> 0 | K22: 0 | L22: =SUM(H22-K22) -> 0
A23: TOTAL PIPE HOURS | B23: Total | D23: =F23/E23 -> 0 | E23: =SUM(E5:E22) -> 3680 | F23: =SUM(F5:F22) -> 0 | G23: =SUM(G5:G22) -> #DIV/0! | H23: =SUM(H5:H22) -> 0 | I23: 0 | J23: =SUM(J5:J22) -> 0 | K23: 0 | L23: =SUM(L5:L22) -> 0 | M23: GOAL | N23: REMAINDER TO EARN FOR THE WEEK
N24: =L23-M24 -> 0
